<?xml version="1.0" ?>
<!-- =================================================================================== -->
<!-- |    This document was autogenerated by xacro from daedalus.urdf.xacro            | -->
<!-- |    EDITING THIS FILE BY HAND IS NOT RECOMMENDED                                 | -->
<!-- =================================================================================== -->
<robot name="daedalus">
  <self_collide>false</self_collide>
  <!--Define some parameters -->
  <material name="white">
    <color rgba="1 1 1 0.2"/>
  </material>
  <material name="blue">
    <color rgba="0 0 0.8 0.1"/>
  </material>
  <material name="black">
    <color rgba="0 0 0 1"/>
  </material>
  <!--The sphere -->
  <link name="base_link"/>
  <link name="sphere">
    <!-- <visual>
      <geometry>
        <sphere radius="0.232"/>
      </geometry>
    </visual> -->
    <collision>
      <geometry>
        <sphere radius="0.232"/>
      </geometry>
    </collision>
    <inertial>
      <mass value="3"/>
      <inertia ixx="0.10764800000000001" ixy="0.0" ixz="0.0" iyy="0.10764800000000001" iyz="0.0" izz="0.10764800000000001"/>
    </inertial>
  </link>
  <gazebo reference="sphere">
    <mu1 value="200.0"/>
    <mu2 value="100.0"/>
    <kp value="10000000.0"/>
    <kd value="1.0"/>
    <material>Gazebo/GreyTransparent</material>
  </gazebo>
  <link name="filler_link">
    <visual>
      <geometry>
        <box size=".2 .38 .1"/>
      </geometry>
      <origin rpy="0 0 0" xyz="0 0 0"/>
      <material name="blue"/>
    </visual>
    <inertial>
      <mass value="1"/>
      <inertia ixx=".0145" ixy="0.0" ixz="0" iyy=".0181" iyz="0.0" izz=".006"/>
    </inertial>
  </link>
  <gazebo reference="filler_link">
    <material>Gazebo/Black</material>
  </gazebo>
  <link name="baseplate">
    <visual>
      <geometry>
        <box size=".2 .38 .1"/>
      </geometry>
      <origin rpy="0 0 0" xyz="0 0 0"/>
      <material name="blue"/>
    </visual>
    <inertial>
      <mass value="30"/>
      <inertia ixx="0.436" ixy="0.0" ixz="0" iyy="0.544" iyz="0.0" izz="0.18"/>
    </inertial>
  </link>
  <gazebo reference="baseplate">
    <material>Gazebo/Black</material>
  </gazebo>
  <joint name="connector_to_sphere_left" type="fixed">
    <parent link="inner_outer_connector_left"/>
    <child link="sphere"/>
    <origin xyz="0 0.2 0"/>
  </joint>
  <joint name="temp_cyl_1" type="continuous">
    <parent link="filler_link"/>
    <child link="inner_outer_connector_right"/>
    <axis rpy="0 0 0" xyz="0 1 0"/>
    <origin xyz="0 0.2 0"/>
    <limit effort="30.0" velocity="30.0"/>
    <joint_properties damping="1000.0" friction="1000.0"/>
    <dynamics damping="100.0" friction="200.0"/>
  </joint>
  <!--gazebo reference="temp_cyl_1">
    <implicitSpringDamper>true</implicitSpringDamper>
  </gazebo-->
  <joint name="temp_cyl_2" type="continuous">
    <parent link="filler_link"/>
    <child link="inner_outer_connector_left"/>
    <axis rpy="0 0 0" xyz="0 1 0"/>
    <origin xyz="0 -0.2 0"/>
    <limit effort="30.0" velocity="30.0"/>
    <joint_properties damping="1000.0" friction="1000.0"/>
    <dynamics damping="100.0" friction="200.0"/>
  </joint>
  <!--gazebo reference="temp_cyl_2">
    <implicitSpringDamper>true</implicitSpringDamper>
  </gazebo-->
  <joint name="filler" type="fixed">
    <parent link="base_link"/>
    <child link="filler_link"/>
    <origin xyz="0 0 0"/>
  </joint>
  <joint name="base_joint" type="fixed">
    <parent link="base_link"/>
    <child link="baseplate"/>
    <origin xyz="0 0 0"/>
  </joint>
  <transmission name="temp_cyl_1">
    <type>transmission_interface/SimpleTransmission</type>
    <actuator name="$temp_cyl_1">
      <mechanicalReduction>1</mechanicalReduction>
    </actuator>
    <joint name="temp_cyl_1">
      <hardwareInterface>hardware_interface/VelocityJointInterface</hardwareInterface>
    </joint>
  </transmission>
  <transmission name="temp_cyl_2">
    <type>transmission_interface/SimpleTransmission</type>
    <actuator name="$temp_cyl_2">
      <mechanicalReduction>1</mechanicalReduction>
    </actuator>
    <joint name="temp_cyl_2">
      <hardwareInterface>hardware_interface/VelocityJointInterface</hardwareInterface>
    </joint>
  </transmission>
  <link name="inner_outer_connector_right">
    <visual>
      <geometry>
        <cylinder length="0.025" radius="0.05"/>
      </geometry>
      <material name="black"/>
      <origin rpy="1.57 0 0" xyz="0 0 0"/>
    </visual>
    <collision>
      <geometry>
        <cylinder length="0.025" radius="0.05"/>
        <origin rpy="1.57 0 0" xyz="0 0 0"/>
      </geometry>
    </collision>
    <inertial>
      <mass value="0.3"/>
      <inertia ixx="1" ixy="0.0" ixz="0.0" iyy="1" iyz="0.0" izz="1"/>
    </inertial>
  </link>
  <gazebo reference="inner_outer_connector_right">
    <material>Gazebo/Black</material>
  </gazebo>
  <link name="inner_outer_connector_left">
    <visual>
      <geometry>
        <cylinder length="0.025" radius="0.05"/>
      </geometry>
      <material name="black"/>
      <origin rpy="1.57 0 0" xyz="0 0 0"/>
    </visual>
    <collision>
      <geometry>
        <cylinder length="0.025" radius="0.05"/>
        <origin rpy="1.57 0 0" xyz="0 0 0"/>
      </geometry>
    </collision>
    <inertial>
      <mass value="0.3"/>
      <inertia ixx="1" ixy="0.0" ixz="0.0" iyy="1" iyz="0.0" izz="1"/>
    </inertial>
  </link>
  <gazebo reference="inner_outer_connector_left">
    <material>Gazebo/Black</material>
  </gazebo>
  <link name="battery_holder">
    <visual>
      <geometry>
        <cylinder length="0.2" radius="0.01"/>
      </geometry>
      <origin rpy="0 0 0" xyz="0 0 -0.07"/>
      <material name="black"/>
    </visual>
    <collision>
      <geometry>
        <cylinder length="0.2" radius="0.01"/>
      </geometry>
    </collision>
    <inertial>
      <mass value="1"/>
      <inertia ixx="0.019" ixy="0.0" ixz="0.0" iyy="0.019" iyz="0.0" izz="0"/>
    </inertial>
  </link>
  <gazebo reference="battery_holder">
    <material>Gazebo/Black</material>
  </gazebo>
  <link name="battery">
    <visual>
      <geometry>
        <box size="0.1 0.1 0.05"/>
      </geometry>
      <origin rpy="0 0 0" xyz="0 0 0"/>
      <material name="black"/>
    </visual>
    <inertial>
      <mass value="10.0"/>
      <inertia ixx="0.01666666666666667" ixy="0.0" ixz="0.0" iyy="0.01666666666666667" iyz="0.0" izz="0.01041666666666667"/>
    </inertial>
    <collision>
      <geometry>
        <box size="0.1 0.1 0.05"/>
      </geometry>
    </collision>
  </link>
  <gazebo reference="battery">
    <material>Gazebo/Grey</material>
  </gazebo>
  <joint name="battery_joint" type="fixed">
    <parent link="battery_holder"/>
    <child link="battery"/>
    <origin xyz="0 0 -0.175"/>
  </joint>
  <joint name="battery_yaw" type="revolute">
    <parent link="baseplate"/>
    <axis xyz="1 0 0"/>
    <child link="battery_holder"/>
    <limit effort="1000.0" lower="-0.7853981633974483" upper="0.7853981633974483" velocity="0.5"/>
    <origin xyz="0 0 0"/>
    <joint_properties damping="1000.0" friction="1000.0"/>
    <dynamics damping="100.0" friction="200.0"/>
  </joint>
  <gazebo reference="battery_yaw">
    <implicitSpringDamper>true</implicitSpringDamper>
  </gazebo>
  <transmission name="battery_holder_trans">
    <type>transmission_interface/SimpleTransmission</type>
    <actuator name="$battery_holder__motor">
      <mechanicalReduction>1</mechanicalReduction>
    </actuator>
    <joint name="battery_yaw">
      <hardwareInterface>hardware_interface/PositionJointInterface</hardwareInterface>
    </joint>
  </transmission>
  <link name="hip_right_0">
    <visual>
      <geometry>
        <cylinder length="0.07" radius="0.01"/>
      </geometry>
      <material name="black"/>
    </visual>
    <collision>
      <geometry>
        <cylinder length="0.07" radius="0.01"/>
      </geometry>
    </collision>
    <inertial>
      <mass value="0.01"/>
      <inertia ixx="4.083333333333334e-06" ixy="0.0" ixz="0.0" iyy="0.0" iyz="0.0" izz="4.083333333333334e-06"/>
    </inertial>
  </link>
  <gazebo reference="hip_right_0">
    <material>Gazebo/Grey</material>
  </gazebo>
  <link name="outer_leg_right_0">
    <visual>
      <geometry>
        <cylinder length="0.07" radius="0.008"/>
      </geometry>
      <material name="black"/>
    </visual>
    <collision>
      <geometry>
        <cylinder length="0.07" radius="0.008"/>
      </geometry>
    </collision>
    <inertial>
      <mass value="0.008"/>
      <inertia ixx="3.2666666666666674e-06" ixy="0.0" ixz="0.0" iyy="0.0" iyz="0.0" izz="3.2666666666666674e-06"/>
    </inertial>
  </link>
  <gazebo reference="outer_leg_right_0">
    <material>Gazebo/Grey</material>
  </gazebo>
  <link name="center_leg_right_0">
    <visual>
      <geometry>
        <cylinder length="0.07" radius="0.006"/>
      </geometry>
      <material name="black"/>
    </visual>
    <collision>
      <geometry>
        <cylinder length="0.07" radius="0.006"/>
      </geometry>
    </collision>
    <inertial>
      <mass value="0.006"/>
      <inertia ixx="2.45e-06" ixy="0.0" ixz="0.0" iyy="2.45e-06" iyz="0.0" izz="0.0"/>
    </inertial>
  </link>
  <gazebo reference="center_leg_right_0">
    <material>Gazebo/Grey</material>
  </gazebo>
  <link name="inner_leg_right_0">
    <visual>
      <geometry>
        <cylinder length="0.07" radius="0.004"/>
      </geometry>
      <material name="black"/>
    </visual>
    <collision>
      <geometry>
        <cylinder length="0.07" radius="0.004"/>
      </geometry>
    </collision>
    <inertial>
      <mass value="0.004"/>
      <inertia ixx="1.6333333333333337e-06" ixy="0.0" ixz="0.0" iyy="1.6333333333333337e-06" iyz="0.0" izz="0.0"/>
    </inertial>
  </link>
  <gazebo reference="inner_leg_right_0">
    <material>Gazebo/Grey</material>
  </gazebo>
  <joint name="base_to_hip_right_0" type="fixed">
    <parent link="inner_outer_connector_right"/>
    <child link="hip_right_0"/>
    <origin rpy="0 0.0 0" xyz="0.0 0 0.07"/>
  </joint>
  <joint name="hip_to_outer_leg_right_0" type="prismatic">
    <axis xyz="0 0 1"/>
    <parent link="hip_right_0"/>
    <child link="outer_leg_right_0"/>
    <limit effort="200.0" lower="0.0" upper="0.07" velocity="0.1"/>
    <origin rpy="0 0 0" xyz="0 0 0"/>
    <dynamics damping="100" friction="200"/>
  </joint>
  <gazebo reference="hip_to_outer_leg_right_0">
    <implicitSpringDamper>true</implicitSpringDamper>
  </gazebo>
  <joint name="outer_to_center_leg_right_0" type="prismatic">
    <axis xyz="0 0 1"/>
    <parent link="outer_leg_right_0"/>
    <child link="center_leg_right_0"/>
    <limit effort="200.0" lower="0.0" upper="0.07" velocity="0.1"/>
    <origin rpy="0 0 0" xyz="0 0 0"/>
    <dynamics damping="100" friction="200"/>
  </joint>
  <gazebo reference="outer_to_center_leg_right_0">
    <implicitSpringDamper>true</implicitSpringDamper>
  </gazebo>
  <joint name="center_to_inner_leg_right_0" type="prismatic">
    <axis xyz="0 0 1"/>
    <parent link="center_leg_right_0"/>
    <child link="inner_leg_right_0"/>
    <limit effort="200.0" lower="0.0" upper="0.07" velocity="0.1"/>
    <origin rpy="0 0 0" xyz="0 0 0"/>
    <dynamics damping="100" friction="200"/>
  </joint>
  <gazebo reference="center_to_inner_leg_right_0">
    <implicitSpringDamper>true</implicitSpringDamper>
  </gazebo>
  <transmission name="outer_leg_extension_right_0_trans" type="SimpleTransmission">
    <type>transmission_interface/SimpleTransmission</type>
    <actuator name="outer_leg_extension_right_0_motor">
      <hardwareInterface>hardware_interface/PositionJointInterface</hardwareInterface>
      <mechanicalReduction>1</mechanicalReduction>
    </actuator>
    <joint name="hip_to_outer_leg_right_0">
      <hardwareInterface>hardware_interface/PositionJointInterface</hardwareInterface>
    </joint>
  </transmission>
  <transmission name="center_leg_extension_right_0_trans" type="SimpleTransmission">
    <type>transmission_interface/SimpleTransmission</type>
    <actuator name="center_leg_extension_right_0_motor">
      <hardwareInterface>hardware_interface/PositionJointInterface</hardwareInterface>
      <mechanicalReduction>1</mechanicalReduction>
    </actuator>
    <joint name="outer_to_center_leg_right_0">
      <hardwareInterface>hardware_interface/PositionJointInterface</hardwareInterface>
    </joint>
  </transmission>
  <transmission name="inner_leg_extension_right_0_trans" type="SimpleTransmission">
    <type>transmission_interface/SimpleTransmission</type>
    <actuator name="inner_leg_extension_right_0_motor">
      <hardwareInterface>hardware_interface/PositionJointInterface</hardwareInterface>
      <mechanicalReduction>1</mechanicalReduction>
    </actuator>
    <joint name="center_to_inner_leg_right_0">
      <hardwareInterface>hardware_interface/PositionJointInterface</hardwareInterface>
    </joint>
  </transmission>
  <link name="hip_right_2">
    <visual>
      <geometry>
        <cylinder length="0.07" radius="0.01"/>
      </geometry>
      <material name="black"/>
    </visual>
    <collision>
      <geometry>
        <cylinder length="0.07" radius="0.01"/>
      </geometry>
    </collision>
    <inertial>
      <mass value="0.01"/>
      <inertia ixx="4.083333333333334e-06" ixy="0.0" ixz="0.0" iyy="0.0" iyz="0.0" izz="4.083333333333334e-06"/>
    </inertial>
  </link>
  <gazebo reference="hip_right_2">
    <material>Gazebo/Grey</material>
  </gazebo>
  <link name="outer_leg_right_2">
    <visual>
      <geometry>
        <cylinder length="0.07" radius="0.008"/>
      </geometry>
      <material name="black"/>
    </visual>
    <collision>
      <geometry>
        <cylinder length="0.07" radius="0.008"/>
      </geometry>
    </collision>
    <inertial>
      <mass value="0.008"/>
      <inertia ixx="3.2666666666666674e-06" ixy="0.0" ixz="0.0" iyy="0.0" iyz="0.0" izz="3.2666666666666674e-06"/>
    </inertial>
  </link>
  <gazebo reference="outer_leg_right_2">
    <material>Gazebo/Grey</material>
  </gazebo>
  <link name="center_leg_right_2">
    <visual>
      <geometry>
        <cylinder length="0.07" radius="0.006"/>
      </geometry>
      <material name="black"/>
    </visual>
    <collision>
      <geometry>
        <cylinder length="0.07" radius="0.006"/>
      </geometry>
    </collision>
    <inertial>
      <mass value="0.006"/>
      <inertia ixx="2.45e-06" ixy="0.0" ixz="0.0" iyy="2.45e-06" iyz="0.0" izz="0.0"/>
    </inertial>
  </link>
  <gazebo reference="center_leg_right_2">
    <material>Gazebo/Grey</material>
  </gazebo>
  <link name="inner_leg_right_2">
    <visual>
      <geometry>
        <cylinder length="0.07" radius="0.004"/>
      </geometry>
      <material name="black"/>
    </visual>
    <collision>
      <geometry>
        <cylinder length="0.07" radius="0.004"/>
      </geometry>
    </collision>
    <inertial>
      <mass value="0.004"/>
      <inertia ixx="1.6333333333333337e-06" ixy="0.0" ixz="0.0" iyy="1.6333333333333337e-06" iyz="0.0" izz="0.0"/>
    </inertial>
  </link>
  <gazebo reference="inner_leg_right_2">
    <material>Gazebo/Grey</material>
  </gazebo>
  <joint name="base_to_hip_right_2" type="fixed">
    <parent link="inner_outer_connector_right"/>
    <child link="hip_right_2"/>
    <origin rpy="0 1.5707963267948966 0" xyz="0.07 0 4.286263797015737e-18"/>
  </joint>
  <joint name="hip_to_outer_leg_right_2" type="prismatic">
    <axis xyz="0 0 1"/>
    <parent link="hip_right_2"/>
    <child link="outer_leg_right_2"/>
    <limit effort="200.0" lower="0.0" upper="0.07" velocity="0.1"/>
    <origin rpy="0 0 0" xyz="0 0 0"/>
    <dynamics damping="100" friction="200"/>
  </joint>
  <gazebo reference="hip_to_outer_leg_right_2">
    <implicitSpringDamper>true</implicitSpringDamper>
  </gazebo>
  <joint name="outer_to_center_leg_right_2" type="prismatic">
    <axis xyz="0 0 1"/>
    <parent link="outer_leg_right_2"/>
    <child link="center_leg_right_2"/>
    <limit effort="200.0" lower="0.0" upper="0.07" velocity="0.1"/>
    <origin rpy="0 0 0" xyz="0 0 0"/>
    <dynamics damping="100" friction="200"/>
  </joint>
  <gazebo reference="outer_to_center_leg_right_2">
    <implicitSpringDamper>true</implicitSpringDamper>
  </gazebo>
  <joint name="center_to_inner_leg_right_2" type="prismatic">
    <axis xyz="0 0 1"/>
    <parent link="center_leg_right_2"/>
    <child link="inner_leg_right_2"/>
    <limit effort="200.0" lower="0.0" upper="0.07" velocity="0.1"/>
    <origin rpy="0 0 0" xyz="0 0 0"/>
    <dynamics damping="100" friction="200"/>
  </joint>
  <gazebo reference="center_to_inner_leg_right_2">
    <implicitSpringDamper>true</implicitSpringDamper>
  </gazebo>
  <transmission name="outer_leg_extension_right_2_trans" type="SimpleTransmission">
    <type>transmission_interface/SimpleTransmission</type>
    <actuator name="outer_leg_extension_right_2_motor">
      <hardwareInterface>hardware_interface/PositionJointInterface</hardwareInterface>
      <mechanicalReduction>1</mechanicalReduction>
    </actuator>
    <joint name="hip_to_outer_leg_right_2">
      <hardwareInterface>hardware_interface/PositionJointInterface</hardwareInterface>
    </joint>
  </transmission>
  <transmission name="center_leg_extension_right_2_trans" type="SimpleTransmission">
    <type>transmission_interface/SimpleTransmission</type>
    <actuator name="center_leg_extension_right_2_motor">
      <hardwareInterface>hardware_interface/PositionJointInterface</hardwareInterface>
      <mechanicalReduction>1</mechanicalReduction>
    </actuator>
    <joint name="outer_to_center_leg_right_2">
      <hardwareInterface>hardware_interface/PositionJointInterface</hardwareInterface>
    </joint>
  </transmission>
  <transmission name="inner_leg_extension_right_2_trans" type="SimpleTransmission">
    <type>transmission_interface/SimpleTransmission</type>
    <actuator name="inner_leg_extension_right_2_motor">
      <hardwareInterface>hardware_interface/PositionJointInterface</hardwareInterface>
      <mechanicalReduction>1</mechanicalReduction>
    </actuator>
    <joint name="center_to_inner_leg_right_2">
      <hardwareInterface>hardware_interface/PositionJointInterface</hardwareInterface>
    </joint>
  </transmission>
  <link name="hip_right_4">
    <visual>
      <geometry>
        <cylinder length="0.07" radius="0.01"/>
      </geometry>
      <material name="black"/>
    </visual>
    <collision>
      <geometry>
        <cylinder length="0.07" radius="0.01"/>
      </geometry>
    </collision>
    <inertial>
      <mass value="0.01"/>
      <inertia ixx="4.083333333333334e-06" ixy="0.0" ixz="0.0" iyy="0.0" iyz="0.0" izz="4.083333333333334e-06"/>
    </inertial>
  </link>
  <gazebo reference="hip_right_4">
    <material>Gazebo/Grey</material>
  </gazebo>
  <link name="outer_leg_right_4">
    <visual>
      <geometry>
        <cylinder length="0.07" radius="0.008"/>
      </geometry>
      <material name="black"/>
    </visual>
    <collision>
      <geometry>
        <cylinder length="0.07" radius="0.008"/>
      </geometry>
    </collision>
    <inertial>
      <mass value="0.008"/>
      <inertia ixx="3.2666666666666674e-06" ixy="0.0" ixz="0.0" iyy="0.0" iyz="0.0" izz="3.2666666666666674e-06"/>
    </inertial>
  </link>
  <gazebo reference="outer_leg_right_4">
    <material>Gazebo/Grey</material>
  </gazebo>
  <link name="center_leg_right_4">
    <visual>
      <geometry>
        <cylinder length="0.07" radius="0.006"/>
      </geometry>
      <material name="black"/>
    </visual>
    <collision>
      <geometry>
        <cylinder length="0.07" radius="0.006"/>
      </geometry>
    </collision>
    <inertial>
      <mass value="0.006"/>
      <inertia ixx="2.45e-06" ixy="0.0" ixz="0.0" iyy="2.45e-06" iyz="0.0" izz="0.0"/>
    </inertial>
  </link>
  <gazebo reference="center_leg_right_4">
    <material>Gazebo/Grey</material>
  </gazebo>
  <link name="inner_leg_right_4">
    <visual>
      <geometry>
        <cylinder length="0.07" radius="0.004"/>
      </geometry>
      <material name="black"/>
    </visual>
    <collision>
      <geometry>
        <cylinder length="0.07" radius="0.004"/>
      </geometry>
    </collision>
    <inertial>
      <mass value="0.004"/>
      <inertia ixx="1.6333333333333337e-06" ixy="0.0" ixz="0.0" iyy="1.6333333333333337e-06" iyz="0.0" izz="0.0"/>
    </inertial>
  </link>
  <gazebo reference="inner_leg_right_4">
    <material>Gazebo/Grey</material>
  </gazebo>
  <joint name="base_to_hip_right_4" type="fixed">
    <parent link="inner_outer_connector_right"/>
    <child link="hip_right_4"/>
    <origin rpy="0 3.141592653589793 0" xyz="8.572527594031473e-18 0 -0.07"/>
  </joint>
  <joint name="hip_to_outer_leg_right_4" type="prismatic">
    <axis xyz="0 0 1"/>
    <parent link="hip_right_4"/>
    <child link="outer_leg_right_4"/>
    <limit effort="200.0" lower="0.0" upper="0.07" velocity="0.1"/>
    <origin rpy="0 0 0" xyz="0 0 0"/>
    <dynamics damping="100" friction="200"/>
  </joint>
  <gazebo reference="hip_to_outer_leg_right_4">
    <implicitSpringDamper>true</implicitSpringDamper>
  </gazebo>
  <joint name="outer_to_center_leg_right_4" type="prismatic">
    <axis xyz="0 0 1"/>
    <parent link="outer_leg_right_4"/>
    <child link="center_leg_right_4"/>
    <limit effort="200.0" lower="0.0" upper="0.07" velocity="0.1"/>
    <origin rpy="0 0 0" xyz="0 0 0"/>
    <dynamics damping="100" friction="200"/>
  </joint>
  <gazebo reference="outer_to_center_leg_right_4">
    <implicitSpringDamper>true</implicitSpringDamper>
  </gazebo>
  <joint name="center_to_inner_leg_right_4" type="prismatic">
    <axis xyz="0 0 1"/>
    <parent link="center_leg_right_4"/>
    <child link="inner_leg_right_4"/>
    <limit effort="200.0" lower="0.0" upper="0.07" velocity="0.1"/>
    <origin rpy="0 0 0" xyz="0 0 0"/>
    <dynamics damping="100" friction="200"/>
  </joint>
  <gazebo reference="center_to_inner_leg_right_4">
    <implicitSpringDamper>true</implicitSpringDamper>
  </gazebo>
  <transmission name="outer_leg_extension_right_4_trans" type="SimpleTransmission">
    <type>transmission_interface/SimpleTransmission</type>
    <actuator name="outer_leg_extension_right_4_motor">
      <hardwareInterface>hardware_interface/PositionJointInterface</hardwareInterface>
      <mechanicalReduction>1</mechanicalReduction>
    </actuator>
    <joint name="hip_to_outer_leg_right_4">
      <hardwareInterface>hardware_interface/PositionJointInterface</hardwareInterface>
    </joint>
  </transmission>
  <transmission name="center_leg_extension_right_4_trans" type="SimpleTransmission">
    <type>transmission_interface/SimpleTransmission</type>
    <actuator name="center_leg_extension_right_4_motor">
      <hardwareInterface>hardware_interface/PositionJointInterface</hardwareInterface>
      <mechanicalReduction>1</mechanicalReduction>
    </actuator>
    <joint name="outer_to_center_leg_right_4">
      <hardwareInterface>hardware_interface/PositionJointInterface</hardwareInterface>
    </joint>
  </transmission>
  <transmission name="inner_leg_extension_right_4_trans" type="SimpleTransmission">
    <type>transmission_interface/SimpleTransmission</type>
    <actuator name="inner_leg_extension_right_4_motor">
      <hardwareInterface>hardware_interface/PositionJointInterface</hardwareInterface>
      <mechanicalReduction>1</mechanicalReduction>
    </actuator>
    <joint name="center_to_inner_leg_right_4">
      <hardwareInterface>hardware_interface/PositionJointInterface</hardwareInterface>
    </joint>
  </transmission>
  <link name="hip_right_6">
    <visual>
      <geometry>
        <cylinder length="0.07" radius="0.01"/>
      </geometry>
      <material name="black"/>
    </visual>
    <collision>
      <geometry>
        <cylinder length="0.07" radius="0.01"/>
      </geometry>
    </collision>
    <inertial>
      <mass value="0.01"/>
      <inertia ixx="4.083333333333334e-06" ixy="0.0" ixz="0.0" iyy="0.0" iyz="0.0" izz="4.083333333333334e-06"/>
    </inertial>
  </link>
  <gazebo reference="hip_right_6">
    <material>Gazebo/Grey</material>
  </gazebo>
  <link name="outer_leg_right_6">
    <visual>
      <geometry>
        <cylinder length="0.07" radius="0.008"/>
      </geometry>
      <material name="black"/>
    </visual>
    <collision>
      <geometry>
        <cylinder length="0.07" radius="0.008"/>
      </geometry>
    </collision>
    <inertial>
      <mass value="0.008"/>
      <inertia ixx="3.2666666666666674e-06" ixy="0.0" ixz="0.0" iyy="0.0" iyz="0.0" izz="3.2666666666666674e-06"/>
    </inertial>
  </link>
  <gazebo reference="outer_leg_right_6">
    <material>Gazebo/Grey</material>
  </gazebo>
  <link name="center_leg_right_6">
    <visual>
      <geometry>
        <cylinder length="0.07" radius="0.006"/>
      </geometry>
      <material name="black"/>
    </visual>
    <collision>
      <geometry>
        <cylinder length="0.07" radius="0.006"/>
      </geometry>
    </collision>
    <inertial>
      <mass value="0.006"/>
      <inertia ixx="2.45e-06" ixy="0.0" ixz="0.0" iyy="2.45e-06" iyz="0.0" izz="0.0"/>
    </inertial>
  </link>
  <gazebo reference="center_leg_right_6">
    <material>Gazebo/Grey</material>
  </gazebo>
  <link name="inner_leg_right_6">
    <visual>
      <geometry>
        <cylinder length="0.07" radius="0.004"/>
      </geometry>
      <material name="black"/>
    </visual>
    <collision>
      <geometry>
        <cylinder length="0.07" radius="0.004"/>
      </geometry>
    </collision>
    <inertial>
      <mass value="0.004"/>
      <inertia ixx="1.6333333333333337e-06" ixy="0.0" ixz="0.0" iyy="1.6333333333333337e-06" iyz="0.0" izz="0.0"/>
    </inertial>
  </link>
  <gazebo reference="inner_leg_right_6">
    <material>Gazebo/Grey</material>
  </gazebo>
  <joint name="base_to_hip_right_6" type="fixed">
    <parent link="inner_outer_connector_right"/>
    <child link="hip_right_6"/>
    <origin rpy="0 4.71238898038469 0" xyz="-0.07 0 -1.285879139104721e-17"/>
  </joint>
  <joint name="hip_to_outer_leg_right_6" type="prismatic">
    <axis xyz="0 0 1"/>
    <parent link="hip_right_6"/>
    <child link="outer_leg_right_6"/>
    <limit effort="200.0" lower="0.0" upper="0.07" velocity="0.1"/>
    <origin rpy="0 0 0" xyz="0 0 0"/>
    <dynamics damping="100" friction="200"/>
  </joint>
  <gazebo reference="hip_to_outer_leg_right_6">
    <implicitSpringDamper>true</implicitSpringDamper>
  </gazebo>
  <joint name="outer_to_center_leg_right_6" type="prismatic">
    <axis xyz="0 0 1"/>
    <parent link="outer_leg_right_6"/>
    <child link="center_leg_right_6"/>
    <limit effort="200.0" lower="0.0" upper="0.07" velocity="0.1"/>
    <origin rpy="0 0 0" xyz="0 0 0"/>
    <dynamics damping="100" friction="200"/>
  </joint>
  <gazebo reference="outer_to_center_leg_right_6">
    <implicitSpringDamper>true</implicitSpringDamper>
  </gazebo>
  <joint name="center_to_inner_leg_right_6" type="prismatic">
    <axis xyz="0 0 1"/>
    <parent link="center_leg_right_6"/>
    <child link="inner_leg_right_6"/>
    <limit effort="200.0" lower="0.0" upper="0.07" velocity="0.1"/>
    <origin rpy="0 0 0" xyz="0 0 0"/>
    <dynamics damping="100" friction="200"/>
  </joint>
  <gazebo reference="center_to_inner_leg_right_6">
    <implicitSpringDamper>true</implicitSpringDamper>
  </gazebo>
  <transmission name="outer_leg_extension_right_6_trans" type="SimpleTransmission">
    <type>transmission_interface/SimpleTransmission</type>
    <actuator name="outer_leg_extension_right_6_motor">
      <hardwareInterface>hardware_interface/PositionJointInterface</hardwareInterface>
      <mechanicalReduction>1</mechanicalReduction>
    </actuator>
    <joint name="hip_to_outer_leg_right_6">
      <hardwareInterface>hardware_interface/PositionJointInterface</hardwareInterface>
    </joint>
  </transmission>
  <transmission name="center_leg_extension_right_6_trans" type="SimpleTransmission">
    <type>transmission_interface/SimpleTransmission</type>
    <actuator name="center_leg_extension_right_6_motor">
      <hardwareInterface>hardware_interface/PositionJointInterface</hardwareInterface>
      <mechanicalReduction>1</mechanicalReduction>
    </actuator>
    <joint name="outer_to_center_leg_right_6">
      <hardwareInterface>hardware_interface/PositionJointInterface</hardwareInterface>
    </joint>
  </transmission>
  <transmission name="inner_leg_extension_right_6_trans" type="SimpleTransmission">
    <type>transmission_interface/SimpleTransmission</type>
    <actuator name="inner_leg_extension_right_6_motor">
      <hardwareInterface>hardware_interface/PositionJointInterface</hardwareInterface>
      <mechanicalReduction>1</mechanicalReduction>
    </actuator>
    <joint name="center_to_inner_leg_right_6">
      <hardwareInterface>hardware_interface/PositionJointInterface</hardwareInterface>
    </joint>
  </transmission>
  <link name="hip_right_1">
    <visual>
      <geometry>
        <cylinder length="0.07" radius="0.01"/>
      </geometry>
      <material name="black"/>
    </visual>
    <collision>
      <geometry>
        <cylinder length="0.07" radius="0.01"/>
      </geometry>
    </collision>
    <inertial>
      <mass value="0.01"/>
      <inertia ixx="4.083333333333334e-06" ixy="0.0" ixz="0.0" iyy="0.0" iyz="0.0" izz="4.083333333333334e-06"/>
    </inertial>
  </link>
  <gazebo reference="hip_right_1">
    <material>Gazebo/Grey</material>
  </gazebo>
  <link name="outer_leg_right_1">
    <visual>
      <geometry>
        <cylinder length="0.07" radius="0.008"/>
      </geometry>
      <material name="black"/>
    </visual>
    <collision>
      <geometry>
        <cylinder length="0.07" radius="0.008"/>
      </geometry>
    </collision>
    <inertial>
      <mass value="0.008"/>
      <inertia ixx="3.2666666666666674e-06" ixy="0.0" ixz="0.0" iyy="0.0" iyz="0.0" izz="3.2666666666666674e-06"/>
    </inertial>
  </link>
  <gazebo reference="outer_leg_right_1">
    <material>Gazebo/Grey</material>
  </gazebo>
  <link name="center_leg_right_1">
    <visual>
      <geometry>
        <cylinder length="0.07" radius="0.006"/>
      </geometry>
      <material name="black"/>
    </visual>
    <collision>
      <geometry>
        <cylinder length="0.07" radius="0.006"/>
      </geometry>
    </collision>
    <inertial>
      <mass value="0.006"/>
      <inertia ixx="2.45e-06" ixy="0.0" ixz="0.0" iyy="2.45e-06" iyz="0.0" izz="0.0"/>
    </inertial>
  </link>
  <gazebo reference="center_leg_right_1">
    <material>Gazebo/Grey</material>
  </gazebo>
  <link name="inner_leg_right_1">
    <visual>
      <geometry>
        <cylinder length="0.07" radius="0.004"/>
      </geometry>
      <material name="black"/>
    </visual>
    <collision>
      <geometry>
        <cylinder length="0.07" radius="0.004"/>
      </geometry>
    </collision>
    <inertial>
      <mass value="0.004"/>
      <inertia ixx="1.6333333333333337e-06" ixy="0.0" ixz="0.0" iyy="1.6333333333333337e-06" iyz="0.0" izz="0.0"/>
    </inertial>
  </link>
  <gazebo reference="inner_leg_right_1">
    <material>Gazebo/Grey</material>
  </gazebo>
  <joint name="base_to_hip_right_1" type="fixed">
    <parent link="inner_outer_connector_right"/>
    <child link="hip_right_1"/>
    <origin rpy="0 0.7853981633974483 0" xyz="0.049497474683058325 0 0.04949747468305833"/>
  </joint>
  <joint name="hip_to_outer_leg_right_1" type="prismatic">
    <axis xyz="0 0 1"/>
    <parent link="hip_right_1"/>
    <child link="outer_leg_right_1"/>
    <limit effort="200.0" lower="0.0" upper="0.07" velocity="0.1"/>
    <origin rpy="0 0 0" xyz="0 0 0"/>
    <dynamics damping="100" friction="200"/>
  </joint>
  <gazebo reference="hip_to_outer_leg_right_1">
    <implicitSpringDamper>true</implicitSpringDamper>
  </gazebo>
  <joint name="outer_to_center_leg_right_1" type="prismatic">
    <axis xyz="0 0 1"/>
    <parent link="outer_leg_right_1"/>
    <child link="center_leg_right_1"/>
    <limit effort="200.0" lower="0.0" upper="0.07" velocity="0.1"/>
    <origin rpy="0 0 0" xyz="0 0 0"/>
    <dynamics damping="100" friction="200"/>
  </joint>
  <gazebo reference="outer_to_center_leg_right_1">
    <implicitSpringDamper>true</implicitSpringDamper>
  </gazebo>
  <joint name="center_to_inner_leg_right_1" type="prismatic">
    <axis xyz="0 0 1"/>
    <parent link="center_leg_right_1"/>
    <child link="inner_leg_right_1"/>
    <limit effort="200.0" lower="0.0" upper="0.07" velocity="0.1"/>
    <origin rpy="0 0 0" xyz="0 0 0"/>
    <dynamics damping="100" friction="200"/>
  </joint>
  <gazebo reference="center_to_inner_leg_right_1">
    <implicitSpringDamper>true</implicitSpringDamper>
  </gazebo>
  <transmission name="outer_leg_extension_right_1_trans" type="SimpleTransmission">
    <type>transmission_interface/SimpleTransmission</type>
    <actuator name="outer_leg_extension_right_1_motor">
      <hardwareInterface>hardware_interface/PositionJointInterface</hardwareInterface>
      <mechanicalReduction>1</mechanicalReduction>
    </actuator>
    <joint name="hip_to_outer_leg_right_1">
      <hardwareInterface>hardware_interface/PositionJointInterface</hardwareInterface>
    </joint>
  </transmission>
  <transmission name="center_leg_extension_right_1_trans" type="SimpleTransmission">
    <type>transmission_interface/SimpleTransmission</type>
    <actuator name="center_leg_extension_right_1_motor">
      <hardwareInterface>hardware_interface/PositionJointInterface</hardwareInterface>
      <mechanicalReduction>1</mechanicalReduction>
    </actuator>
    <joint name="outer_to_center_leg_right_1">
      <hardwareInterface>hardware_interface/PositionJointInterface</hardwareInterface>
    </joint>
  </transmission>
  <transmission name="inner_leg_extension_right_1_trans" type="SimpleTransmission">
    <type>transmission_interface/SimpleTransmission</type>
    <actuator name="inner_leg_extension_right_1_motor">
      <hardwareInterface>hardware_interface/PositionJointInterface</hardwareInterface>
      <mechanicalReduction>1</mechanicalReduction>
    </actuator>
    <joint name="center_to_inner_leg_right_1">
      <hardwareInterface>hardware_interface/PositionJointInterface</hardwareInterface>
    </joint>
  </transmission>
  <link name="hip_right_3">
    <visual>
      <geometry>
        <cylinder length="0.07" radius="0.01"/>
      </geometry>
      <material name="black"/>
    </visual>
    <collision>
      <geometry>
        <cylinder length="0.07" radius="0.01"/>
      </geometry>
    </collision>
    <inertial>
      <mass value="0.01"/>
      <inertia ixx="4.083333333333334e-06" ixy="0.0" ixz="0.0" iyy="0.0" iyz="0.0" izz="4.083333333333334e-06"/>
    </inertial>
  </link>
  <gazebo reference="hip_right_3">
    <material>Gazebo/Grey</material>
  </gazebo>
  <link name="outer_leg_right_3">
    <visual>
      <geometry>
        <cylinder length="0.07" radius="0.008"/>
      </geometry>
      <material name="black"/>
    </visual>
    <collision>
      <geometry>
        <cylinder length="0.07" radius="0.008"/>
      </geometry>
    </collision>
    <inertial>
      <mass value="0.008"/>
      <inertia ixx="3.2666666666666674e-06" ixy="0.0" ixz="0.0" iyy="0.0" iyz="0.0" izz="3.2666666666666674e-06"/>
    </inertial>
  </link>
  <gazebo reference="outer_leg_right_3">
    <material>Gazebo/Grey</material>
  </gazebo>
  <link name="center_leg_right_3">
    <visual>
      <geometry>
        <cylinder length="0.07" radius="0.006"/>
      </geometry>
      <material name="black"/>
    </visual>
    <collision>
      <geometry>
        <cylinder length="0.07" radius="0.006"/>
      </geometry>
    </collision>
    <inertial>
      <mass value="0.006"/>
      <inertia ixx="2.45e-06" ixy="0.0" ixz="0.0" iyy="2.45e-06" iyz="0.0" izz="0.0"/>
    </inertial>
  </link>
  <gazebo reference="center_leg_right_3">
    <material>Gazebo/Grey</material>
  </gazebo>
  <link name="inner_leg_right_3">
    <visual>
      <geometry>
        <cylinder length="0.07" radius="0.004"/>
      </geometry>
      <material name="black"/>
    </visual>
    <collision>
      <geometry>
        <cylinder length="0.07" radius="0.004"/>
      </geometry>
    </collision>
    <inertial>
      <mass value="0.004"/>
      <inertia ixx="1.6333333333333337e-06" ixy="0.0" ixz="0.0" iyy="1.6333333333333337e-06" iyz="0.0" izz="0.0"/>
    </inertial>
  </link>
  <gazebo reference="inner_leg_right_3">
    <material>Gazebo/Grey</material>
  </gazebo>
  <joint name="base_to_hip_right_3" type="fixed">
    <parent link="inner_outer_connector_right"/>
    <child link="hip_right_3"/>
    <origin rpy="0 2.356194490192345 0" xyz="0.04949747468305833 0 -0.049497474683058325"/>
  </joint>
  <joint name="hip_to_outer_leg_right_3" type="prismatic">
    <axis xyz="0 0 1"/>
    <parent link="hip_right_3"/>
    <child link="outer_leg_right_3"/>
    <limit effort="200.0" lower="0.0" upper="0.07" velocity="0.1"/>
    <origin rpy="0 0 0" xyz="0 0 0"/>
    <dynamics damping="100" friction="200"/>
  </joint>
  <gazebo reference="hip_to_outer_leg_right_3">
    <implicitSpringDamper>true</implicitSpringDamper>
  </gazebo>
  <joint name="outer_to_center_leg_right_3" type="prismatic">
    <axis xyz="0 0 1"/>
    <parent link="outer_leg_right_3"/>
    <child link="center_leg_right_3"/>
    <limit effort="200.0" lower="0.0" upper="0.07" velocity="0.1"/>
    <origin rpy="0 0 0" xyz="0 0 0"/>
    <dynamics damping="100" friction="200"/>
  </joint>
  <gazebo reference="outer_to_center_leg_right_3">
    <implicitSpringDamper>true</implicitSpringDamper>
  </gazebo>
  <joint name="center_to_inner_leg_right_3" type="prismatic">
    <axis xyz="0 0 1"/>
    <parent link="center_leg_right_3"/>
    <child link="inner_leg_right_3"/>
    <limit effort="200.0" lower="0.0" upper="0.07" velocity="0.1"/>
    <origin rpy="0 0 0" xyz="0 0 0"/>
    <dynamics damping="100" friction="200"/>
  </joint>
  <gazebo reference="center_to_inner_leg_right_3">
    <implicitSpringDamper>true</implicitSpringDamper>
  </gazebo>
  <transmission name="outer_leg_extension_right_3_trans" type="SimpleTransmission">
    <type>transmission_interface/SimpleTransmission</type>
    <actuator name="outer_leg_extension_right_3_motor">
      <hardwareInterface>hardware_interface/PositionJointInterface</hardwareInterface>
      <mechanicalReduction>1</mechanicalReduction>
    </actuator>
    <joint name="hip_to_outer_leg_right_3">
      <hardwareInterface>hardware_interface/PositionJointInterface</hardwareInterface>
    </joint>
  </transmission>
  <transmission name="center_leg_extension_right_3_trans" type="SimpleTransmission">
    <type>transmission_interface/SimpleTransmission</type>
    <actuator name="center_leg_extension_right_3_motor">
      <hardwareInterface>hardware_interface/PositionJointInterface</hardwareInterface>
      <mechanicalReduction>1</mechanicalReduction>
    </actuator>
    <joint name="outer_to_center_leg_right_3">
      <hardwareInterface>hardware_interface/PositionJointInterface</hardwareInterface>
    </joint>
  </transmission>
  <transmission name="inner_leg_extension_right_3_trans" type="SimpleTransmission">
    <type>transmission_interface/SimpleTransmission</type>
    <actuator name="inner_leg_extension_right_3_motor">
      <hardwareInterface>hardware_interface/PositionJointInterface</hardwareInterface>
      <mechanicalReduction>1</mechanicalReduction>
    </actuator>
    <joint name="center_to_inner_leg_right_3">
      <hardwareInterface>hardware_interface/PositionJointInterface</hardwareInterface>
    </joint>
  </transmission>
  <link name="hip_right_5">
    <visual>
      <geometry>
        <cylinder length="0.07" radius="0.01"/>
      </geometry>
      <material name="black"/>
    </visual>
    <collision>
      <geometry>
        <cylinder length="0.07" radius="0.01"/>
      </geometry>
    </collision>
    <inertial>
      <mass value="0.01"/>
      <inertia ixx="4.083333333333334e-06" ixy="0.0" ixz="0.0" iyy="0.0" iyz="0.0" izz="4.083333333333334e-06"/>
    </inertial>
  </link>
  <gazebo reference="hip_right_5">
    <material>Gazebo/Grey</material>
  </gazebo>
  <link name="outer_leg_right_5">
    <visual>
      <geometry>
        <cylinder length="0.07" radius="0.008"/>
      </geometry>
      <material name="black"/>
    </visual>
    <collision>
      <geometry>
        <cylinder length="0.07" radius="0.008"/>
      </geometry>
    </collision>
    <inertial>
      <mass value="0.008"/>
      <inertia ixx="3.2666666666666674e-06" ixy="0.0" ixz="0.0" iyy="0.0" iyz="0.0" izz="3.2666666666666674e-06"/>
    </inertial>
  </link>
  <gazebo reference="outer_leg_right_5">
    <material>Gazebo/Grey</material>
  </gazebo>
  <link name="center_leg_right_5">
    <visual>
      <geometry>
        <cylinder length="0.07" radius="0.006"/>
      </geometry>
      <material name="black"/>
    </visual>
    <collision>
      <geometry>
        <cylinder length="0.07" radius="0.006"/>
      </geometry>
    </collision>
    <inertial>
      <mass value="0.006"/>
      <inertia ixx="2.45e-06" ixy="0.0" ixz="0.0" iyy="2.45e-06" iyz="0.0" izz="0.0"/>
    </inertial>
  </link>
  <gazebo reference="center_leg_right_5">
    <material>Gazebo/Grey</material>
  </gazebo>
  <link name="inner_leg_right_5">
    <visual>
      <geometry>
        <cylinder length="0.07" radius="0.004"/>
      </geometry>
      <material name="black"/>
    </visual>
    <collision>
      <geometry>
        <cylinder length="0.07" radius="0.004"/>
      </geometry>
    </collision>
    <inertial>
      <mass value="0.004"/>
      <inertia ixx="1.6333333333333337e-06" ixy="0.0" ixz="0.0" iyy="1.6333333333333337e-06" iyz="0.0" izz="0.0"/>
    </inertial>
  </link>
  <gazebo reference="inner_leg_right_5">
    <material>Gazebo/Grey</material>
  </gazebo>
  <joint name="base_to_hip_right_5" type="fixed">
    <parent link="inner_outer_connector_right"/>
    <child link="hip_right_5"/>
    <origin rpy="0 3.9269908169872414 0" xyz="-0.049497474683058325 0 -0.049497474683058346"/>
  </joint>
  <joint name="hip_to_outer_leg_right_5" type="prismatic">
    <axis xyz="0 0 1"/>
    <parent link="hip_right_5"/>
    <child link="outer_leg_right_5"/>
    <limit effort="200.0" lower="0.0" upper="0.07" velocity="0.1"/>
    <origin rpy="0 0 0" xyz="0 0 0"/>
    <dynamics damping="100" friction="200"/>
  </joint>
  <gazebo reference="hip_to_outer_leg_right_5">
    <implicitSpringDamper>true</implicitSpringDamper>
  </gazebo>
  <joint name="outer_to_center_leg_right_5" type="prismatic">
    <axis xyz="0 0 1"/>
    <parent link="outer_leg_right_5"/>
    <child link="center_leg_right_5"/>
    <limit effort="200.0" lower="0.0" upper="0.07" velocity="0.1"/>
    <origin rpy="0 0 0" xyz="0 0 0"/>
    <dynamics damping="100" friction="200"/>
  </joint>
  <gazebo reference="outer_to_center_leg_right_5">
    <implicitSpringDamper>true</implicitSpringDamper>
  </gazebo>
  <joint name="center_to_inner_leg_right_5" type="prismatic">
    <axis xyz="0 0 1"/>
    <parent link="center_leg_right_5"/>
    <child link="inner_leg_right_5"/>
    <limit effort="200.0" lower="0.0" upper="0.07" velocity="0.1"/>
    <origin rpy="0 0 0" xyz="0 0 0"/>
    <dynamics damping="100" friction="200"/>
  </joint>
  <gazebo reference="center_to_inner_leg_right_5">
    <implicitSpringDamper>true</implicitSpringDamper>
  </gazebo>
  <transmission name="outer_leg_extension_right_5_trans" type="SimpleTransmission">
    <type>transmission_interface/SimpleTransmission</type>
    <actuator name="outer_leg_extension_right_5_motor">
      <hardwareInterface>hardware_interface/PositionJointInterface</hardwareInterface>
      <mechanicalReduction>1</mechanicalReduction>
    </actuator>
    <joint name="hip_to_outer_leg_right_5">
      <hardwareInterface>hardware_interface/PositionJointInterface</hardwareInterface>
    </joint>
  </transmission>
  <transmission name="center_leg_extension_right_5_trans" type="SimpleTransmission">
    <type>transmission_interface/SimpleTransmission</type>
    <actuator name="center_leg_extension_right_5_motor">
      <hardwareInterface>hardware_interface/PositionJointInterface</hardwareInterface>
      <mechanicalReduction>1</mechanicalReduction>
    </actuator>
    <joint name="outer_to_center_leg_right_5">
      <hardwareInterface>hardware_interface/PositionJointInterface</hardwareInterface>
    </joint>
  </transmission>
  <transmission name="inner_leg_extension_right_5_trans" type="SimpleTransmission">
    <type>transmission_interface/SimpleTransmission</type>
    <actuator name="inner_leg_extension_right_5_motor">
      <hardwareInterface>hardware_interface/PositionJointInterface</hardwareInterface>
      <mechanicalReduction>1</mechanicalReduction>
    </actuator>
    <joint name="center_to_inner_leg_right_5">
      <hardwareInterface>hardware_interface/PositionJointInterface</hardwareInterface>
    </joint>
  </transmission>
  <link name="hip_right_7">
    <visual>
      <geometry>
        <cylinder length="0.07" radius="0.01"/>
      </geometry>
      <material name="black"/>
    </visual>
    <collision>
      <geometry>
        <cylinder length="0.07" radius="0.01"/>
      </geometry>
    </collision>
    <inertial>
      <mass value="0.01"/>
      <inertia ixx="4.083333333333334e-06" ixy="0.0" ixz="0.0" iyy="0.0" iyz="0.0" izz="4.083333333333334e-06"/>
    </inertial>
  </link>
  <gazebo reference="hip_right_7">
    <material>Gazebo/Grey</material>
  </gazebo>
  <link name="outer_leg_right_7">
    <visual>
      <geometry>
        <cylinder length="0.07" radius="0.008"/>
      </geometry>
      <material name="black"/>
    </visual>
    <collision>
      <geometry>
        <cylinder length="0.07" radius="0.008"/>
      </geometry>
    </collision>
    <inertial>
      <mass value="0.008"/>
      <inertia ixx="3.2666666666666674e-06" ixy="0.0" ixz="0.0" iyy="0.0" iyz="0.0" izz="3.2666666666666674e-06"/>
    </inertial>
  </link>
  <gazebo reference="outer_leg_right_7">
    <material>Gazebo/Grey</material>
  </gazebo>
  <link name="center_leg_right_7">
    <visual>
      <geometry>
        <cylinder length="0.07" radius="0.006"/>
      </geometry>
      <material name="black"/>
    </visual>
    <collision>
      <geometry>
        <cylinder length="0.07" radius="0.006"/>
      </geometry>
    </collision>
    <inertial>
      <mass value="0.006"/>
      <inertia ixx="2.45e-06" ixy="0.0" ixz="0.0" iyy="2.45e-06" iyz="0.0" izz="0.0"/>
    </inertial>
  </link>
  <gazebo reference="center_leg_right_7">
    <material>Gazebo/Grey</material>
  </gazebo>
  <link name="inner_leg_right_7">
    <visual>
      <geometry>
        <cylinder length="0.07" radius="0.004"/>
      </geometry>
      <material name="black"/>
    </visual>
    <collision>
      <geometry>
        <cylinder length="0.07" radius="0.004"/>
      </geometry>
    </collision>
    <inertial>
      <mass value="0.004"/>
      <inertia ixx="1.6333333333333337e-06" ixy="0.0" ixz="0.0" iyy="1.6333333333333337e-06" iyz="0.0" izz="0.0"/>
    </inertial>
  </link>
  <gazebo reference="inner_leg_right_7">
    <material>Gazebo/Grey</material>
  </gazebo>
  <joint name="base_to_hip_right_7" type="fixed">
    <parent link="inner_outer_connector_right"/>
    <child link="hip_right_7"/>
    <origin rpy="0 5.497787143782138 0" xyz="-0.049497474683058346 0 0.04949747468305832"/>
  </joint>
  <joint name="hip_to_outer_leg_right_7" type="prismatic">
    <axis xyz="0 0 1"/>
    <parent link="hip_right_7"/>
    <child link="outer_leg_right_7"/>
    <limit effort="200.0" lower="0.0" upper="0.07" velocity="0.1"/>
    <origin rpy="0 0 0" xyz="0 0 0"/>
    <dynamics damping="100" friction="200"/>
  </joint>
  <gazebo reference="hip_to_outer_leg_right_7">
    <implicitSpringDamper>true</implicitSpringDamper>
  </gazebo>
  <joint name="outer_to_center_leg_right_7" type="prismatic">
    <axis xyz="0 0 1"/>
    <parent link="outer_leg_right_7"/>
    <child link="center_leg_right_7"/>
    <limit effort="200.0" lower="0.0" upper="0.07" velocity="0.1"/>
    <origin rpy="0 0 0" xyz="0 0 0"/>
    <dynamics damping="100" friction="200"/>
  </joint>
  <gazebo reference="outer_to_center_leg_right_7">
    <implicitSpringDamper>true</implicitSpringDamper>
  </gazebo>
  <joint name="center_to_inner_leg_right_7" type="prismatic">
    <axis xyz="0 0 1"/>
    <parent link="center_leg_right_7"/>
    <child link="inner_leg_right_7"/>
    <limit effort="200.0" lower="0.0" upper="0.07" velocity="0.1"/>
    <origin rpy="0 0 0" xyz="0 0 0"/>
    <dynamics damping="100" friction="200"/>
  </joint>
  <gazebo reference="center_to_inner_leg_right_7">
    <implicitSpringDamper>true</implicitSpringDamper>
  </gazebo>
  <transmission name="outer_leg_extension_right_7_trans" type="SimpleTransmission">
    <type>transmission_interface/SimpleTransmission</type>
    <actuator name="outer_leg_extension_right_7_motor">
      <hardwareInterface>hardware_interface/PositionJointInterface</hardwareInterface>
      <mechanicalReduction>1</mechanicalReduction>
    </actuator>
    <joint name="hip_to_outer_leg_right_7">
      <hardwareInterface>hardware_interface/PositionJointInterface</hardwareInterface>
    </joint>
  </transmission>
  <transmission name="center_leg_extension_right_7_trans" type="SimpleTransmission">
    <type>transmission_interface/SimpleTransmission</type>
    <actuator name="center_leg_extension_right_7_motor">
      <hardwareInterface>hardware_interface/PositionJointInterface</hardwareInterface>
      <mechanicalReduction>1</mechanicalReduction>
    </actuator>
    <joint name="outer_to_center_leg_right_7">
      <hardwareInterface>hardware_interface/PositionJointInterface</hardwareInterface>
    </joint>
  </transmission>
  <transmission name="inner_leg_extension_right_7_trans" type="SimpleTransmission">
    <type>transmission_interface/SimpleTransmission</type>
    <actuator name="inner_leg_extension_right_7_motor">
      <hardwareInterface>hardware_interface/PositionJointInterface</hardwareInterface>
      <mechanicalReduction>1</mechanicalReduction>
    </actuator>
    <joint name="center_to_inner_leg_right_7">
      <hardwareInterface>hardware_interface/PositionJointInterface</hardwareInterface>
    </joint>
  </transmission>
  <link name="hip_left_0">
    <visual>
      <geometry>
        <cylinder length="0.07" radius="0.01"/>
      </geometry>
      <material name="black"/>
    </visual>
    <collision>
      <geometry>
        <cylinder length="0.07" radius="0.01"/>
      </geometry>
    </collision>
    <inertial>
      <mass value="0.01"/>
      <inertia ixx="4.083333333333334e-06" ixy="0.0" ixz="0.0" iyy="0.0" iyz="0.0" izz="4.083333333333334e-06"/>
    </inertial>
  </link>
  <gazebo reference="hip_left_0">
    <material>Gazebo/Grey</material>
  </gazebo>
  <link name="outer_leg_left_0">
    <visual>
      <geometry>
        <cylinder length="0.07" radius="0.008"/>
      </geometry>
      <material name="black"/>
    </visual>
    <collision>
      <geometry>
        <cylinder length="0.07" radius="0.008"/>
      </geometry>
    </collision>
    <inertial>
      <mass value="0.008"/>
      <inertia ixx="3.2666666666666674e-06" ixy="0.0" ixz="0.0" iyy="0.0" iyz="0.0" izz="3.2666666666666674e-06"/>
    </inertial>
  </link>
  <gazebo reference="outer_leg_left_0">
    <material>Gazebo/Grey</material>
  </gazebo>
  <link name="center_leg_left_0">
    <visual>
      <geometry>
        <cylinder length="0.07" radius="0.006"/>
      </geometry>
      <material name="black"/>
    </visual>
    <collision>
      <geometry>
        <cylinder length="0.07" radius="0.006"/>
      </geometry>
    </collision>
    <inertial>
      <mass value="0.006"/>
      <inertia ixx="2.45e-06" ixy="0.0" ixz="0.0" iyy="2.45e-06" iyz="0.0" izz="0.0"/>
    </inertial>
  </link>
  <gazebo reference="center_leg_left_0">
    <material>Gazebo/Grey</material>
  </gazebo>
  <link name="inner_leg_left_0">
    <visual>
      <geometry>
        <cylinder length="0.07" radius="0.004"/>
      </geometry>
      <material name="black"/>
    </visual>
    <collision>
      <geometry>
        <cylinder length="0.07" radius="0.004"/>
      </geometry>
    </collision>
    <inertial>
      <mass value="0.004"/>
      <inertia ixx="1.6333333333333337e-06" ixy="0.0" ixz="0.0" iyy="1.6333333333333337e-06" iyz="0.0" izz="0.0"/>
    </inertial>
  </link>
  <gazebo reference="inner_leg_left_0">
    <material>Gazebo/Grey</material>
  </gazebo>
  <joint name="base_to_hip_left_0" type="fixed">
    <parent link="inner_outer_connector_left"/>
    <child link="hip_left_0"/>
    <origin rpy="0 0.0 0" xyz="0.0 0 0.07"/>
  </joint>
  <joint name="hip_to_outer_leg_left_0" type="prismatic">
    <axis xyz="0 0 1"/>
    <parent link="hip_left_0"/>
    <child link="outer_leg_left_0"/>
    <limit effort="200.0" lower="0.0" upper="0.07" velocity="0.1"/>
    <origin rpy="0 0 0" xyz="0 0 0"/>
    <dynamics damping="100" friction="200"/>
  </joint>
  <gazebo reference="hip_to_outer_leg_left_0">
    <implicitSpringDamper>true</implicitSpringDamper>
  </gazebo>
  <joint name="outer_to_center_leg_left_0" type="prismatic">
    <axis xyz="0 0 1"/>
    <parent link="outer_leg_left_0"/>
    <child link="center_leg_left_0"/>
    <limit effort="200.0" lower="0.0" upper="0.07" velocity="0.1"/>
    <origin rpy="0 0 0" xyz="0 0 0"/>
    <dynamics damping="100" friction="200"/>
  </joint>
  <gazebo reference="outer_to_center_leg_left_0">
    <implicitSpringDamper>true</implicitSpringDamper>
  </gazebo>
  <joint name="center_to_inner_leg_left_0" type="prismatic">
    <axis xyz="0 0 1"/>
    <parent link="center_leg_left_0"/>
    <child link="inner_leg_left_0"/>
    <limit effort="200.0" lower="0.0" upper="0.07" velocity="0.1"/>
    <origin rpy="0 0 0" xyz="0 0 0"/>
    <dynamics damping="100" friction="200"/>
  </joint>
  <gazebo reference="center_to_inner_leg_left_0">
    <implicitSpringDamper>true</implicitSpringDamper>
  </gazebo>
  <transmission name="outer_leg_extension_left_0_trans" type="SimpleTransmission">
    <type>transmission_interface/SimpleTransmission</type>
    <actuator name="outer_leg_extension_left_0_motor">
      <hardwareInterface>hardware_interface/PositionJointInterface</hardwareInterface>
      <mechanicalReduction>1</mechanicalReduction>
    </actuator>
    <joint name="hip_to_outer_leg_left_0">
      <hardwareInterface>hardware_interface/PositionJointInterface</hardwareInterface>
    </joint>
  </transmission>
  <transmission name="center_leg_extension_left_0_trans" type="SimpleTransmission">
    <type>transmission_interface/SimpleTransmission</type>
    <actuator name="center_leg_extension_left_0_motor">
      <hardwareInterface>hardware_interface/PositionJointInterface</hardwareInterface>
      <mechanicalReduction>1</mechanicalReduction>
    </actuator>
    <joint name="outer_to_center_leg_left_0">
      <hardwareInterface>hardware_interface/PositionJointInterface</hardwareInterface>
    </joint>
  </transmission>
  <transmission name="inner_leg_extension_left_0_trans" type="SimpleTransmission">
    <type>transmission_interface/SimpleTransmission</type>
    <actuator name="inner_leg_extension_left_0_motor">
      <hardwareInterface>hardware_interface/PositionJointInterface</hardwareInterface>
      <mechanicalReduction>1</mechanicalReduction>
    </actuator>
    <joint name="center_to_inner_leg_left_0">
      <hardwareInterface>hardware_interface/PositionJointInterface</hardwareInterface>
    </joint>
  </transmission>
  <link name="hip_left_2">
    <visual>
      <geometry>
        <cylinder length="0.07" radius="0.01"/>
      </geometry>
      <material name="black"/>
    </visual>
    <collision>
      <geometry>
        <cylinder length="0.07" radius="0.01"/>
      </geometry>
    </collision>
    <inertial>
      <mass value="0.01"/>
      <inertia ixx="4.083333333333334e-06" ixy="0.0" ixz="0.0" iyy="0.0" iyz="0.0" izz="4.083333333333334e-06"/>
    </inertial>
  </link>
  <gazebo reference="hip_left_2">
    <material>Gazebo/Grey</material>
  </gazebo>
  <link name="outer_leg_left_2">
    <visual>
      <geometry>
        <cylinder length="0.07" radius="0.008"/>
      </geometry>
      <material name="black"/>
    </visual>
    <collision>
      <geometry>
        <cylinder length="0.07" radius="0.008"/>
      </geometry>
    </collision>
    <inertial>
      <mass value="0.008"/>
      <inertia ixx="3.2666666666666674e-06" ixy="0.0" ixz="0.0" iyy="0.0" iyz="0.0" izz="3.2666666666666674e-06"/>
    </inertial>
  </link>
  <gazebo reference="outer_leg_left_2">
    <material>Gazebo/Grey</material>
  </gazebo>
  <link name="center_leg_left_2">
    <visual>
      <geometry>
        <cylinder length="0.07" radius="0.006"/>
      </geometry>
      <material name="black"/>
    </visual>
    <collision>
      <geometry>
        <cylinder length="0.07" radius="0.006"/>
      </geometry>
    </collision>
    <inertial>
      <mass value="0.006"/>
      <inertia ixx="2.45e-06" ixy="0.0" ixz="0.0" iyy="2.45e-06" iyz="0.0" izz="0.0"/>
    </inertial>
  </link>
  <gazebo reference="center_leg_left_2">
    <material>Gazebo/Grey</material>
  </gazebo>
  <link name="inner_leg_left_2">
    <visual>
      <geometry>
        <cylinder length="0.07" radius="0.004"/>
      </geometry>
      <material name="black"/>
    </visual>
    <collision>
      <geometry>
        <cylinder length="0.07" radius="0.004"/>
      </geometry>
    </collision>
    <inertial>
      <mass value="0.004"/>
      <inertia ixx="1.6333333333333337e-06" ixy="0.0" ixz="0.0" iyy="1.6333333333333337e-06" iyz="0.0" izz="0.0"/>
    </inertial>
  </link>
  <gazebo reference="inner_leg_left_2">
    <material>Gazebo/Grey</material>
  </gazebo>
  <joint name="base_to_hip_left_2" type="fixed">
    <parent link="inner_outer_connector_left"/>
    <child link="hip_left_2"/>
    <origin rpy="0 1.5707963267948966 0" xyz="0.07 0 4.286263797015737e-18"/>
  </joint>
  <joint name="hip_to_outer_leg_left_2" type="prismatic">
    <axis xyz="0 0 1"/>
    <parent link="hip_left_2"/>
    <child link="outer_leg_left_2"/>
    <limit effort="200.0" lower="0.0" upper="0.07" velocity="0.1"/>
    <origin rpy="0 0 0" xyz="0 0 0"/>
    <dynamics damping="100" friction="200"/>
  </joint>
  <gazebo reference="hip_to_outer_leg_left_2">
    <implicitSpringDamper>true</implicitSpringDamper>
  </gazebo>
  <joint name="outer_to_center_leg_left_2" type="prismatic">
    <axis xyz="0 0 1"/>
    <parent link="outer_leg_left_2"/>
    <child link="center_leg_left_2"/>
    <limit effort="200.0" lower="0.0" upper="0.07" velocity="0.1"/>
    <origin rpy="0 0 0" xyz="0 0 0"/>
    <dynamics damping="100" friction="200"/>
  </joint>
  <gazebo reference="outer_to_center_leg_left_2">
    <implicitSpringDamper>true</implicitSpringDamper>
  </gazebo>
  <joint name="center_to_inner_leg_left_2" type="prismatic">
    <axis xyz="0 0 1"/>
    <parent link="center_leg_left_2"/>
    <child link="inner_leg_left_2"/>
    <limit effort="200.0" lower="0.0" upper="0.07" velocity="0.1"/>
    <origin rpy="0 0 0" xyz="0 0 0"/>
    <dynamics damping="100" friction="200"/>
  </joint>
  <gazebo reference="center_to_inner_leg_left_2">
    <implicitSpringDamper>true</implicitSpringDamper>
  </gazebo>
  <transmission name="outer_leg_extension_left_2_trans" type="SimpleTransmission">
    <type>transmission_interface/SimpleTransmission</type>
    <actuator name="outer_leg_extension_left_2_motor">
      <hardwareInterface>hardware_interface/PositionJointInterface</hardwareInterface>
      <mechanicalReduction>1</mechanicalReduction>
    </actuator>
    <joint name="hip_to_outer_leg_left_2">
      <hardwareInterface>hardware_interface/PositionJointInterface</hardwareInterface>
    </joint>
  </transmission>
  <transmission name="center_leg_extension_left_2_trans" type="SimpleTransmission">
    <type>transmission_interface/SimpleTransmission</type>
    <actuator name="center_leg_extension_left_2_motor">
      <hardwareInterface>hardware_interface/PositionJointInterface</hardwareInterface>
      <mechanicalReduction>1</mechanicalReduction>
    </actuator>
    <joint name="outer_to_center_leg_left_2">
      <hardwareInterface>hardware_interface/PositionJointInterface</hardwareInterface>
    </joint>
  </transmission>
  <transmission name="inner_leg_extension_left_2_trans" type="SimpleTransmission">
    <type>transmission_interface/SimpleTransmission</type>
    <actuator name="inner_leg_extension_left_2_motor">
      <hardwareInterface>hardware_interface/PositionJointInterface</hardwareInterface>
      <mechanicalReduction>1</mechanicalReduction>
    </actuator>
    <joint name="center_to_inner_leg_left_2">
      <hardwareInterface>hardware_interface/PositionJointInterface</hardwareInterface>
    </joint>
  </transmission>
  <link name="hip_left_4">
    <visual>
      <geometry>
        <cylinder length="0.07" radius="0.01"/>
      </geometry>
      <material name="black"/>
    </visual>
    <collision>
      <geometry>
        <cylinder length="0.07" radius="0.01"/>
      </geometry>
    </collision>
    <inertial>
      <mass value="0.01"/>
      <inertia ixx="4.083333333333334e-06" ixy="0.0" ixz="0.0" iyy="0.0" iyz="0.0" izz="4.083333333333334e-06"/>
    </inertial>
  </link>
  <gazebo reference="hip_left_4">
    <material>Gazebo/Grey</material>
  </gazebo>
  <link name="outer_leg_left_4">
    <visual>
      <geometry>
        <cylinder length="0.07" radius="0.008"/>
      </geometry>
      <material name="black"/>
    </visual>
    <collision>
      <geometry>
        <cylinder length="0.07" radius="0.008"/>
      </geometry>
    </collision>
    <inertial>
      <mass value="0.008"/>
      <inertia ixx="3.2666666666666674e-06" ixy="0.0" ixz="0.0" iyy="0.0" iyz="0.0" izz="3.2666666666666674e-06"/>
    </inertial>
  </link>
  <gazebo reference="outer_leg_left_4">
    <material>Gazebo/Grey</material>
  </gazebo>
  <link name="center_leg_left_4">
    <visual>
      <geometry>
        <cylinder length="0.07" radius="0.006"/>
      </geometry>
      <material name="black"/>
    </visual>
    <collision>
      <geometry>
        <cylinder length="0.07" radius="0.006"/>
      </geometry>
    </collision>
    <inertial>
      <mass value="0.006"/>
      <inertia ixx="2.45e-06" ixy="0.0" ixz="0.0" iyy="2.45e-06" iyz="0.0" izz="0.0"/>
    </inertial>
  </link>
  <gazebo reference="center_leg_left_4">
    <material>Gazebo/Grey</material>
  </gazebo>
  <link name="inner_leg_left_4">
    <visual>
      <geometry>
        <cylinder length="0.07" radius="0.004"/>
      </geometry>
      <material name="black"/>
    </visual>
    <collision>
      <geometry>
        <cylinder length="0.07" radius="0.004"/>
      </geometry>
    </collision>
    <inertial>
      <mass value="0.004"/>
      <inertia ixx="1.6333333333333337e-06" ixy="0.0" ixz="0.0" iyy="1.6333333333333337e-06" iyz="0.0" izz="0.0"/>
    </inertial>
  </link>
  <gazebo reference="inner_leg_left_4">
    <material>Gazebo/Grey</material>
  </gazebo>
  <joint name="base_to_hip_left_4" type="fixed">
    <parent link="inner_outer_connector_left"/>
    <child link="hip_left_4"/>
    <origin rpy="0 3.141592653589793 0" xyz="8.572527594031473e-18 0 -0.07"/>
  </joint>
  <joint name="hip_to_outer_leg_left_4" type="prismatic">
    <axis xyz="0 0 1"/>
    <parent link="hip_left_4"/>
    <child link="outer_leg_left_4"/>
    <limit effort="200.0" lower="0.0" upper="0.07" velocity="0.1"/>
    <origin rpy="0 0 0" xyz="0 0 0"/>
    <dynamics damping="100" friction="200"/>
  </joint>
  <gazebo reference="hip_to_outer_leg_left_4">
    <implicitSpringDamper>true</implicitSpringDamper>
  </gazebo>
  <joint name="outer_to_center_leg_left_4" type="prismatic">
    <axis xyz="0 0 1"/>
    <parent link="outer_leg_left_4"/>
    <child link="center_leg_left_4"/>
    <limit effort="200.0" lower="0.0" upper="0.07" velocity="0.1"/>
    <origin rpy="0 0 0" xyz="0 0 0"/>
    <dynamics damping="100" friction="200"/>
  </joint>
  <gazebo reference="outer_to_center_leg_left_4">
    <implicitSpringDamper>true</implicitSpringDamper>
  </gazebo>
  <joint name="center_to_inner_leg_left_4" type="prismatic">
    <axis xyz="0 0 1"/>
    <parent link="center_leg_left_4"/>
    <child link="inner_leg_left_4"/>
    <limit effort="200.0" lower="0.0" upper="0.07" velocity="0.1"/>
    <origin rpy="0 0 0" xyz="0 0 0"/>
    <dynamics damping="100" friction="200"/>
  </joint>
  <gazebo reference="center_to_inner_leg_left_4">
    <implicitSpringDamper>true</implicitSpringDamper>
  </gazebo>
  <transmission name="outer_leg_extension_left_4_trans" type="SimpleTransmission">
    <type>transmission_interface/SimpleTransmission</type>
    <actuator name="outer_leg_extension_left_4_motor">
      <hardwareInterface>hardware_interface/PositionJointInterface</hardwareInterface>
      <mechanicalReduction>1</mechanicalReduction>
    </actuator>
    <joint name="hip_to_outer_leg_left_4">
      <hardwareInterface>hardware_interface/PositionJointInterface</hardwareInterface>
    </joint>
  </transmission>
  <transmission name="center_leg_extension_left_4_trans" type="SimpleTransmission">
    <type>transmission_interface/SimpleTransmission</type>
    <actuator name="center_leg_extension_left_4_motor">
      <hardwareInterface>hardware_interface/PositionJointInterface</hardwareInterface>
      <mechanicalReduction>1</mechanicalReduction>
    </actuator>
    <joint name="outer_to_center_leg_left_4">
      <hardwareInterface>hardware_interface/PositionJointInterface</hardwareInterface>
    </joint>
  </transmission>
  <transmission name="inner_leg_extension_left_4_trans" type="SimpleTransmission">
    <type>transmission_interface/SimpleTransmission</type>
    <actuator name="inner_leg_extension_left_4_motor">
      <hardwareInterface>hardware_interface/PositionJointInterface</hardwareInterface>
      <mechanicalReduction>1</mechanicalReduction>
    </actuator>
    <joint name="center_to_inner_leg_left_4">
      <hardwareInterface>hardware_interface/PositionJointInterface</hardwareInterface>
    </joint>
  </transmission>
  <link name="hip_left_6">
    <visual>
      <geometry>
        <cylinder length="0.07" radius="0.01"/>
      </geometry>
      <material name="black"/>
    </visual>
    <collision>
      <geometry>
        <cylinder length="0.07" radius="0.01"/>
      </geometry>
    </collision>
    <inertial>
      <mass value="0.01"/>
      <inertia ixx="4.083333333333334e-06" ixy="0.0" ixz="0.0" iyy="0.0" iyz="0.0" izz="4.083333333333334e-06"/>
    </inertial>
  </link>
  <gazebo reference="hip_left_6">
    <material>Gazebo/Grey</material>
  </gazebo>
  <link name="outer_leg_left_6">
    <visual>
      <geometry>
        <cylinder length="0.07" radius="0.008"/>
      </geometry>
      <material name="black"/>
    </visual>
    <collision>
      <geometry>
        <cylinder length="0.07" radius="0.008"/>
      </geometry>
    </collision>
    <inertial>
      <mass value="0.008"/>
      <inertia ixx="3.2666666666666674e-06" ixy="0.0" ixz="0.0" iyy="0.0" iyz="0.0" izz="3.2666666666666674e-06"/>
    </inertial>
  </link>
  <gazebo reference="outer_leg_left_6">
    <material>Gazebo/Grey</material>
  </gazebo>
  <link name="center_leg_left_6">
    <visual>
      <geometry>
        <cylinder length="0.07" radius="0.006"/>
      </geometry>
      <material name="black"/>
    </visual>
    <collision>
      <geometry>
        <cylinder length="0.07" radius="0.006"/>
      </geometry>
    </collision>
    <inertial>
      <mass value="0.006"/>
      <inertia ixx="2.45e-06" ixy="0.0" ixz="0.0" iyy="2.45e-06" iyz="0.0" izz="0.0"/>
    </inertial>
  </link>
  <gazebo reference="center_leg_left_6">
    <material>Gazebo/Grey</material>
  </gazebo>
  <link name="inner_leg_left_6">
    <visual>
      <geometry>
        <cylinder length="0.07" radius="0.004"/>
      </geometry>
      <material name="black"/>
    </visual>
    <collision>
      <geometry>
        <cylinder length="0.07" radius="0.004"/>
      </geometry>
    </collision>
    <inertial>
      <mass value="0.004"/>
      <inertia ixx="1.6333333333333337e-06" ixy="0.0" ixz="0.0" iyy="1.6333333333333337e-06" iyz="0.0" izz="0.0"/>
    </inertial>
  </link>
  <gazebo reference="inner_leg_left_6">
    <material>Gazebo/Grey</material>
  </gazebo>
  <joint name="base_to_hip_left_6" type="fixed">
    <parent link="inner_outer_connector_left"/>
    <child link="hip_left_6"/>
    <origin rpy="0 4.71238898038469 0" xyz="-0.07 0 -1.285879139104721e-17"/>
  </joint>
  <joint name="hip_to_outer_leg_left_6" type="prismatic">
    <axis xyz="0 0 1"/>
    <parent link="hip_left_6"/>
    <child link="outer_leg_left_6"/>
    <limit effort="200.0" lower="0.0" upper="0.07" velocity="0.1"/>
    <origin rpy="0 0 0" xyz="0 0 0"/>
    <dynamics damping="100" friction="200"/>
  </joint>
  <gazebo reference="hip_to_outer_leg_left_6">
    <implicitSpringDamper>true</implicitSpringDamper>
  </gazebo>
  <joint name="outer_to_center_leg_left_6" type="prismatic">
    <axis xyz="0 0 1"/>
    <parent link="outer_leg_left_6"/>
    <child link="center_leg_left_6"/>
    <limit effort="200.0" lower="0.0" upper="0.07" velocity="0.1"/>
    <origin rpy="0 0 0" xyz="0 0 0"/>
    <dynamics damping="100" friction="200"/>
  </joint>
  <gazebo reference="outer_to_center_leg_left_6">
    <implicitSpringDamper>true</implicitSpringDamper>
  </gazebo>
  <joint name="center_to_inner_leg_left_6" type="prismatic">
    <axis xyz="0 0 1"/>
    <parent link="center_leg_left_6"/>
    <child link="inner_leg_left_6"/>
    <limit effort="200.0" lower="0.0" upper="0.07" velocity="0.1"/>
    <origin rpy="0 0 0" xyz="0 0 0"/>
    <dynamics damping="100" friction="200"/>
  </joint>
  <gazebo reference="center_to_inner_leg_left_6">
    <implicitSpringDamper>true</implicitSpringDamper>
  </gazebo>
  <transmission name="outer_leg_extension_left_6_trans" type="SimpleTransmission">
    <type>transmission_interface/SimpleTransmission</type>
    <actuator name="outer_leg_extension_left_6_motor">
      <hardwareInterface>hardware_interface/PositionJointInterface</hardwareInterface>
      <mechanicalReduction>1</mechanicalReduction>
    </actuator>
    <joint name="hip_to_outer_leg_left_6">
      <hardwareInterface>hardware_interface/PositionJointInterface</hardwareInterface>
    </joint>
  </transmission>
  <transmission name="center_leg_extension_left_6_trans" type="SimpleTransmission">
    <type>transmission_interface/SimpleTransmission</type>
    <actuator name="center_leg_extension_left_6_motor">
      <hardwareInterface>hardware_interface/PositionJointInterface</hardwareInterface>
      <mechanicalReduction>1</mechanicalReduction>
    </actuator>
    <joint name="outer_to_center_leg_left_6">
      <hardwareInterface>hardware_interface/PositionJointInterface</hardwareInterface>
    </joint>
  </transmission>
  <transmission name="inner_leg_extension_left_6_trans" type="SimpleTransmission">
    <type>transmission_interface/SimpleTransmission</type>
    <actuator name="inner_leg_extension_left_6_motor">
      <hardwareInterface>hardware_interface/PositionJointInterface</hardwareInterface>
      <mechanicalReduction>1</mechanicalReduction>
    </actuator>
    <joint name="center_to_inner_leg_left_6">
      <hardwareInterface>hardware_interface/PositionJointInterface</hardwareInterface>
    </joint>
  </transmission>
  <link name="hip_left_1">
    <visual>
      <geometry>
        <cylinder length="0.07" radius="0.01"/>
      </geometry>
      <material name="black"/>
    </visual>
    <collision>
      <geometry>
        <cylinder length="0.07" radius="0.01"/>
      </geometry>
    </collision>
    <inertial>
      <mass value="0.01"/>
      <inertia ixx="4.083333333333334e-06" ixy="0.0" ixz="0.0" iyy="0.0" iyz="0.0" izz="4.083333333333334e-06"/>
    </inertial>
  </link>
  <gazebo reference="hip_left_1">
    <material>Gazebo/Grey</material>
  </gazebo>
  <link name="outer_leg_left_1">
    <visual>
      <geometry>
        <cylinder length="0.07" radius="0.008"/>
      </geometry>
      <material name="black"/>
    </visual>
    <collision>
      <geometry>
        <cylinder length="0.07" radius="0.008"/>
      </geometry>
    </collision>
    <inertial>
      <mass value="0.008"/>
      <inertia ixx="3.2666666666666674e-06" ixy="0.0" ixz="0.0" iyy="0.0" iyz="0.0" izz="3.2666666666666674e-06"/>
    </inertial>
  </link>
  <gazebo reference="outer_leg_left_1">
    <material>Gazebo/Grey</material>
  </gazebo>
  <link name="center_leg_left_1">
    <visual>
      <geometry>
        <cylinder length="0.07" radius="0.006"/>
      </geometry>
      <material name="black"/>
    </visual>
    <collision>
      <geometry>
        <cylinder length="0.07" radius="0.006"/>
      </geometry>
    </collision>
    <inertial>
      <mass value="0.006"/>
      <inertia ixx="2.45e-06" ixy="0.0" ixz="0.0" iyy="2.45e-06" iyz="0.0" izz="0.0"/>
    </inertial>
  </link>
  <gazebo reference="center_leg_left_1">
    <material>Gazebo/Grey</material>
  </gazebo>
  <link name="inner_leg_left_1">
    <visual>
      <geometry>
        <cylinder length="0.07" radius="0.004"/>
      </geometry>
      <material name="black"/>
    </visual>
    <collision>
      <geometry>
        <cylinder length="0.07" radius="0.004"/>
      </geometry>
    </collision>
    <inertial>
      <mass value="0.004"/>
      <inertia ixx="1.6333333333333337e-06" ixy="0.0" ixz="0.0" iyy="1.6333333333333337e-06" iyz="0.0" izz="0.0"/>
    </inertial>
  </link>
  <gazebo reference="inner_leg_left_1">
    <material>Gazebo/Grey</material>
  </gazebo>
  <joint name="base_to_hip_left_1" type="fixed">
    <parent link="inner_outer_connector_left"/>
    <child link="hip_left_1"/>
    <origin rpy="0 0.7853981633974483 0" xyz="0.049497474683058325 0 0.04949747468305833"/>
  </joint>
  <joint name="hip_to_outer_leg_left_1" type="prismatic">
    <axis xyz="0 0 1"/>
    <parent link="hip_left_1"/>
    <child link="outer_leg_left_1"/>
    <limit effort="200.0" lower="0.0" upper="0.07" velocity="0.1"/>
    <origin rpy="0 0 0" xyz="0 0 0"/>
    <dynamics damping="100" friction="200"/>
  </joint>
  <gazebo reference="hip_to_outer_leg_left_1">
    <implicitSpringDamper>true</implicitSpringDamper>
  </gazebo>
  <joint name="outer_to_center_leg_left_1" type="prismatic">
    <axis xyz="0 0 1"/>
    <parent link="outer_leg_left_1"/>
    <child link="center_leg_left_1"/>
    <limit effort="200.0" lower="0.0" upper="0.07" velocity="0.1"/>
    <origin rpy="0 0 0" xyz="0 0 0"/>
    <dynamics damping="100" friction="200"/>
  </joint>
  <gazebo reference="outer_to_center_leg_left_1">
    <implicitSpringDamper>true</implicitSpringDamper>
  </gazebo>
  <joint name="center_to_inner_leg_left_1" type="prismatic">
    <axis xyz="0 0 1"/>
    <parent link="center_leg_left_1"/>
    <child link="inner_leg_left_1"/>
    <limit effort="200.0" lower="0.0" upper="0.07" velocity="0.1"/>
    <origin rpy="0 0 0" xyz="0 0 0"/>
    <dynamics damping="100" friction="200"/>
  </joint>
  <gazebo reference="center_to_inner_leg_left_1">
    <implicitSpringDamper>true</implicitSpringDamper>
  </gazebo>
  <transmission name="outer_leg_extension_left_1_trans" type="SimpleTransmission">
    <type>transmission_interface/SimpleTransmission</type>
    <actuator name="outer_leg_extension_left_1_motor">
      <hardwareInterface>hardware_interface/PositionJointInterface</hardwareInterface>
      <mechanicalReduction>1</mechanicalReduction>
    </actuator>
    <joint name="hip_to_outer_leg_left_1">
      <hardwareInterface>hardware_interface/PositionJointInterface</hardwareInterface>
    </joint>
  </transmission>
  <transmission name="center_leg_extension_left_1_trans" type="SimpleTransmission">
    <type>transmission_interface/SimpleTransmission</type>
    <actuator name="center_leg_extension_left_1_motor">
      <hardwareInterface>hardware_interface/PositionJointInterface</hardwareInterface>
      <mechanicalReduction>1</mechanicalReduction>
    </actuator>
    <joint name="outer_to_center_leg_left_1">
      <hardwareInterface>hardware_interface/PositionJointInterface</hardwareInterface>
    </joint>
  </transmission>
  <transmission name="inner_leg_extension_left_1_trans" type="SimpleTransmission">
    <type>transmission_interface/SimpleTransmission</type>
    <actuator name="inner_leg_extension_left_1_motor">
      <hardwareInterface>hardware_interface/PositionJointInterface</hardwareInterface>
      <mechanicalReduction>1</mechanicalReduction>
    </actuator>
    <joint name="center_to_inner_leg_left_1">
      <hardwareInterface>hardware_interface/PositionJointInterface</hardwareInterface>
    </joint>
  </transmission>
  <link name="hip_left_3">
    <visual>
      <geometry>
        <cylinder length="0.07" radius="0.01"/>
      </geometry>
      <material name="black"/>
    </visual>
    <collision>
      <geometry>
        <cylinder length="0.07" radius="0.01"/>
      </geometry>
    </collision>
    <inertial>
      <mass value="0.01"/>
      <inertia ixx="4.083333333333334e-06" ixy="0.0" ixz="0.0" iyy="0.0" iyz="0.0" izz="4.083333333333334e-06"/>
    </inertial>
  </link>
  <gazebo reference="hip_left_3">
    <material>Gazebo/Grey</material>
  </gazebo>
  <link name="outer_leg_left_3">
    <visual>
      <geometry>
        <cylinder length="0.07" radius="0.008"/>
      </geometry>
      <material name="black"/>
    </visual>
    <collision>
      <geometry>
        <cylinder length="0.07" radius="0.008"/>
      </geometry>
    </collision>
    <inertial>
      <mass value="0.008"/>
      <inertia ixx="3.2666666666666674e-06" ixy="0.0" ixz="0.0" iyy="0.0" iyz="0.0" izz="3.2666666666666674e-06"/>
    </inertial>
  </link>
  <gazebo reference="outer_leg_left_3">
    <material>Gazebo/Grey</material>
  </gazebo>
  <link name="center_leg_left_3">
    <visual>
      <geometry>
        <cylinder length="0.07" radius="0.006"/>
      </geometry>
      <material name="black"/>
    </visual>
    <collision>
      <geometry>
        <cylinder length="0.07" radius="0.006"/>
      </geometry>
    </collision>
    <inertial>
      <mass value="0.006"/>
      <inertia ixx="2.45e-06" ixy="0.0" ixz="0.0" iyy="2.45e-06" iyz="0.0" izz="0.0"/>
    </inertial>
  </link>
  <gazebo reference="center_leg_left_3">
    <material>Gazebo/Grey</material>
  </gazebo>
  <link name="inner_leg_left_3">
    <visual>
      <geometry>
        <cylinder length="0.07" radius="0.004"/>
      </geometry>
      <material name="black"/>
    </visual>
    <collision>
      <geometry>
        <cylinder length="0.07" radius="0.004"/>
      </geometry>
    </collision>
    <inertial>
      <mass value="0.004"/>
      <inertia ixx="1.6333333333333337e-06" ixy="0.0" ixz="0.0" iyy="1.6333333333333337e-06" iyz="0.0" izz="0.0"/>
    </inertial>
  </link>
  <gazebo reference="inner_leg_left_3">
    <material>Gazebo/Grey</material>
  </gazebo>
  <joint name="base_to_hip_left_3" type="fixed">
    <parent link="inner_outer_connector_left"/>
    <child link="hip_left_3"/>
    <origin rpy="0 2.356194490192345 0" xyz="0.04949747468305833 0 -0.049497474683058325"/>
  </joint>
  <joint name="hip_to_outer_leg_left_3" type="prismatic">
    <axis xyz="0 0 1"/>
    <parent link="hip_left_3"/>
    <child link="outer_leg_left_3"/>
    <limit effort="200.0" lower="0.0" upper="0.07" velocity="0.1"/>
    <origin rpy="0 0 0" xyz="0 0 0"/>
    <dynamics damping="100" friction="200"/>
  </joint>
  <gazebo reference="hip_to_outer_leg_left_3">
    <implicitSpringDamper>true</implicitSpringDamper>
  </gazebo>
  <joint name="outer_to_center_leg_left_3" type="prismatic">
    <axis xyz="0 0 1"/>
    <parent link="outer_leg_left_3"/>
    <child link="center_leg_left_3"/>
    <limit effort="200.0" lower="0.0" upper="0.07" velocity="0.1"/>
    <origin rpy="0 0 0" xyz="0 0 0"/>
    <dynamics damping="100" friction="200"/>
  </joint>
  <gazebo reference="outer_to_center_leg_left_3">
    <implicitSpringDamper>true</implicitSpringDamper>
  </gazebo>
  <joint name="center_to_inner_leg_left_3" type="prismatic">
    <axis xyz="0 0 1"/>
    <parent link="center_leg_left_3"/>
    <child link="inner_leg_left_3"/>
    <limit effort="200.0" lower="0.0" upper="0.07" velocity="0.1"/>
    <origin rpy="0 0 0" xyz="0 0 0"/>
    <dynamics damping="100" friction="200"/>
  </joint>
  <gazebo reference="center_to_inner_leg_left_3">
    <implicitSpringDamper>true</implicitSpringDamper>
  </gazebo>
  <transmission name="outer_leg_extension_left_3_trans" type="SimpleTransmission">
    <type>transmission_interface/SimpleTransmission</type>
    <actuator name="outer_leg_extension_left_3_motor">
      <hardwareInterface>hardware_interface/PositionJointInterface</hardwareInterface>
      <mechanicalReduction>1</mechanicalReduction>
    </actuator>
    <joint name="hip_to_outer_leg_left_3">
      <hardwareInterface>hardware_interface/PositionJointInterface</hardwareInterface>
    </joint>
  </transmission>
  <transmission name="center_leg_extension_left_3_trans" type="SimpleTransmission">
    <type>transmission_interface/SimpleTransmission</type>
    <actuator name="center_leg_extension_left_3_motor">
      <hardwareInterface>hardware_interface/PositionJointInterface</hardwareInterface>
      <mechanicalReduction>1</mechanicalReduction>
    </actuator>
    <joint name="outer_to_center_leg_left_3">
      <hardwareInterface>hardware_interface/PositionJointInterface</hardwareInterface>
    </joint>
  </transmission>
  <transmission name="inner_leg_extension_left_3_trans" type="SimpleTransmission">
    <type>transmission_interface/SimpleTransmission</type>
    <actuator name="inner_leg_extension_left_3_motor">
      <hardwareInterface>hardware_interface/PositionJointInterface</hardwareInterface>
      <mechanicalReduction>1</mechanicalReduction>
    </actuator>
    <joint name="center_to_inner_leg_left_3">
      <hardwareInterface>hardware_interface/PositionJointInterface</hardwareInterface>
    </joint>
  </transmission>
  <link name="hip_left_5">
    <visual>
      <geometry>
        <cylinder length="0.07" radius="0.01"/>
      </geometry>
      <material name="black"/>
    </visual>
    <collision>
      <geometry>
        <cylinder length="0.07" radius="0.01"/>
      </geometry>
    </collision>
    <inertial>
      <mass value="0.01"/>
      <inertia ixx="4.083333333333334e-06" ixy="0.0" ixz="0.0" iyy="0.0" iyz="0.0" izz="4.083333333333334e-06"/>
    </inertial>
  </link>
  <gazebo reference="hip_left_5">
    <material>Gazebo/Grey</material>
  </gazebo>
  <link name="outer_leg_left_5">
    <visual>
      <geometry>
        <cylinder length="0.07" radius="0.008"/>
      </geometry>
      <material name="black"/>
    </visual>
    <collision>
      <geometry>
        <cylinder length="0.07" radius="0.008"/>
      </geometry>
    </collision>
    <inertial>
      <mass value="0.008"/>
      <inertia ixx="3.2666666666666674e-06" ixy="0.0" ixz="0.0" iyy="0.0" iyz="0.0" izz="3.2666666666666674e-06"/>
    </inertial>
  </link>
  <gazebo reference="outer_leg_left_5">
    <material>Gazebo/Grey</material>
  </gazebo>
  <link name="center_leg_left_5">
    <visual>
      <geometry>
        <cylinder length="0.07" radius="0.006"/>
      </geometry>
      <material name="black"/>
    </visual>
    <collision>
      <geometry>
        <cylinder length="0.07" radius="0.006"/>
      </geometry>
    </collision>
    <inertial>
      <mass value="0.006"/>
      <inertia ixx="2.45e-06" ixy="0.0" ixz="0.0" iyy="2.45e-06" iyz="0.0" izz="0.0"/>
    </inertial>
  </link>
  <gazebo reference="center_leg_left_5">
    <material>Gazebo/Grey</material>
  </gazebo>
  <link name="inner_leg_left_5">
    <visual>
      <geometry>
        <cylinder length="0.07" radius="0.004"/>
      </geometry>
      <material name="black"/>
    </visual>
    <collision>
      <geometry>
        <cylinder length="0.07" radius="0.004"/>
      </geometry>
    </collision>
    <inertial>
      <mass value="0.004"/>
      <inertia ixx="1.6333333333333337e-06" ixy="0.0" ixz="0.0" iyy="1.6333333333333337e-06" iyz="0.0" izz="0.0"/>
    </inertial>
  </link>
  <gazebo reference="inner_leg_left_5">
    <material>Gazebo/Grey</material>
  </gazebo>
  <joint name="base_to_hip_left_5" type="fixed">
    <parent link="inner_outer_connector_left"/>
    <child link="hip_left_5"/>
    <origin rpy="0 3.9269908169872414 0" xyz="-0.049497474683058325 0 -0.049497474683058346"/>
  </joint>
  <joint name="hip_to_outer_leg_left_5" type="prismatic">
    <axis xyz="0 0 1"/>
    <parent link="hip_left_5"/>
    <child link="outer_leg_left_5"/>
    <limit effort="200.0" lower="0.0" upper="0.07" velocity="0.1"/>
    <origin rpy="0 0 0" xyz="0 0 0"/>
    <dynamics damping="100" friction="200"/>
  </joint>
  <gazebo reference="hip_to_outer_leg_left_5">
    <implicitSpringDamper>true</implicitSpringDamper>
  </gazebo>
  <joint name="outer_to_center_leg_left_5" type="prismatic">
    <axis xyz="0 0 1"/>
    <parent link="outer_leg_left_5"/>
    <child link="center_leg_left_5"/>
    <limit effort="200.0" lower="0.0" upper="0.07" velocity="0.1"/>
    <origin rpy="0 0 0" xyz="0 0 0"/>
    <dynamics damping="100" friction="200"/>
  </joint>
  <gazebo reference="outer_to_center_leg_left_5">
    <implicitSpringDamper>true</implicitSpringDamper>
  </gazebo>
  <joint name="center_to_inner_leg_left_5" type="prismatic">
    <axis xyz="0 0 1"/>
    <parent link="center_leg_left_5"/>
    <child link="inner_leg_left_5"/>
    <limit effort="200.0" lower="0.0" upper="0.07" velocity="0.1"/>
    <origin rpy="0 0 0" xyz="0 0 0"/>
    <dynamics damping="100" friction="200"/>
  </joint>
  <gazebo reference="center_to_inner_leg_left_5">
    <implicitSpringDamper>true</implicitSpringDamper>
  </gazebo>
  <transmission name="outer_leg_extension_left_5_trans" type="SimpleTransmission">
    <type>transmission_interface/SimpleTransmission</type>
    <actuator name="outer_leg_extension_left_5_motor">
      <hardwareInterface>hardware_interface/PositionJointInterface</hardwareInterface>
      <mechanicalReduction>1</mechanicalReduction>
    </actuator>
    <joint name="hip_to_outer_leg_left_5">
      <hardwareInterface>hardware_interface/PositionJointInterface</hardwareInterface>
    </joint>
  </transmission>
  <transmission name="center_leg_extension_left_5_trans" type="SimpleTransmission">
    <type>transmission_interface/SimpleTransmission</type>
    <actuator name="center_leg_extension_left_5_motor">
      <hardwareInterface>hardware_interface/PositionJointInterface</hardwareInterface>
      <mechanicalReduction>1</mechanicalReduction>
    </actuator>
    <joint name="outer_to_center_leg_left_5">
      <hardwareInterface>hardware_interface/PositionJointInterface</hardwareInterface>
    </joint>
  </transmission>
  <transmission name="inner_leg_extension_left_5_trans" type="SimpleTransmission">
    <type>transmission_interface/SimpleTransmission</type>
    <actuator name="inner_leg_extension_left_5_motor">
      <hardwareInterface>hardware_interface/PositionJointInterface</hardwareInterface>
      <mechanicalReduction>1</mechanicalReduction>
    </actuator>
    <joint name="center_to_inner_leg_left_5">
      <hardwareInterface>hardware_interface/PositionJointInterface</hardwareInterface>
    </joint>
  </transmission>
  <link name="hip_left_7">
    <visual>
      <geometry>
        <cylinder length="0.07" radius="0.01"/>
      </geometry>
      <material name="black"/>
    </visual>
    <collision>
      <geometry>
        <cylinder length="0.07" radius="0.01"/>
      </geometry>
    </collision>
    <inertial>
      <mass value="0.01"/>
      <inertia ixx="4.083333333333334e-06" ixy="0.0" ixz="0.0" iyy="0.0" iyz="0.0" izz="4.083333333333334e-06"/>
    </inertial>
  </link>
  <gazebo reference="hip_left_7">
    <material>Gazebo/Grey</material>
  </gazebo>
  <link name="outer_leg_left_7">
    <visual>
      <geometry>
        <cylinder length="0.07" radius="0.008"/>
      </geometry>
      <material name="black"/>
    </visual>
    <collision>
      <geometry>
        <cylinder length="0.07" radius="0.008"/>
      </geometry>
    </collision>
    <inertial>
      <mass value="0.008"/>
      <inertia ixx="3.2666666666666674e-06" ixy="0.0" ixz="0.0" iyy="0.0" iyz="0.0" izz="3.2666666666666674e-06"/>
    </inertial>
  </link>
  <gazebo reference="outer_leg_left_7">
    <material>Gazebo/Grey</material>
  </gazebo>
  <link name="center_leg_left_7">
    <visual>
      <geometry>
        <cylinder length="0.07" radius="0.006"/>
      </geometry>
      <material name="black"/>
    </visual>
    <collision>
      <geometry>
        <cylinder length="0.07" radius="0.006"/>
      </geometry>
    </collision>
    <inertial>
      <mass value="0.006"/>
      <inertia ixx="2.45e-06" ixy="0.0" ixz="0.0" iyy="2.45e-06" iyz="0.0" izz="0.0"/>
    </inertial>
  </link>
  <gazebo reference="center_leg_left_7">
    <material>Gazebo/Grey</material>
  </gazebo>
  <link name="inner_leg_left_7">
    <visual>
      <geometry>
        <cylinder length="0.07" radius="0.004"/>
      </geometry>
      <material name="black"/>
    </visual>
    <collision>
      <geometry>
        <cylinder length="0.07" radius="0.004"/>
      </geometry>
    </collision>
    <inertial>
      <mass value="0.004"/>
      <inertia ixx="1.6333333333333337e-06" ixy="0.0" ixz="0.0" iyy="1.6333333333333337e-06" iyz="0.0" izz="0.0"/>
    </inertial>
  </link>
  <gazebo reference="inner_leg_left_7">
    <material>Gazebo/Grey</material>
  </gazebo>
  <joint name="base_to_hip_left_7" type="fixed">
    <parent link="inner_outer_connector_left"/>
    <child link="hip_left_7"/>
    <origin rpy="0 5.497787143782138 0" xyz="-0.049497474683058346 0 0.04949747468305832"/>
  </joint>
  <joint name="hip_to_outer_leg_left_7" type="prismatic">
    <axis xyz="0 0 1"/>
    <parent link="hip_left_7"/>
    <child link="outer_leg_left_7"/>
    <limit effort="200.0" lower="0.0" upper="0.07" velocity="0.1"/>
    <origin rpy="0 0 0" xyz="0 0 0"/>
    <dynamics damping="100" friction="200"/>
  </joint>
  <gazebo reference="hip_to_outer_leg_left_7">
    <implicitSpringDamper>true</implicitSpringDamper>
  </gazebo>
  <joint name="outer_to_center_leg_left_7" type="prismatic">
    <axis xyz="0 0 1"/>
    <parent link="outer_leg_left_7"/>
    <child link="center_leg_left_7"/>
    <limit effort="200.0" lower="0.0" upper="0.07" velocity="0.1"/>
    <origin rpy="0 0 0" xyz="0 0 0"/>
    <dynamics damping="100" friction="200"/>
  </joint>
  <gazebo reference="outer_to_center_leg_left_7">
    <implicitSpringDamper>true</implicitSpringDamper>
  </gazebo>
  <joint name="center_to_inner_leg_left_7" type="prismatic">
    <axis xyz="0 0 1"/>
    <parent link="center_leg_left_7"/>
    <child link="inner_leg_left_7"/>
    <limit effort="200.0" lower="0.0" upper="0.07" velocity="0.1"/>
    <origin rpy="0 0 0" xyz="0 0 0"/>
    <dynamics damping="100" friction="200"/>
  </joint>
  <gazebo reference="center_to_inner_leg_left_7">
    <implicitSpringDamper>true</implicitSpringDamper>
  </gazebo>
  <transmission name="outer_leg_extension_left_7_trans" type="SimpleTransmission">
    <type>transmission_interface/SimpleTransmission</type>
    <actuator name="outer_leg_extension_left_7_motor">
      <hardwareInterface>hardware_interface/PositionJointInterface</hardwareInterface>
      <mechanicalReduction>1</mechanicalReduction>
    </actuator>
    <joint name="hip_to_outer_leg_left_7">
      <hardwareInterface>hardware_interface/PositionJointInterface</hardwareInterface>
    </joint>
  </transmission>
  <transmission name="center_leg_extension_left_7_trans" type="SimpleTransmission">
    <type>transmission_interface/SimpleTransmission</type>
    <actuator name="center_leg_extension_left_7_motor">
      <hardwareInterface>hardware_interface/PositionJointInterface</hardwareInterface>
      <mechanicalReduction>1</mechanicalReduction>
    </actuator>
    <joint name="outer_to_center_leg_left_7">
      <hardwareInterface>hardware_interface/PositionJointInterface</hardwareInterface>
    </joint>
  </transmission>
  <transmission name="inner_leg_extension_left_7_trans" type="SimpleTransmission">
    <type>transmission_interface/SimpleTransmission</type>
    <actuator name="inner_leg_extension_left_7_motor">
      <hardwareInterface>hardware_interface/PositionJointInterface</hardwareInterface>
      <mechanicalReduction>1</mechanicalReduction>
    </actuator>
    <joint name="center_to_inner_leg_left_7">
      <hardwareInterface>hardware_interface/PositionJointInterface</hardwareInterface>
    </joint>
  </transmission>
  <!--
  -->
  <link name="mid70_0">
    <!--visual>
        <geometry>
          <box size=".097 .064 .0627"/>
        </geometry>
        <material name="white"/>
      </visual-->
    <visual>
      <!-- <origin xyz="0 0 -0.0377" /> -->
      <geometry>
        <!-- <mesh filename="package://velodyne_description/meshes/VLP16_scan.dae" /> -->
        <mesh filename="package://daedalus/meshes/MID-40.stl" scale="0.001 0.001 0.001"/>
      </geometry>
    </visual>
    <inertial>
      <mass value="0.58"/>
      <inertia ixx="0.00038" ixy="0.0" ixz="0.0" iyy="0.00064" iyz="0.0" izz="0.00065"/>
    </inertial>
  </link>
  <joint name="baseplate_to_mid70_0" type="fixed">
    <origin rpy="0 0 -0.436332" xyz="0.1 -0.1 0.095"/>
    <parent link="baseplate"/>
    <child link="mid70_0"/>
  </joint>
  <link name="anchor_0">
    <collision>
      <geometry>
        <box size=".001 .064 .0627"/>
      </geometry>
    </collision>
    <inertial>
      <mass value="0.01"/>
      <inertia ixx="0.00038" ixy="0.0" ixz="0.0" iyy="0.00064" iyz="0.0" izz="0.00065"/>
    </inertial>
  </link>
  <joint name="anchor_joint_0" type="continuous">
    <axis xyz="1 0 0"/>
    <origin rpy="0 0 0" xyz="-0.0175 0 0"/>
    <parent link="mid70_0"/>
    <child link="anchor_0"/>
    <limit effort="2000.0" velocity="6.28"/>
    <origin rpy="0 0 0" xyz="0 0 0"/>
    <dynamics damping="10.0" friction="20.0"/>
  </joint>
  <transmission name="anchor_joint_0">
    <type>transmission_interface/SimpleTransmission</type>
    <actuator name="anchor_joint_0">
      <mechanicalReduction>1</mechanicalReduction>
    </actuator>
    <joint name="anchor_joint_0">
      <hardwareInterface>hardware_interface/VelocityJointInterface</hardwareInterface>
    </joint>
  </transmission>
  <!-- <joint name="anchor_joint_${prefix}" type="fixed">
      <origin xyz="0 0 0" rpy="0 0 0"/>
      <origin xyz="0.0323 0 0" rpy="0 0 0"/>
      <parent link="mid70_${prefix}"/>
      <child link="anchor_${prefix}"/>
    </joint> -->
  <!--gazebo reference="anchor_joint_${prefix}">
    <implicitSpringDamper>true</implicitSpringDamper>
  </gazebo-->
  <gazebo reference="anchor_0">
    <material>Gazebo/Grey</material>
    <sensor name="hokuyo" type="gpu_ray">
      <pose>0 0 0 0 0 0</pose>
      <visualize>false</visualize>
      <update_rate>60</update_rate>
      <ray>
        <scan>
          <horizontal>
            <samples>90</samples>
            <resolution>1</resolution>
            <min_angle>-0.614356</min_angle>
            <max_angle>0.614356</max_angle>
          </horizontal>
          <!-- <vertical>
                    <samples>30</samples>
                    <resolution>1</resolution>
                    <min_angle>-0.614356</min_angle>
                    <max_angle>0.614356</max_angle>
                </vertical> -->
        </scan>
        <range>
          <min>0.05</min>
          <max>90.0</max>
          <resolution>0.01</resolution>
        </range>
        <noise>
          <type>gaussian</type>
          <mean>0.0</mean>
          <stddev>0.01</stddev>
        </noise>
      </ray>
      <plugin filename="libgazebo_ros_gpu_laser.so" name="gazebo_laser">
        <topicName>/daedalus/laser/scan_0</topicName>
        <frameName>anchor_0</frameName>
      </plugin>
    </sensor>
    <!--sensor name="block_lidar" type="gpu_ray">
        <visualize>true</visualize>
        <pose>0.0 0.0 0.0 0.0 0.0 0.0</pose>
        <ray>
            <scan>
                <horizontal>
                    <samples>30</samples>
                    <resolution>1</resolution>
                    <min_angle>-0.614356</min_angle>
                    <max_angle>0.614356</max_angle>
                </horizontal>
                <vertical>
                    <samples>30</samples>
                    <resolution>1</resolution>
                    <min_angle>-0.614356</min_angle>
                    <max_angle>0.614356</max_angle>
                </vertical>
            </scan>
            <range>
                <min>0.05</min>
                <max>90.0</max>
            </range>
        </ray>
        <plugin name="lidar_plugin" filename="libgazebo_ros_gpu_block_laser.so">
            <gaussianNoise>0.00</gaussianNoise>
            <alwaysOn>true</alwaysOn>
            <updateRate>20</updateRate>
            <topicName>/daedalus/laser_scan_${prefix}</topicName>
            <frameName>anchor_${prefix}</frameName>
        </plugin>
        <always_on>true</always_on>
        <update_rate>10.0</update_rate>
      </sensor>
    </gazebo-->
    <!-- <sensor type="ray" name="MID-40_${prefix}">
        <pose>0 0 0 0 0 0</pose>
        <visualize>false</visualize>
        <update_rate>20</update_rate>
        <ray>
          <scan>
            <horizontal>
              <samples>1</samples>
              <resolution>1</resolution>
              <min_angle>-${43*M_PI/180.0}</min_angle>
              <max_angle> ${43*M_PI/180.0}</max_angle>
            </horizontal>
            <vertical>
              <samples>1</samples>
              <resolution>1</resolution>
              <min_angle>-${43*M_PI/180.0}</min_angle>
              <max_angle> ${43*M_PI/180.0}</max_angle>
            </vertical>
          </scan>
          <range>
            <min>0.3</min>
            <max>130</max>
            <resolution>0.001</resolution>
          </range>
          <noise>
            <type>gaussian</type>
            <mean>0.0</mean>
            <stddev>0.0</stddev>
          </noise>
        </ray> -->
    <!--plugin name="gazebo_ros_laser_controller" filename="libgazebo_ros_livox_gpu_laser.so">
            <topicName>/daedalus/laser_scan_${prefix}</topicName>
            <frameName>anchor_${prefix}</frameName>
            <<min_range>0.2</min_range>
            <max_range>100</max_range>
            <num_samples>10</num_samples>
            <num_ellipses>4</num_ellipses>
            <rotation_step>0.33</rotation_step>
            <update_rate>20</update_rate>>
          </plugin-->
    <!-- <plugin name="gazebo_ros_laser_controller_${prefix}" filename="libgazebo_ros_livox_laser.so">
            <topicName>/daedalus/laser_scan_${prefix}</topicName>
            <frameName>anchor_${prefix}</frameName>
            <min_range>0.3</min_range>
            <max_range>130</max_range>
            <num_samples>10</num_samples>
            <num_ellipses>4</num_ellipses>
            <rotation_step>0.33</rotation_step>
            <update_rate>20</update_rate>
          </plugin>
      </sensor> -->
  </gazebo>
  <link name="mid70_1">
    <!--visual>
        <geometry>
          <box size=".097 .064 .0627"/>
        </geometry>
        <material name="white"/>
      </visual-->
    <visual>
      <!-- <origin xyz="0 0 -0.0377" /> -->
      <geometry>
        <!-- <mesh filename="package://velodyne_description/meshes/VLP16_scan.dae" /> -->
        <mesh filename="package://daedalus/meshes/MID-40.stl" scale="0.001 0.001 0.001"/>
      </geometry>
    </visual>
    <inertial>
      <mass value="0.58"/>
      <inertia ixx="0.00038" ixy="0.0" ixz="0.0" iyy="0.00064" iyz="0.0" izz="0.00065"/>
    </inertial>
  </link>
  <joint name="baseplate_to_mid70_1" type="fixed">
    <origin rpy="0 0 0.436332" xyz="0.1 0.1 0.095"/>
    <parent link="baseplate"/>
    <child link="mid70_1"/>
  </joint>
  <link name="anchor_1">
    <collision>
      <geometry>
        <box size=".001 .064 .0627"/>
      </geometry>
    </collision>
    <inertial>
      <mass value="0.01"/>
      <inertia ixx="0.00038" ixy="0.0" ixz="0.0" iyy="0.00064" iyz="0.0" izz="0.00065"/>
    </inertial>
  </link>
  <joint name="anchor_joint_1" type="continuous">
    <axis xyz="1 0 0"/>
    <origin rpy="0 0 0" xyz="-0.0175 0 0"/>
    <parent link="mid70_1"/>
    <child link="anchor_1"/>
    <limit effort="2000.0" velocity="6.28"/>
    <origin rpy="0 0 0" xyz="0 0 0"/>
    <dynamics damping="10.0" friction="20.0"/>
  </joint>
  <transmission name="anchor_joint_1">
    <type>transmission_interface/SimpleTransmission</type>
    <actuator name="anchor_joint_1">
      <mechanicalReduction>1</mechanicalReduction>
    </actuator>
    <joint name="anchor_joint_1">
      <hardwareInterface>hardware_interface/VelocityJointInterface</hardwareInterface>
    </joint>
  </transmission>
  <!-- <joint name="anchor_joint_${prefix}" type="fixed">
      <origin xyz="0 0 0" rpy="0 0 0"/>
      <origin xyz="0.0323 0 0" rpy="0 0 0"/>
      <parent link="mid70_${prefix}"/>
      <child link="anchor_${prefix}"/>
    </joint> -->
  <!--gazebo reference="anchor_joint_${prefix}">
    <implicitSpringDamper>true</implicitSpringDamper>
  </gazebo-->
  <gazebo reference="anchor_1">
    <material>Gazebo/Grey</material>
    <sensor name="hokuyo" type="gpu_ray">
      <pose>0 0 0 0 0 0</pose>
      <visualize>false</visualize>
      <update_rate>60</update_rate>
      <ray>
        <scan>
          <horizontal>
            <samples>90</samples>
            <resolution>1</resolution>
            <min_angle>-0.614356</min_angle>
            <max_angle>0.614356</max_angle>
          </horizontal>
          <!-- <vertical>
                    <samples>30</samples>
                    <resolution>1</resolution>
                    <min_angle>-0.614356</min_angle>
                    <max_angle>0.614356</max_angle>
                </vertical> -->
        </scan>
        <range>
          <min>0.05</min>
          <max>90.0</max>
          <resolution>0.01</resolution>
        </range>
        <noise>
          <type>gaussian</type>
          <mean>0.0</mean>
          <stddev>0.01</stddev>
        </noise>
      </ray>
      <plugin filename="libgazebo_ros_gpu_laser.so" name="gazebo_laser">
        <topicName>/daedalus/laser/scan_1</topicName>
        <frameName>anchor_1</frameName>
      </plugin>
    </sensor>
    <!--sensor name="block_lidar" type="gpu_ray">
        <visualize>true</visualize>
        <pose>0.0 0.0 0.0 0.0 0.0 0.0</pose>
        <ray>
            <scan>
                <horizontal>
                    <samples>30</samples>
                    <resolution>1</resolution>
                    <min_angle>-0.614356</min_angle>
                    <max_angle>0.614356</max_angle>
                </horizontal>
                <vertical>
                    <samples>30</samples>
                    <resolution>1</resolution>
                    <min_angle>-0.614356</min_angle>
                    <max_angle>0.614356</max_angle>
                </vertical>
            </scan>
            <range>
                <min>0.05</min>
                <max>90.0</max>
            </range>
        </ray>
        <plugin name="lidar_plugin" filename="libgazebo_ros_gpu_block_laser.so">
            <gaussianNoise>0.00</gaussianNoise>
            <alwaysOn>true</alwaysOn>
            <updateRate>20</updateRate>
            <topicName>/daedalus/laser_scan_${prefix}</topicName>
            <frameName>anchor_${prefix}</frameName>
        </plugin>
        <always_on>true</always_on>
        <update_rate>10.0</update_rate>
      </sensor>
    </gazebo-->
    <!-- <sensor type="ray" name="MID-40_${prefix}">
        <pose>0 0 0 0 0 0</pose>
        <visualize>false</visualize>
        <update_rate>20</update_rate>
        <ray>
          <scan>
            <horizontal>
              <samples>1</samples>
              <resolution>1</resolution>
              <min_angle>-${43*M_PI/180.0}</min_angle>
              <max_angle> ${43*M_PI/180.0}</max_angle>
            </horizontal>
            <vertical>
              <samples>1</samples>
              <resolution>1</resolution>
              <min_angle>-${43*M_PI/180.0}</min_angle>
              <max_angle> ${43*M_PI/180.0}</max_angle>
            </vertical>
          </scan>
          <range>
            <min>0.3</min>
            <max>130</max>
            <resolution>0.001</resolution>
          </range>
          <noise>
            <type>gaussian</type>
            <mean>0.0</mean>
            <stddev>0.0</stddev>
          </noise>
        </ray> -->
    <!--plugin name="gazebo_ros_laser_controller" filename="libgazebo_ros_livox_gpu_laser.so">
            <topicName>/daedalus/laser_scan_${prefix}</topicName>
            <frameName>anchor_${prefix}</frameName>
            <<min_range>0.2</min_range>
            <max_range>100</max_range>
            <num_samples>10</num_samples>
            <num_ellipses>4</num_ellipses>
            <rotation_step>0.33</rotation_step>
            <update_rate>20</update_rate>>
          </plugin-->
    <!-- <plugin name="gazebo_ros_laser_controller_${prefix}" filename="libgazebo_ros_livox_laser.so">
            <topicName>/daedalus/laser_scan_${prefix}</topicName>
            <frameName>anchor_${prefix}</frameName>
            <min_range>0.3</min_range>
            <max_range>130</max_range>
            <num_samples>10</num_samples>
            <num_ellipses>4</num_ellipses>
            <rotation_step>0.33</rotation_step>
            <update_rate>20</update_rate>
          </plugin>
      </sensor> -->
  </gazebo>
  <link name="mid70_2">
    <!--visual>
        <geometry>
          <box size=".097 .064 .0627"/>
        </geometry>
        <material name="white"/>
      </visual-->
    <visual>
      <!-- <origin xyz="0 0 -0.0377" /> -->
      <geometry>
        <!-- <mesh filename="package://velodyne_description/meshes/VLP16_scan.dae" /> -->
        <mesh filename="package://daedalus/meshes/MID-40.stl" scale="0.001 0.001 0.001"/>
      </geometry>
    </visual>
    <inertial>
      <mass value="0.58"/>
      <inertia ixx="0.00038" ixy="0.0" ixz="0.0" iyy="0.00064" iyz="0.0" izz="0.00065"/>
    </inertial>
  </link>
  <joint name="baseplate_to_mid70_2" type="fixed">
    <origin rpy="0 0 2.705260653589793" xyz="-0.1 0.1 0.095"/>
    <parent link="baseplate"/>
    <child link="mid70_2"/>
  </joint>
  <link name="anchor_2">
    <collision>
      <geometry>
        <box size=".001 .064 .0627"/>
      </geometry>
    </collision>
    <inertial>
      <mass value="0.01"/>
      <inertia ixx="0.00038" ixy="0.0" ixz="0.0" iyy="0.00064" iyz="0.0" izz="0.00065"/>
    </inertial>
  </link>
  <joint name="anchor_joint_2" type="continuous">
    <axis xyz="1 0 0"/>
    <origin rpy="0 0 0" xyz="-0.0175 0 0"/>
    <parent link="mid70_2"/>
    <child link="anchor_2"/>
    <limit effort="2000.0" velocity="6.28"/>
    <origin rpy="0 0 0" xyz="0 0 0"/>
    <dynamics damping="10.0" friction="20.0"/>
  </joint>
  <transmission name="anchor_joint_2">
    <type>transmission_interface/SimpleTransmission</type>
    <actuator name="anchor_joint_2">
      <mechanicalReduction>1</mechanicalReduction>
    </actuator>
    <joint name="anchor_joint_2">
      <hardwareInterface>hardware_interface/VelocityJointInterface</hardwareInterface>
    </joint>
  </transmission>
  <!-- <joint name="anchor_joint_${prefix}" type="fixed">
      <origin xyz="0 0 0" rpy="0 0 0"/>
      <origin xyz="0.0323 0 0" rpy="0 0 0"/>
      <parent link="mid70_${prefix}"/>
      <child link="anchor_${prefix}"/>
    </joint> -->
  <!--gazebo reference="anchor_joint_${prefix}">
    <implicitSpringDamper>true</implicitSpringDamper>
  </gazebo-->
  <gazebo reference="anchor_2">
    <material>Gazebo/Grey</material>
    <sensor name="hokuyo" type="gpu_ray">
      <pose>0 0 0 0 0 0</pose>
      <visualize>false</visualize>
      <update_rate>60</update_rate>
      <ray>
        <scan>
          <horizontal>
            <samples>90</samples>
            <resolution>1</resolution>
            <min_angle>-0.614356</min_angle>
            <max_angle>0.614356</max_angle>
          </horizontal>
          <!-- <vertical>
                    <samples>30</samples>
                    <resolution>1</resolution>
                    <min_angle>-0.614356</min_angle>
                    <max_angle>0.614356</max_angle>
                </vertical> -->
        </scan>
        <range>
          <min>0.05</min>
          <max>90.0</max>
          <resolution>0.01</resolution>
        </range>
        <noise>
          <type>gaussian</type>
          <mean>0.0</mean>
          <stddev>0.01</stddev>
        </noise>
      </ray>
      <plugin filename="libgazebo_ros_gpu_laser.so" name="gazebo_laser">
        <topicName>/daedalus/laser/scan_2</topicName>
        <frameName>anchor_2</frameName>
      </plugin>
    </sensor>
    <!--sensor name="block_lidar" type="gpu_ray">
        <visualize>true</visualize>
        <pose>0.0 0.0 0.0 0.0 0.0 0.0</pose>
        <ray>
            <scan>
                <horizontal>
                    <samples>30</samples>
                    <resolution>1</resolution>
                    <min_angle>-0.614356</min_angle>
                    <max_angle>0.614356</max_angle>
                </horizontal>
                <vertical>
                    <samples>30</samples>
                    <resolution>1</resolution>
                    <min_angle>-0.614356</min_angle>
                    <max_angle>0.614356</max_angle>
                </vertical>
            </scan>
            <range>
                <min>0.05</min>
                <max>90.0</max>
            </range>
        </ray>
        <plugin name="lidar_plugin" filename="libgazebo_ros_gpu_block_laser.so">
            <gaussianNoise>0.00</gaussianNoise>
            <alwaysOn>true</alwaysOn>
            <updateRate>20</updateRate>
            <topicName>/daedalus/laser_scan_${prefix}</topicName>
            <frameName>anchor_${prefix}</frameName>
        </plugin>
        <always_on>true</always_on>
        <update_rate>10.0</update_rate>
      </sensor>
    </gazebo-->
    <!-- <sensor type="ray" name="MID-40_${prefix}">
        <pose>0 0 0 0 0 0</pose>
        <visualize>false</visualize>
        <update_rate>20</update_rate>
        <ray>
          <scan>
            <horizontal>
              <samples>1</samples>
              <resolution>1</resolution>
              <min_angle>-${43*M_PI/180.0}</min_angle>
              <max_angle> ${43*M_PI/180.0}</max_angle>
            </horizontal>
            <vertical>
              <samples>1</samples>
              <resolution>1</resolution>
              <min_angle>-${43*M_PI/180.0}</min_angle>
              <max_angle> ${43*M_PI/180.0}</max_angle>
            </vertical>
          </scan>
          <range>
            <min>0.3</min>
            <max>130</max>
            <resolution>0.001</resolution>
          </range>
          <noise>
            <type>gaussian</type>
            <mean>0.0</mean>
            <stddev>0.0</stddev>
          </noise>
        </ray> -->
    <!--plugin name="gazebo_ros_laser_controller" filename="libgazebo_ros_livox_gpu_laser.so">
            <topicName>/daedalus/laser_scan_${prefix}</topicName>
            <frameName>anchor_${prefix}</frameName>
            <<min_range>0.2</min_range>
            <max_range>100</max_range>
            <num_samples>10</num_samples>
            <num_ellipses>4</num_ellipses>
            <rotation_step>0.33</rotation_step>
            <update_rate>20</update_rate>>
          </plugin-->
    <!-- <plugin name="gazebo_ros_laser_controller_${prefix}" filename="libgazebo_ros_livox_laser.so">
            <topicName>/daedalus/laser_scan_${prefix}</topicName>
            <frameName>anchor_${prefix}</frameName>
            <min_range>0.3</min_range>
            <max_range>130</max_range>
            <num_samples>10</num_samples>
            <num_ellipses>4</num_ellipses>
            <rotation_step>0.33</rotation_step>
            <update_rate>20</update_rate>
          </plugin>
      </sensor> -->
  </gazebo>
  <link name="mid70_3">
    <!--visual>
        <geometry>
          <box size=".097 .064 .0627"/>
        </geometry>
        <material name="white"/>
      </visual-->
    <visual>
      <!-- <origin xyz="0 0 -0.0377" /> -->
      <geometry>
        <!-- <mesh filename="package://velodyne_description/meshes/VLP16_scan.dae" /> -->
        <mesh filename="package://daedalus/meshes/MID-40.stl" scale="0.001 0.001 0.001"/>
      </geometry>
    </visual>
    <inertial>
      <mass value="0.58"/>
      <inertia ixx="0.00038" ixy="0.0" ixz="0.0" iyy="0.00064" iyz="0.0" izz="0.00065"/>
    </inertial>
  </link>
  <joint name="baseplate_to_mid70_3" type="fixed">
    <origin rpy="0 0 3.5779246535897933" xyz="-0.1 -0.1 0.095"/>
    <parent link="baseplate"/>
    <child link="mid70_3"/>
  </joint>
  <link name="anchor_3">
    <collision>
      <geometry>
        <box size=".001 .064 .0627"/>
      </geometry>
    </collision>
    <inertial>
      <mass value="0.01"/>
      <inertia ixx="0.00038" ixy="0.0" ixz="0.0" iyy="0.00064" iyz="0.0" izz="0.00065"/>
    </inertial>
  </link>
  <joint name="anchor_joint_3" type="continuous">
    <axis xyz="1 0 0"/>
    <origin rpy="0 0 0" xyz="-0.0175 0 0"/>
    <parent link="mid70_3"/>
    <child link="anchor_3"/>
    <limit effort="2000.0" velocity="6.28"/>
    <origin rpy="0 0 0" xyz="0 0 0"/>
    <dynamics damping="10.0" friction="20.0"/>
  </joint>
  <transmission name="anchor_joint_3">
    <type>transmission_interface/SimpleTransmission</type>
    <actuator name="anchor_joint_3">
      <mechanicalReduction>1</mechanicalReduction>
    </actuator>
    <joint name="anchor_joint_3">
      <hardwareInterface>hardware_interface/VelocityJointInterface</hardwareInterface>
    </joint>
  </transmission>
  <!-- <joint name="anchor_joint_${prefix}" type="fixed">
      <origin xyz="0 0 0" rpy="0 0 0"/>
      <origin xyz="0.0323 0 0" rpy="0 0 0"/>
      <parent link="mid70_${prefix}"/>
      <child link="anchor_${prefix}"/>
    </joint> -->
  <!--gazebo reference="anchor_joint_${prefix}">
    <implicitSpringDamper>true</implicitSpringDamper>
  </gazebo-->
  <gazebo reference="anchor_3">
    <material>Gazebo/Grey</material>
    <sensor name="hokuyo" type="gpu_ray">
      <pose>0 0 0 0 0 0</pose>
      <visualize>false</visualize>
      <update_rate>60</update_rate>
      <ray>
        <scan>
          <horizontal>
            <samples>90</samples>
            <resolution>1</resolution>
            <min_angle>-0.614356</min_angle>
            <max_angle>0.614356</max_angle>
          </horizontal>
          <!-- <vertical>
                    <samples>30</samples>
                    <resolution>1</resolution>
                    <min_angle>-0.614356</min_angle>
                    <max_angle>0.614356</max_angle>
                </vertical> -->
        </scan>
        <range>
          <min>0.05</min>
          <max>90.0</max>
          <resolution>0.01</resolution>
        </range>
        <noise>
          <type>gaussian</type>
          <mean>0.0</mean>
          <stddev>0.01</stddev>
        </noise>
      </ray>
      <plugin filename="libgazebo_ros_gpu_laser.so" name="gazebo_laser">
        <topicName>/daedalus/laser/scan_3</topicName>
        <frameName>anchor_3</frameName>
      </plugin>
    </sensor>
    <!--sensor name="block_lidar" type="gpu_ray">
        <visualize>true</visualize>
        <pose>0.0 0.0 0.0 0.0 0.0 0.0</pose>
        <ray>
            <scan>
                <horizontal>
                    <samples>30</samples>
                    <resolution>1</resolution>
                    <min_angle>-0.614356</min_angle>
                    <max_angle>0.614356</max_angle>
                </horizontal>
                <vertical>
                    <samples>30</samples>
                    <resolution>1</resolution>
                    <min_angle>-0.614356</min_angle>
                    <max_angle>0.614356</max_angle>
                </vertical>
            </scan>
            <range>
                <min>0.05</min>
                <max>90.0</max>
            </range>
        </ray>
        <plugin name="lidar_plugin" filename="libgazebo_ros_gpu_block_laser.so">
            <gaussianNoise>0.00</gaussianNoise>
            <alwaysOn>true</alwaysOn>
            <updateRate>20</updateRate>
            <topicName>/daedalus/laser_scan_${prefix}</topicName>
            <frameName>anchor_${prefix}</frameName>
        </plugin>
        <always_on>true</always_on>
        <update_rate>10.0</update_rate>
      </sensor>
    </gazebo-->
    <!-- <sensor type="ray" name="MID-40_${prefix}">
        <pose>0 0 0 0 0 0</pose>
        <visualize>false</visualize>
        <update_rate>20</update_rate>
        <ray>
          <scan>
            <horizontal>
              <samples>1</samples>
              <resolution>1</resolution>
              <min_angle>-${43*M_PI/180.0}</min_angle>
              <max_angle> ${43*M_PI/180.0}</max_angle>
            </horizontal>
            <vertical>
              <samples>1</samples>
              <resolution>1</resolution>
              <min_angle>-${43*M_PI/180.0}</min_angle>
              <max_angle> ${43*M_PI/180.0}</max_angle>
            </vertical>
          </scan>
          <range>
            <min>0.3</min>
            <max>130</max>
            <resolution>0.001</resolution>
          </range>
          <noise>
            <type>gaussian</type>
            <mean>0.0</mean>
            <stddev>0.0</stddev>
          </noise>
        </ray> -->
    <!--plugin name="gazebo_ros_laser_controller" filename="libgazebo_ros_livox_gpu_laser.so">
            <topicName>/daedalus/laser_scan_${prefix}</topicName>
            <frameName>anchor_${prefix}</frameName>
            <<min_range>0.2</min_range>
            <max_range>100</max_range>
            <num_samples>10</num_samples>
            <num_ellipses>4</num_ellipses>
            <rotation_step>0.33</rotation_step>
            <update_rate>20</update_rate>>
          </plugin-->
    <!-- <plugin name="gazebo_ros_laser_controller_${prefix}" filename="libgazebo_ros_livox_laser.so">
            <topicName>/daedalus/laser_scan_${prefix}</topicName>
            <frameName>anchor_${prefix}</frameName>
            <min_range>0.3</min_range>
            <max_range>130</max_range>
            <num_samples>10</num_samples>
            <num_ellipses>4</num_ellipses>
            <rotation_step>0.33</rotation_step>
            <update_rate>20</update_rate>
          </plugin>
      </sensor> -->
  </gazebo>
  <link name="imu_link_0">
    <visual>
      <geometry>
        <box size=".01 .01 .01"/>
      </geometry>
      <origin rpy="0 0 0" xyz="0 0 0"/>
      <material name="blue"/>
    </visual>
  </link>
  <joint name="imu_joint_0" type="fixed">
    <parent link="baseplate"/>
    <child link="imu_link_0"/>
    <origin rpy="0 0 0" xyz="0 0 .05"/>
  </joint>
  <gazebo reference="imu_link_0">
    <gravity>true</gravity>
    <sensor name="imu_sensor_0" type="imu">
      <always_on>true</always_on>
      <update_rate>100</update_rate>
      <visualize>true</visualize>
      <topic>/daedalus/imu_0</topic>
      <plugin filename="libgazebo_ros_imu_sensor.so" name="imu_plugin">
        <topicName>/daedalus/imu_0</topicName>
        <bodyName>imu_link_0</bodyName>
        <updateRateHZ>100</updateRateHZ>
        <gaussianNoise>2e-4</gaussianNoise>
        <xyzOffset>0 0 0</xyzOffset>
        <rpyOffset>0 0 0</rpyOffset>
        <frameName>imu_link_0</frameName>
        <initialOrientationAsReference>true</initialOrientationAsReference>
      </plugin>
      <pose>0 0 0 0 0 0</pose>
    </sensor>
    <material>Gazebo/Green</material>
  </gazebo>
  <link name="imu_link_1">
    <visual>
      <geometry>
        <box size=".01 .01 .01"/>
      </geometry>
      <origin rpy="0 0 0" xyz="0 0 0"/>
      <material name="blue"/>
    </visual>
  </link>
  <joint name="imu_joint_1" type="fixed">
    <parent link="baseplate"/>
    <child link="imu_link_1"/>
    <origin rpy="0 0 1.5707963267948966" xyz="0 0 .05"/>
  </joint>
  <gazebo reference="imu_link_1">
    <gravity>true</gravity>
    <sensor name="imu_sensor_1" type="imu">
      <always_on>true</always_on>
      <update_rate>100</update_rate>
      <visualize>true</visualize>
      <topic>/daedalus/imu_1</topic>
      <plugin filename="libgazebo_ros_imu_sensor.so" name="imu_plugin">
        <topicName>/daedalus/imu_1</topicName>
        <bodyName>imu_link_1</bodyName>
        <updateRateHZ>100</updateRateHZ>
        <gaussianNoise>2e-4</gaussianNoise>
        <xyzOffset>0 0 0</xyzOffset>
        <rpyOffset>0 0 0</rpyOffset>
        <frameName>imu_link_1</frameName>
        <initialOrientationAsReference>true</initialOrientationAsReference>
      </plugin>
      <pose>0 0 0 0 0 0</pose>
    </sensor>
    <material>Gazebo/Green</material>
  </gazebo>
  <link name="imu_link_2">
    <visual>
      <geometry>
        <box size=".01 .01 .01"/>
      </geometry>
      <origin rpy="0 0 0" xyz="0 0 0"/>
      <material name="blue"/>
    </visual>
  </link>
  <joint name="imu_joint_2" type="fixed">
    <parent link="baseplate"/>
    <child link="imu_link_2"/>
    <origin rpy="0 1.5707963267948966 0" xyz="0 0 .05"/>
  </joint>
  <gazebo reference="imu_link_2">
    <gravity>true</gravity>
    <sensor name="imu_sensor_2" type="imu">
      <always_on>true</always_on>
      <update_rate>100</update_rate>
      <visualize>true</visualize>
      <topic>/daedalus/imu_2</topic>
      <plugin filename="libgazebo_ros_imu_sensor.so" name="imu_plugin">
        <topicName>/daedalus/imu_2</topicName>
        <bodyName>imu_link_2</bodyName>
        <updateRateHZ>100</updateRateHZ>
        <gaussianNoise>2e-4</gaussianNoise>
        <xyzOffset>0 0 0</xyzOffset>
        <rpyOffset>0 0 0</rpyOffset>
        <frameName>imu_link_2</frameName>
        <initialOrientationAsReference>true</initialOrientationAsReference>
      </plugin>
      <pose>0 0 0 0 0 0</pose>
    </sensor>
    <material>Gazebo/Green</material>
  </gazebo>
  <link name="drive_encoder_r_0">
    <visual>
      <geometry>
        <box size="0.005 0.01 0.01"/>
      </geometry>
      <origin rpy="0 0 0" xyz="0 0 0"/>
    </visual>
  </link>
  <joint name="encoder_joint_r_0" type="fixed">
    <parent link="baseplate"/>
    <child link="drive_encoder_r_0"/>
    <origin rpy="0 0 1.5707963267948966" xyz="0.2 0.05 -0.05"/>
  </joint>
  <gazebo reference="drive_encoder_r_0">
    <material>Gazebo/White</material>
    <sensor name="hokuyo" type="gpu_ray">
      <pose>0 0 0 0 0 0</pose>
      <visualize>false</visualize>
      <update_rate>60</update_rate>
      <ray>
        <scan>
          <horizontal>
            <samples>1</samples>
            <resolution>1</resolution>
            <min_angle>0</min_angle>
            <max_angle>0</max_angle>
          </horizontal>
        </scan>
        <range>
          <min>0.05</min>
          <max>90.0</max>
          <resolution>0.01</resolution>
        </range>
        <noise>
          <type>gaussian</type>
          <mean>0.0</mean>
          <stddev>0.01</stddev>
        </noise>
      </ray>
      <plugin filename="libgazebo_ros_gpu_laser.so" name="gazebo_laser">
        <topicName>/daedalus/drive_encoder_r_0</topicName>
        <frameName>drive_encoder_r_0</frameName>
      </plugin>
    </sensor>
  </gazebo>
  <link name="drive_encoder_r_1">
    <visual>
      <geometry>
        <box size="0.005 0.01 0.01"/>
      </geometry>
      <origin rpy="0 0 0" xyz="0 0 0"/>
    </visual>
  </link>
  <joint name="encoder_joint_r_1" type="fixed">
    <parent link="baseplate"/>
    <child link="drive_encoder_r_1"/>
    <origin rpy="0 0 1.5707963267948966" xyz="0.2 -0.05 -0.05"/>
  </joint>
  <gazebo reference="drive_encoder_r_1">
    <material>Gazebo/White</material>
    <sensor name="hokuyo" type="gpu_ray">
      <pose>0 0 0 0 0 0</pose>
      <visualize>false</visualize>
      <update_rate>60</update_rate>
      <ray>
        <scan>
          <horizontal>
            <samples>1</samples>
            <resolution>1</resolution>
            <min_angle>0</min_angle>
            <max_angle>0</max_angle>
          </horizontal>
        </scan>
        <range>
          <min>0.05</min>
          <max>90.0</max>
          <resolution>0.01</resolution>
        </range>
        <noise>
          <type>gaussian</type>
          <mean>0.0</mean>
          <stddev>0.01</stddev>
        </noise>
      </ray>
      <plugin filename="libgazebo_ros_gpu_laser.so" name="gazebo_laser">
        <topicName>/daedalus/drive_encoder_r_1</topicName>
        <frameName>drive_encoder_r_1</frameName>
      </plugin>
    </sensor>
  </gazebo>
  <link name="drive_encoder_l_0">
    <visual>
      <geometry>
        <box size="0.005 0.01 0.01"/>
      </geometry>
      <origin rpy="0 0 0" xyz="0 0 0"/>
    </visual>
  </link>
  <joint name="encoder_joint_l_0" type="fixed">
    <parent link="baseplate"/>
    <child link="drive_encoder_l_0"/>
    <origin rpy="0 0 -1.5707963267948966" xyz="-0.2 0.05 -0.05"/>
  </joint>
  <gazebo reference="drive_encoder_l_0">
    <material>Gazebo/White</material>
    <sensor name="hokuyo" type="gpu_ray">
      <pose>0 0 0 0 0 0</pose>
      <visualize>false</visualize>
      <update_rate>60</update_rate>
      <ray>
        <scan>
          <horizontal>
            <samples>1</samples>
            <resolution>1</resolution>
            <min_angle>0</min_angle>
            <max_angle>0</max_angle>
          </horizontal>
        </scan>
        <range>
          <min>0.05</min>
          <max>90.0</max>
          <resolution>0.01</resolution>
        </range>
        <noise>
          <type>gaussian</type>
          <mean>0.0</mean>
          <stddev>0.01</stddev>
        </noise>
      </ray>
      <plugin filename="libgazebo_ros_gpu_laser.so" name="gazebo_laser">
        <topicName>/daedalus/drive_encoder_l_0</topicName>
        <frameName>drive_encoder_l_0</frameName>
      </plugin>
    </sensor>
  </gazebo>
  <link name="drive_encoder_l_1">
    <visual>
      <geometry>
        <box size="0.005 0.01 0.01"/>
      </geometry>
      <origin rpy="0 0 0" xyz="0 0 0"/>
    </visual>
  </link>
  <joint name="encoder_joint_l_1" type="fixed">
    <parent link="baseplate"/>
    <child link="drive_encoder_l_1"/>
    <origin rpy="0 0 -1.5707963267948966" xyz="-0.2 -0.05 -0.05"/>
  </joint>
  <gazebo reference="drive_encoder_l_1">
    <material>Gazebo/White</material>
    <sensor name="hokuyo" type="gpu_ray">
      <pose>0 0 0 0 0 0</pose>
      <visualize>false</visualize>
      <update_rate>60</update_rate>
      <ray>
        <scan>
          <horizontal>
            <samples>1</samples>
            <resolution>1</resolution>
            <min_angle>0</min_angle>
            <max_angle>0</max_angle>
          </horizontal>
        </scan>
        <range>
          <min>0.05</min>
          <max>90.0</max>
          <resolution>0.01</resolution>
        </range>
        <noise>
          <type>gaussian</type>
          <mean>0.0</mean>
          <stddev>0.01</stddev>
        </noise>
      </ray>
      <plugin filename="libgazebo_ros_gpu_laser.so" name="gazebo_laser">
        <topicName>/daedalus/drive_encoder_l_1</topicName>
        <frameName>drive_encoder_l_1</frameName>
      </plugin>
    </sensor>
  </gazebo>
  <gazebo>
    <plugin filename="libgazebo_ros_control.so" name="gazebo_ros_control">
      <robotNamespace>/</robotNamespace>
    </plugin>
  </gazebo>
</robot>
