<?xml version="1.0" ?>
<!-- =================================================================================== -->
<!-- |    This document was autogenerated by xacro from daedalus_simple.urdf.xacro     | -->
<!-- |    EDITING THIS FILE BY HAND IS NOT RECOMMENDED                                 | -->
<!-- =================================================================================== -->
<robot name="daedalus">
  <self_collide>false</self_collide>
  <!--Define some parameters -->
  <material name="white">
    <color rgba="1 1 1 0.2"/>
  </material>
  <material name="blue">
    <color rgba="0 0 0.8 0.1"/>
  </material>
  <material name="black">
    <color rgba="0 0 0 1"/>
  </material>
  <!--The sphere -->
  <link name="base_link">
    <visual>
      <geometry>
        <cylinder length="0.8" radius="0.24"/>
      </geometry>
      <origin rpy="1.5707963267948966 0 0" xyz="0 0 0"/>
      <material name="blue"/>
    </visual>
    <collision>
      <geometry>
        <sphere radius="0.464"/>
      </geometry>
    </collision>
  </link>
  <link name="sphere">
    <visual>
      <geometry>
        <sphere radius="0.464"/>
      </geometry>
      <material name="white"/>
    </visual>
    <collision>
      <geometry>
        <sphere radius="0.464"/>
      </geometry>
    </collision>
    <inertial>
      <mass value="5.0"/>
      <inertia ixx="0.7176533333333334" ixy="0.0" ixz="0.0" iyy="0.7176533333333334" iyz="0.0" izz="0.7176533333333334"/>
    </inertial>
  </link>
  <gazebo reference="sphere">
    <mu1 value="200.0"/>
    <mu2 value="100.0"/>
    <kp value="10000000.0"/>
    <kd value="1.0"/>
    <material>Gazebo/Grey</material>
  </gazebo>
  <link name="filler_link">
    <visual>
      <geometry>
        <cylinder length="0.8" radius="0.24"/>
      </geometry>
      <origin rpy="1.5707963267948966 0 0" xyz="0 0 0"/>
      <material name="blue"/>
    </visual>
    <inertial>
      <mass value="20"/>
      <inertia ixx="1" ixy="0.0" ixz="0" iyy="1" iyz="0.0" izz=".432"/>
    </inertial>
  </link>
  <joint name="temp_cyl" type="continuous">
    <parent link="filler_link"/>
    <child link="sphere"/>
    <axis rpy="0 0 0" xyz="0 1 0"/>
    <origin xyz="0 0 0"/>
    <limit effort="1000.0" velocity="5.0"/>
    <joint_properties damping="1000.0" friction="1000.0"/>
    <dynamics damping="100.0" friction="200.0"/>
  </joint>
  <!--joint name="temp_cyl_2" type="continuous">
     <parent link="filler_link"/>
     <child link="inner_outer_connector_left"/>
     <axis xyz="0 1 0" rpy="0 0 0"/>
     <origin xyz="0 -0.4 0"/>
     <limit effort="1000.0" velocity="2.0"/>
     <joint_properties damping="1000.0" friction="1000.0"/>
     <dynamics damping="100.0" friction="200.0"/>
  </joint-->
  <joint name="filler" type="fixed">
    <parent link="base_link"/>
    <child link="filler_link"/>
    <origin xyz="0 0 0"/>
  </joint>
  <transmission name="temp_cyl">
    <type>transmission_interface/SimpleTransmission</type>
    <actuator name="$temp_cyl">
      <mechanicalReduction>1</mechanicalReduction>
    </actuator>
    <joint name="temp_cyl">
      <hardwareInterface>hardware_interface/VelocityJointInterface</hardwareInterface>
    </joint>
  </transmission>
  <!--transmission name="temp_cyl_2">
    <type>transmission_interface/SimpleTransmission</type>
    <actuator name="$temp_cyl_2">
      <mechanicalReduction>1</mechanicalReduction>
    </actuator>
    <joint name="temp_cyl_2">
      <hardwareInterface>hardware_interface/VelocityJointInterface</hardwareInterface>
    </joint>
  </transmission-->
  <!--joint name="connector_to_sphere_left" type="fixed">
     <parent link="inner_outer_connector_left"/>
     <child link="sphere"/>
     <origin xyz="0 0.4 0"/>
  </joint-->
  <!--joint name="connector_to_sphere_right" type="fixed">
     <parent link="inner_outer_connector_right"/>
     <child link="sphere"/>
     <origin xyz="0 -0.4 0"/>
  </joint-->
  <!--link name="hip_base">
    <visual>
      <geometry>
        <cylinder radius="0.24" length="0.8"/>
      </geometry>
      <origin rpy="${pi/2.0} 0 0" xyz="0 0 0"/>
      <material name="blue"/>
    </visual>
    <inertial>
       <mass value="1"/>
       <inertia ixx="1" ixy="0.0" ixz="0" iyy="1" iyz="0.0" izz=".432"/>
    </inertial>
  </link-->
  <!--joint name="center_to_base" type="continuous">
     <parent link="filler_link"/>
     <child link="sphere"/>
     <axis xyz="0 1 0" rpy="0 0 0"/>
     <limit effort="1000.0" velocity="2.0"/>
     <joint_properties damping="1000.0" friction="1000.0"/>
     <dynamics damping="100.0" friction="200.0"/>
  </joint-->
  <!--transmission name="center_to_base">
    <type>transmission_interface/SimpleTransmission</type>
    <actuator name="$center_to_base">
      <mechanicalReduction>1</mechanicalReduction>
    </actuator>
    <joint name="center_to_base">
      <hardwareInterface>hardware_interface/VelocityJointInterface</hardwareInterface>
    </joint>
  </transmission-->
  <!--The battery -->
  <!--link name="battery_holder_1">
    <visual>
      <geometry>
        <sphere radius="0.04"/>
      </geometry>
      <origin rpy="0 0 0" xyz="0 0 0"/>
      <material name="black"/>
    </visual>
    <collision>
      <geometry>
        <sphere radius="0.04"/>
      </geometry>
    </collision>
    <inertial>
       <mass value="${5.0}"/>
       <inertia ixx="${2.0/3.0*5.0*0.04*0.04}" ixy="0.0" ixz="0.0" iyy="${2.0/3.0*5.0*0.04*0.04}" iyz="0.0" izz="${2.0/3.0*5.0*0.04*0.04}"/>
    </inertial>
  </link-->
  <link name="battery_holder">
    <visual>
      <geometry>
        <cylinder length="0.3" radius="0.01"/>
      </geometry>
      <origin rpy="0 0 0" xyz="0 0 -0.15"/>
      <material name="black"/>
    </visual>
    <collision>
      <geometry>
        <cylinder length="0.3" radius="0.01"/>
      </geometry>
    </collision>
    <inertial>
      <mass value="1"/>
      <inertia ixx="1.0" ixy="0.0" ixz="0.0" iyy="1.0" iyz="0.0" izz="1.0"/>
    </inertial>
  </link>
  <link name="battery">
    <visual>
      <geometry>
        <box size="0.2 0.2 0.1"/>
      </geometry>
      <origin rpy="0 0 0" xyz="0 0 0"/>
      <material name="black"/>
    </visual>
    <inertial>
      <mass value="7.0"/>
      <inertia ixx="0.04666666666666667" ixy="0.0" ixz="0.0" iyy="0.04666666666666667" iyz="0.0" izz="0.029166666666666674"/>
    </inertial>
    <collision>
      <geometry>
        <box size="0.2 0.2 0.1"/>
      </geometry>
    </collision>
  </link>
  <joint name="battery" type="fixed">
    <parent link="battery_holder"/>
    <child link="battery"/>
    <origin xyz="0 0 -0.3"/>
  </joint>
  <!--joint name="battery_pitch" type="continuous">
     <axis xyz="0 1 0" rpy="0 0 0"/>
     <parent link="sphere"/>
     <child link="battery_holder_1"/>
     <origin xyz="0 0 0" rpy="0 0 0"/>
     <limit effort="1000.0" velocity="10.0"/>
     <joint_properties damping="1000.0" friction="1000.0"/>
     <dynamics damping="100.0" friction="200.0" />
  </joint-->
  <joint name="battery_yaw" type="revolute">
    <parent link="filler_link"/>
    <axis xyz="1 0 0"/>
    <child link="battery_holder"/>
    <limit effort="1000.0" lower="-0.7853981633974483" upper="0.7853981633974483" velocity="0.5"/>
    <origin xyz="0 0 0"/>
    <joint_properties damping="1000.0" friction="1000.0"/>
    <dynamics damping="100.0" friction="200.0"/>
  </joint>
  <!--transmission name="battery_holder_1_trans">
    <type>transmission_interface/SimpleTransmission</type>
    <actuator name="$battery_holder_1__motor">
      <mechanicalReduction>1</mechanicalReduction>
    </actuator>
    <joint name="battery_pitch">
      <hardwareInterface>hardware_interface/VelocityJointInterface</hardwareInterface>
    </joint>
  </transmission-->
  <transmission name="battery_holder_trans">
    <type>transmission_interface/SimpleTransmission</type>
    <actuator name="$battery_holder__motor">
      <mechanicalReduction>1</mechanicalReduction>
    </actuator>
    <joint name="battery_yaw">
      <hardwareInterface>hardware_interface/PositionJointInterface</hardwareInterface>
    </joint>
  </transmission>
  <!--link name="inner_outer_connector_right">
    <visual>
        <geometry>
          <cylinder length="0.1" radius="0.1"/>
        </geometry>
        <material name="black"/>
      </visual>
      <collision>
        <geometry>
          <cylinder length="0.1" radius="0.1"/>
        </geometry>
      </collision>
      <inertial>
       <mass value="1"/>
       <inertia ixx="1/12*0.1*0.1" ixy="0.0" ixz="0.0" iyy="1/12*0.1*0.1" iyz="0.0" izz="0.0"/> 
      </inertial>
    </link-->
  <!--link name="inner_outer_connector_left">
    <visual>
        <geometry>
          <cylinder length="0.1" radius="0.1"/>
        </geometry>
        <material name="black"/>
      </visual>
      <collision>
        <geometry>
          <cylinder length="0.05" radius="0.05"/>
        </geometry>
      </collision>
      <inertial>
       <mass value="1"/>
       <inertia ixx="1/12*0.1*0.1" ixy="0.0" ixz="0.0" iyy="1/12*0.1*0.1" iyz="0.0" izz="0.0"/> 
      </inertial>
    </link-->
  <!--The rods -->
  <link name="hip_right_0">
    <visual>
      <geometry>
        <cylinder length="0.14" radius="0.02"/>
      </geometry>
      <material name="black"/>
    </visual>
    <collision>
      <geometry>
        <cylinder length="0.14" radius="0.02"/>
      </geometry>
    </collision>
    <inertial>
      <mass value="0.3"/>
      <inertia ixx="0.0004900000000000001" ixy="0.0" ixz="0.0" iyy="0.0" iyz="0.0" izz="0.0004900000000000001"/>
    </inertial>
  </link>
  <link name="outer_leg_right_0">
    <visual>
      <geometry>
        <cylinder length="0.14" radius="0.016"/>
      </geometry>
      <material name="black"/>
    </visual>
    <collision>
      <geometry>
        <cylinder length="0.14" radius="0.016"/>
      </geometry>
    </collision>
    <inertial>
      <mass value="0.24"/>
      <inertia ixx="0.0003920000000000001" ixy="0.0" ixz="0.0" iyy="0.0" iyz="0.0" izz="0.0003920000000000001"/>
    </inertial>
  </link>
  <link name="center_leg_right_0">
    <visual>
      <geometry>
        <cylinder length="0.14" radius="0.012"/>
      </geometry>
      <material name="black"/>
    </visual>
    <collision>
      <geometry>
        <cylinder length="0.14" radius="0.012"/>
      </geometry>
    </collision>
    <inertial>
      <mass value="0.18"/>
      <inertia ixx="0.000294" ixy="0.0" ixz="0.0" iyy="0.000294" iyz="0.0" izz="0.0"/>
    </inertial>
  </link>
  <link name="inner_leg_right_0">
    <visual>
      <geometry>
        <cylinder length="0.14" radius="0.008"/>
      </geometry>
      <material name="black"/>
    </visual>
    <collision>
      <geometry>
        <cylinder length="0.14" radius="0.008"/>
      </geometry>
    </collision>
    <inertial>
      <mass value="0.12"/>
      <inertia ixx="0.00019600000000000005" ixy="0.0" ixz="0.0" iyy="0.00019600000000000005" iyz="0.0" izz="0.0"/>
    </inertial>
  </link>
  <joint name="base_to_hip_right_0" type="fixed">
    <parent link="filler_link"/>
    <child link="hip_right_0"/>
    <origin rpy="0 0.0 0" xyz="0.0 0.4 0.14"/>
  </joint>
  <!--
    <joint name="outer_to_center_leg_${prefix}" type="fixed">
       <parent link="outer_leg_${prefix}"/>
       <child link="center_leg_${prefix}"/>
       <origin xyz="0 0 0.02"/>
    </joint>
    <joint name="center_to_inner_leg_${prefix}" type="fixed">
       <parent link="center_leg_${prefix}"/>
       <child link="inner_leg_${prefix}"/>
       <origin xyz="0 0 0.02"/>
    </joint>
    -->
  <joint name="hip_to_outer_leg_right_0" type="prismatic">
    <axis xyz="0 0 1"/>
    <parent link="hip_right_0"/>
    <child link="outer_leg_right_0"/>
    <limit effort="3000.0" lower="0.0" upper="0.14" velocity="0.1"/>
    <origin rpy="0 0 0" xyz="0 0 0"/>
    <dynamics damping="100.0" friction="200.0"/>
  </joint>
  <joint name="outer_to_center_leg_right_0" type="prismatic">
    <axis xyz="0 0 1"/>
    <parent link="outer_leg_right_0"/>
    <child link="center_leg_right_0"/>
    <limit effort="3000.0" lower="0.0" upper="0.14" velocity="0.1"/>
    <origin rpy="0 0 0" xyz="0 0 0"/>
    <dynamics damping="100.0" friction="200.0"/>
  </joint>
  <joint name="center_to_inner_leg_right_0" type="prismatic">
    <axis xyz="0 0 1"/>
    <parent link="center_leg_right_0"/>
    <child link="inner_leg_right_0"/>
    <limit effort="3000.0" lower="0.0" upper="0.14" velocity="0.1"/>
    <origin rpy="0 0 0" xyz="0 0 0"/>
    <dynamics damping="100.0" friction="200.0"/>
  </joint>
  <!--transmission name="base_to_hip_${prefix}">
      <type>transmission_interface/SimpleTransmission</type>
      <actuator name="$base_to_hip_${prefix}">
        <mechanicalReduction>1</mechanicalReduction>
      </actuator>
      <joint name="base_to_hip_${prefix}">
        <hardwareInterface>hardware_interface/VelocityJointInterface</hardwareInterface>
      </joint>
    </transmission-->
  <transmission name="outer_leg_extension_right_0_trans" type="SimpleTransmission">
    <type>transmission_interface/SimpleTransmission</type>
    <actuator name="outer_leg_extension_right_0_motor">
      <hardwareInterface>hardware_interface/PositionJointInterface</hardwareInterface>
      <mechanicalReduction>1</mechanicalReduction>
    </actuator>
    <joint name="hip_to_outer_leg_right_0">
      <hardwareInterface>hardware_interface/PositionJointInterface</hardwareInterface>
    </joint>
  </transmission>
  <transmission name="center_leg_extension_right_0_trans" type="SimpleTransmission">
    <type>transmission_interface/SimpleTransmission</type>
    <actuator name="center_leg_extension_right_0_motor">
      <hardwareInterface>hardware_interface/PositionJointInterface</hardwareInterface>
      <mechanicalReduction>1</mechanicalReduction>
    </actuator>
    <joint name="outer_to_center_leg_right_0">
      <hardwareInterface>hardware_interface/PositionJointInterface</hardwareInterface>
    </joint>
  </transmission>
  <transmission name="inner_leg_extension_right_0_trans" type="SimpleTransmission">
    <type>transmission_interface/SimpleTransmission</type>
    <actuator name="inner_leg_extension_right_0_motor">
      <hardwareInterface>hardware_interface/PositionJointInterface</hardwareInterface>
      <mechanicalReduction>1</mechanicalReduction>
    </actuator>
    <joint name="center_to_inner_leg_right_0">
      <hardwareInterface>hardware_interface/PositionJointInterface</hardwareInterface>
    </joint>
  </transmission>
  <link name="hip_right_2">
    <visual>
      <geometry>
        <cylinder length="0.14" radius="0.02"/>
      </geometry>
      <material name="black"/>
    </visual>
    <collision>
      <geometry>
        <cylinder length="0.14" radius="0.02"/>
      </geometry>
    </collision>
    <inertial>
      <mass value="0.3"/>
      <inertia ixx="0.0004900000000000001" ixy="0.0" ixz="0.0" iyy="0.0" iyz="0.0" izz="0.0004900000000000001"/>
    </inertial>
  </link>
  <link name="outer_leg_right_2">
    <visual>
      <geometry>
        <cylinder length="0.14" radius="0.016"/>
      </geometry>
      <material name="black"/>
    </visual>
    <collision>
      <geometry>
        <cylinder length="0.14" radius="0.016"/>
      </geometry>
    </collision>
    <inertial>
      <mass value="0.24"/>
      <inertia ixx="0.0003920000000000001" ixy="0.0" ixz="0.0" iyy="0.0" iyz="0.0" izz="0.0003920000000000001"/>
    </inertial>
  </link>
  <link name="center_leg_right_2">
    <visual>
      <geometry>
        <cylinder length="0.14" radius="0.012"/>
      </geometry>
      <material name="black"/>
    </visual>
    <collision>
      <geometry>
        <cylinder length="0.14" radius="0.012"/>
      </geometry>
    </collision>
    <inertial>
      <mass value="0.18"/>
      <inertia ixx="0.000294" ixy="0.0" ixz="0.0" iyy="0.000294" iyz="0.0" izz="0.0"/>
    </inertial>
  </link>
  <link name="inner_leg_right_2">
    <visual>
      <geometry>
        <cylinder length="0.14" radius="0.008"/>
      </geometry>
      <material name="black"/>
    </visual>
    <collision>
      <geometry>
        <cylinder length="0.14" radius="0.008"/>
      </geometry>
    </collision>
    <inertial>
      <mass value="0.12"/>
      <inertia ixx="0.00019600000000000005" ixy="0.0" ixz="0.0" iyy="0.00019600000000000005" iyz="0.0" izz="0.0"/>
    </inertial>
  </link>
  <joint name="base_to_hip_right_2" type="fixed">
    <parent link="filler_link"/>
    <child link="hip_right_2"/>
    <origin rpy="0 1.5707963267948966 0" xyz="0.14 0.4 8.572527594031473e-18"/>
  </joint>
  <!--
    <joint name="outer_to_center_leg_${prefix}" type="fixed">
       <parent link="outer_leg_${prefix}"/>
       <child link="center_leg_${prefix}"/>
       <origin xyz="0 0 0.02"/>
    </joint>
    <joint name="center_to_inner_leg_${prefix}" type="fixed">
       <parent link="center_leg_${prefix}"/>
       <child link="inner_leg_${prefix}"/>
       <origin xyz="0 0 0.02"/>
    </joint>
    -->
  <joint name="hip_to_outer_leg_right_2" type="prismatic">
    <axis xyz="0 0 1"/>
    <parent link="hip_right_2"/>
    <child link="outer_leg_right_2"/>
    <limit effort="3000.0" lower="0.0" upper="0.14" velocity="0.1"/>
    <origin rpy="0 0 0" xyz="0 0 0"/>
    <dynamics damping="100.0" friction="200.0"/>
  </joint>
  <joint name="outer_to_center_leg_right_2" type="prismatic">
    <axis xyz="0 0 1"/>
    <parent link="outer_leg_right_2"/>
    <child link="center_leg_right_2"/>
    <limit effort="3000.0" lower="0.0" upper="0.14" velocity="0.1"/>
    <origin rpy="0 0 0" xyz="0 0 0"/>
    <dynamics damping="100.0" friction="200.0"/>
  </joint>
  <joint name="center_to_inner_leg_right_2" type="prismatic">
    <axis xyz="0 0 1"/>
    <parent link="center_leg_right_2"/>
    <child link="inner_leg_right_2"/>
    <limit effort="3000.0" lower="0.0" upper="0.14" velocity="0.1"/>
    <origin rpy="0 0 0" xyz="0 0 0"/>
    <dynamics damping="100.0" friction="200.0"/>
  </joint>
  <!--transmission name="base_to_hip_${prefix}">
      <type>transmission_interface/SimpleTransmission</type>
      <actuator name="$base_to_hip_${prefix}">
        <mechanicalReduction>1</mechanicalReduction>
      </actuator>
      <joint name="base_to_hip_${prefix}">
        <hardwareInterface>hardware_interface/VelocityJointInterface</hardwareInterface>
      </joint>
    </transmission-->
  <transmission name="outer_leg_extension_right_2_trans" type="SimpleTransmission">
    <type>transmission_interface/SimpleTransmission</type>
    <actuator name="outer_leg_extension_right_2_motor">
      <hardwareInterface>hardware_interface/PositionJointInterface</hardwareInterface>
      <mechanicalReduction>1</mechanicalReduction>
    </actuator>
    <joint name="hip_to_outer_leg_right_2">
      <hardwareInterface>hardware_interface/PositionJointInterface</hardwareInterface>
    </joint>
  </transmission>
  <transmission name="center_leg_extension_right_2_trans" type="SimpleTransmission">
    <type>transmission_interface/SimpleTransmission</type>
    <actuator name="center_leg_extension_right_2_motor">
      <hardwareInterface>hardware_interface/PositionJointInterface</hardwareInterface>
      <mechanicalReduction>1</mechanicalReduction>
    </actuator>
    <joint name="outer_to_center_leg_right_2">
      <hardwareInterface>hardware_interface/PositionJointInterface</hardwareInterface>
    </joint>
  </transmission>
  <transmission name="inner_leg_extension_right_2_trans" type="SimpleTransmission">
    <type>transmission_interface/SimpleTransmission</type>
    <actuator name="inner_leg_extension_right_2_motor">
      <hardwareInterface>hardware_interface/PositionJointInterface</hardwareInterface>
      <mechanicalReduction>1</mechanicalReduction>
    </actuator>
    <joint name="center_to_inner_leg_right_2">
      <hardwareInterface>hardware_interface/PositionJointInterface</hardwareInterface>
    </joint>
  </transmission>
  <link name="hip_right_4">
    <visual>
      <geometry>
        <cylinder length="0.14" radius="0.02"/>
      </geometry>
      <material name="black"/>
    </visual>
    <collision>
      <geometry>
        <cylinder length="0.14" radius="0.02"/>
      </geometry>
    </collision>
    <inertial>
      <mass value="0.3"/>
      <inertia ixx="0.0004900000000000001" ixy="0.0" ixz="0.0" iyy="0.0" iyz="0.0" izz="0.0004900000000000001"/>
    </inertial>
  </link>
  <link name="outer_leg_right_4">
    <visual>
      <geometry>
        <cylinder length="0.14" radius="0.016"/>
      </geometry>
      <material name="black"/>
    </visual>
    <collision>
      <geometry>
        <cylinder length="0.14" radius="0.016"/>
      </geometry>
    </collision>
    <inertial>
      <mass value="0.24"/>
      <inertia ixx="0.0003920000000000001" ixy="0.0" ixz="0.0" iyy="0.0" iyz="0.0" izz="0.0003920000000000001"/>
    </inertial>
  </link>
  <link name="center_leg_right_4">
    <visual>
      <geometry>
        <cylinder length="0.14" radius="0.012"/>
      </geometry>
      <material name="black"/>
    </visual>
    <collision>
      <geometry>
        <cylinder length="0.14" radius="0.012"/>
      </geometry>
    </collision>
    <inertial>
      <mass value="0.18"/>
      <inertia ixx="0.000294" ixy="0.0" ixz="0.0" iyy="0.000294" iyz="0.0" izz="0.0"/>
    </inertial>
  </link>
  <link name="inner_leg_right_4">
    <visual>
      <geometry>
        <cylinder length="0.14" radius="0.008"/>
      </geometry>
      <material name="black"/>
    </visual>
    <collision>
      <geometry>
        <cylinder length="0.14" radius="0.008"/>
      </geometry>
    </collision>
    <inertial>
      <mass value="0.12"/>
      <inertia ixx="0.00019600000000000005" ixy="0.0" ixz="0.0" iyy="0.00019600000000000005" iyz="0.0" izz="0.0"/>
    </inertial>
  </link>
  <joint name="base_to_hip_right_4" type="fixed">
    <parent link="filler_link"/>
    <child link="hip_right_4"/>
    <origin rpy="0 3.141592653589793 0" xyz="1.7145055188062947e-17 0.4 -0.14"/>
  </joint>
  <!--
    <joint name="outer_to_center_leg_${prefix}" type="fixed">
       <parent link="outer_leg_${prefix}"/>
       <child link="center_leg_${prefix}"/>
       <origin xyz="0 0 0.02"/>
    </joint>
    <joint name="center_to_inner_leg_${prefix}" type="fixed">
       <parent link="center_leg_${prefix}"/>
       <child link="inner_leg_${prefix}"/>
       <origin xyz="0 0 0.02"/>
    </joint>
    -->
  <joint name="hip_to_outer_leg_right_4" type="prismatic">
    <axis xyz="0 0 1"/>
    <parent link="hip_right_4"/>
    <child link="outer_leg_right_4"/>
    <limit effort="3000.0" lower="0.0" upper="0.14" velocity="0.1"/>
    <origin rpy="0 0 0" xyz="0 0 0"/>
    <dynamics damping="100.0" friction="200.0"/>
  </joint>
  <joint name="outer_to_center_leg_right_4" type="prismatic">
    <axis xyz="0 0 1"/>
    <parent link="outer_leg_right_4"/>
    <child link="center_leg_right_4"/>
    <limit effort="3000.0" lower="0.0" upper="0.14" velocity="0.1"/>
    <origin rpy="0 0 0" xyz="0 0 0"/>
    <dynamics damping="100.0" friction="200.0"/>
  </joint>
  <joint name="center_to_inner_leg_right_4" type="prismatic">
    <axis xyz="0 0 1"/>
    <parent link="center_leg_right_4"/>
    <child link="inner_leg_right_4"/>
    <limit effort="3000.0" lower="0.0" upper="0.14" velocity="0.1"/>
    <origin rpy="0 0 0" xyz="0 0 0"/>
    <dynamics damping="100.0" friction="200.0"/>
  </joint>
  <!--transmission name="base_to_hip_${prefix}">
      <type>transmission_interface/SimpleTransmission</type>
      <actuator name="$base_to_hip_${prefix}">
        <mechanicalReduction>1</mechanicalReduction>
      </actuator>
      <joint name="base_to_hip_${prefix}">
        <hardwareInterface>hardware_interface/VelocityJointInterface</hardwareInterface>
      </joint>
    </transmission-->
  <transmission name="outer_leg_extension_right_4_trans" type="SimpleTransmission">
    <type>transmission_interface/SimpleTransmission</type>
    <actuator name="outer_leg_extension_right_4_motor">
      <hardwareInterface>hardware_interface/PositionJointInterface</hardwareInterface>
      <mechanicalReduction>1</mechanicalReduction>
    </actuator>
    <joint name="hip_to_outer_leg_right_4">
      <hardwareInterface>hardware_interface/PositionJointInterface</hardwareInterface>
    </joint>
  </transmission>
  <transmission name="center_leg_extension_right_4_trans" type="SimpleTransmission">
    <type>transmission_interface/SimpleTransmission</type>
    <actuator name="center_leg_extension_right_4_motor">
      <hardwareInterface>hardware_interface/PositionJointInterface</hardwareInterface>
      <mechanicalReduction>1</mechanicalReduction>
    </actuator>
    <joint name="outer_to_center_leg_right_4">
      <hardwareInterface>hardware_interface/PositionJointInterface</hardwareInterface>
    </joint>
  </transmission>
  <transmission name="inner_leg_extension_right_4_trans" type="SimpleTransmission">
    <type>transmission_interface/SimpleTransmission</type>
    <actuator name="inner_leg_extension_right_4_motor">
      <hardwareInterface>hardware_interface/PositionJointInterface</hardwareInterface>
      <mechanicalReduction>1</mechanicalReduction>
    </actuator>
    <joint name="center_to_inner_leg_right_4">
      <hardwareInterface>hardware_interface/PositionJointInterface</hardwareInterface>
    </joint>
  </transmission>
  <link name="hip_right_6">
    <visual>
      <geometry>
        <cylinder length="0.14" radius="0.02"/>
      </geometry>
      <material name="black"/>
    </visual>
    <collision>
      <geometry>
        <cylinder length="0.14" radius="0.02"/>
      </geometry>
    </collision>
    <inertial>
      <mass value="0.3"/>
      <inertia ixx="0.0004900000000000001" ixy="0.0" ixz="0.0" iyy="0.0" iyz="0.0" izz="0.0004900000000000001"/>
    </inertial>
  </link>
  <link name="outer_leg_right_6">
    <visual>
      <geometry>
        <cylinder length="0.14" radius="0.016"/>
      </geometry>
      <material name="black"/>
    </visual>
    <collision>
      <geometry>
        <cylinder length="0.14" radius="0.016"/>
      </geometry>
    </collision>
    <inertial>
      <mass value="0.24"/>
      <inertia ixx="0.0003920000000000001" ixy="0.0" ixz="0.0" iyy="0.0" iyz="0.0" izz="0.0003920000000000001"/>
    </inertial>
  </link>
  <link name="center_leg_right_6">
    <visual>
      <geometry>
        <cylinder length="0.14" radius="0.012"/>
      </geometry>
      <material name="black"/>
    </visual>
    <collision>
      <geometry>
        <cylinder length="0.14" radius="0.012"/>
      </geometry>
    </collision>
    <inertial>
      <mass value="0.18"/>
      <inertia ixx="0.000294" ixy="0.0" ixz="0.0" iyy="0.000294" iyz="0.0" izz="0.0"/>
    </inertial>
  </link>
  <link name="inner_leg_right_6">
    <visual>
      <geometry>
        <cylinder length="0.14" radius="0.008"/>
      </geometry>
      <material name="black"/>
    </visual>
    <collision>
      <geometry>
        <cylinder length="0.14" radius="0.008"/>
      </geometry>
    </collision>
    <inertial>
      <mass value="0.12"/>
      <inertia ixx="0.00019600000000000005" ixy="0.0" ixz="0.0" iyy="0.00019600000000000005" iyz="0.0" izz="0.0"/>
    </inertial>
  </link>
  <joint name="base_to_hip_right_6" type="fixed">
    <parent link="filler_link"/>
    <child link="hip_right_6"/>
    <origin rpy="0 4.71238898038469 0" xyz="-0.14 0.4 -2.571758278209442e-17"/>
  </joint>
  <!--
    <joint name="outer_to_center_leg_${prefix}" type="fixed">
       <parent link="outer_leg_${prefix}"/>
       <child link="center_leg_${prefix}"/>
       <origin xyz="0 0 0.02"/>
    </joint>
    <joint name="center_to_inner_leg_${prefix}" type="fixed">
       <parent link="center_leg_${prefix}"/>
       <child link="inner_leg_${prefix}"/>
       <origin xyz="0 0 0.02"/>
    </joint>
    -->
  <joint name="hip_to_outer_leg_right_6" type="prismatic">
    <axis xyz="0 0 1"/>
    <parent link="hip_right_6"/>
    <child link="outer_leg_right_6"/>
    <limit effort="3000.0" lower="0.0" upper="0.14" velocity="0.1"/>
    <origin rpy="0 0 0" xyz="0 0 0"/>
    <dynamics damping="100.0" friction="200.0"/>
  </joint>
  <joint name="outer_to_center_leg_right_6" type="prismatic">
    <axis xyz="0 0 1"/>
    <parent link="outer_leg_right_6"/>
    <child link="center_leg_right_6"/>
    <limit effort="3000.0" lower="0.0" upper="0.14" velocity="0.1"/>
    <origin rpy="0 0 0" xyz="0 0 0"/>
    <dynamics damping="100.0" friction="200.0"/>
  </joint>
  <joint name="center_to_inner_leg_right_6" type="prismatic">
    <axis xyz="0 0 1"/>
    <parent link="center_leg_right_6"/>
    <child link="inner_leg_right_6"/>
    <limit effort="3000.0" lower="0.0" upper="0.14" velocity="0.1"/>
    <origin rpy="0 0 0" xyz="0 0 0"/>
    <dynamics damping="100.0" friction="200.0"/>
  </joint>
  <!--transmission name="base_to_hip_${prefix}">
      <type>transmission_interface/SimpleTransmission</type>
      <actuator name="$base_to_hip_${prefix}">
        <mechanicalReduction>1</mechanicalReduction>
      </actuator>
      <joint name="base_to_hip_${prefix}">
        <hardwareInterface>hardware_interface/VelocityJointInterface</hardwareInterface>
      </joint>
    </transmission-->
  <transmission name="outer_leg_extension_right_6_trans" type="SimpleTransmission">
    <type>transmission_interface/SimpleTransmission</type>
    <actuator name="outer_leg_extension_right_6_motor">
      <hardwareInterface>hardware_interface/PositionJointInterface</hardwareInterface>
      <mechanicalReduction>1</mechanicalReduction>
    </actuator>
    <joint name="hip_to_outer_leg_right_6">
      <hardwareInterface>hardware_interface/PositionJointInterface</hardwareInterface>
    </joint>
  </transmission>
  <transmission name="center_leg_extension_right_6_trans" type="SimpleTransmission">
    <type>transmission_interface/SimpleTransmission</type>
    <actuator name="center_leg_extension_right_6_motor">
      <hardwareInterface>hardware_interface/PositionJointInterface</hardwareInterface>
      <mechanicalReduction>1</mechanicalReduction>
    </actuator>
    <joint name="outer_to_center_leg_right_6">
      <hardwareInterface>hardware_interface/PositionJointInterface</hardwareInterface>
    </joint>
  </transmission>
  <transmission name="inner_leg_extension_right_6_trans" type="SimpleTransmission">
    <type>transmission_interface/SimpleTransmission</type>
    <actuator name="inner_leg_extension_right_6_motor">
      <hardwareInterface>hardware_interface/PositionJointInterface</hardwareInterface>
      <mechanicalReduction>1</mechanicalReduction>
    </actuator>
    <joint name="center_to_inner_leg_right_6">
      <hardwareInterface>hardware_interface/PositionJointInterface</hardwareInterface>
    </joint>
  </transmission>
  <link name="hip_right_1">
    <visual>
      <geometry>
        <cylinder length="0.14" radius="0.02"/>
      </geometry>
      <material name="black"/>
    </visual>
    <collision>
      <geometry>
        <cylinder length="0.14" radius="0.02"/>
      </geometry>
    </collision>
    <inertial>
      <mass value="0.3"/>
      <inertia ixx="0.0004900000000000001" ixy="0.0" ixz="0.0" iyy="0.0" iyz="0.0" izz="0.0004900000000000001"/>
    </inertial>
  </link>
  <link name="outer_leg_right_1">
    <visual>
      <geometry>
        <cylinder length="0.14" radius="0.016"/>
      </geometry>
      <material name="black"/>
    </visual>
    <collision>
      <geometry>
        <cylinder length="0.14" radius="0.016"/>
      </geometry>
    </collision>
    <inertial>
      <mass value="0.24"/>
      <inertia ixx="0.0003920000000000001" ixy="0.0" ixz="0.0" iyy="0.0" iyz="0.0" izz="0.0003920000000000001"/>
    </inertial>
  </link>
  <link name="center_leg_right_1">
    <visual>
      <geometry>
        <cylinder length="0.14" radius="0.012"/>
      </geometry>
      <material name="black"/>
    </visual>
    <collision>
      <geometry>
        <cylinder length="0.14" radius="0.012"/>
      </geometry>
    </collision>
    <inertial>
      <mass value="0.18"/>
      <inertia ixx="0.000294" ixy="0.0" ixz="0.0" iyy="0.000294" iyz="0.0" izz="0.0"/>
    </inertial>
  </link>
  <link name="inner_leg_right_1">
    <visual>
      <geometry>
        <cylinder length="0.14" radius="0.008"/>
      </geometry>
      <material name="black"/>
    </visual>
    <collision>
      <geometry>
        <cylinder length="0.14" radius="0.008"/>
      </geometry>
    </collision>
    <inertial>
      <mass value="0.12"/>
      <inertia ixx="0.00019600000000000005" ixy="0.0" ixz="0.0" iyy="0.00019600000000000005" iyz="0.0" izz="0.0"/>
    </inertial>
  </link>
  <joint name="base_to_hip_right_1" type="fixed">
    <parent link="filler_link"/>
    <child link="hip_right_1"/>
    <origin rpy="0 0.7853981633974483 0" xyz="0.09899494936611665 0.4 0.09899494936611666"/>
  </joint>
  <!--
    <joint name="outer_to_center_leg_${prefix}" type="fixed">
       <parent link="outer_leg_${prefix}"/>
       <child link="center_leg_${prefix}"/>
       <origin xyz="0 0 0.02"/>
    </joint>
    <joint name="center_to_inner_leg_${prefix}" type="fixed">
       <parent link="center_leg_${prefix}"/>
       <child link="inner_leg_${prefix}"/>
       <origin xyz="0 0 0.02"/>
    </joint>
    -->
  <joint name="hip_to_outer_leg_right_1" type="prismatic">
    <axis xyz="0 0 1"/>
    <parent link="hip_right_1"/>
    <child link="outer_leg_right_1"/>
    <limit effort="3000.0" lower="0.0" upper="0.14" velocity="0.1"/>
    <origin rpy="0 0 0" xyz="0 0 0"/>
    <dynamics damping="100.0" friction="200.0"/>
  </joint>
  <joint name="outer_to_center_leg_right_1" type="prismatic">
    <axis xyz="0 0 1"/>
    <parent link="outer_leg_right_1"/>
    <child link="center_leg_right_1"/>
    <limit effort="3000.0" lower="0.0" upper="0.14" velocity="0.1"/>
    <origin rpy="0 0 0" xyz="0 0 0"/>
    <dynamics damping="100.0" friction="200.0"/>
  </joint>
  <joint name="center_to_inner_leg_right_1" type="prismatic">
    <axis xyz="0 0 1"/>
    <parent link="center_leg_right_1"/>
    <child link="inner_leg_right_1"/>
    <limit effort="3000.0" lower="0.0" upper="0.14" velocity="0.1"/>
    <origin rpy="0 0 0" xyz="0 0 0"/>
    <dynamics damping="100.0" friction="200.0"/>
  </joint>
  <!--transmission name="base_to_hip_${prefix}">
      <type>transmission_interface/SimpleTransmission</type>
      <actuator name="$base_to_hip_${prefix}">
        <mechanicalReduction>1</mechanicalReduction>
      </actuator>
      <joint name="base_to_hip_${prefix}">
        <hardwareInterface>hardware_interface/VelocityJointInterface</hardwareInterface>
      </joint>
    </transmission-->
  <transmission name="outer_leg_extension_right_1_trans" type="SimpleTransmission">
    <type>transmission_interface/SimpleTransmission</type>
    <actuator name="outer_leg_extension_right_1_motor">
      <hardwareInterface>hardware_interface/PositionJointInterface</hardwareInterface>
      <mechanicalReduction>1</mechanicalReduction>
    </actuator>
    <joint name="hip_to_outer_leg_right_1">
      <hardwareInterface>hardware_interface/PositionJointInterface</hardwareInterface>
    </joint>
  </transmission>
  <transmission name="center_leg_extension_right_1_trans" type="SimpleTransmission">
    <type>transmission_interface/SimpleTransmission</type>
    <actuator name="center_leg_extension_right_1_motor">
      <hardwareInterface>hardware_interface/PositionJointInterface</hardwareInterface>
      <mechanicalReduction>1</mechanicalReduction>
    </actuator>
    <joint name="outer_to_center_leg_right_1">
      <hardwareInterface>hardware_interface/PositionJointInterface</hardwareInterface>
    </joint>
  </transmission>
  <transmission name="inner_leg_extension_right_1_trans" type="SimpleTransmission">
    <type>transmission_interface/SimpleTransmission</type>
    <actuator name="inner_leg_extension_right_1_motor">
      <hardwareInterface>hardware_interface/PositionJointInterface</hardwareInterface>
      <mechanicalReduction>1</mechanicalReduction>
    </actuator>
    <joint name="center_to_inner_leg_right_1">
      <hardwareInterface>hardware_interface/PositionJointInterface</hardwareInterface>
    </joint>
  </transmission>
  <link name="hip_right_3">
    <visual>
      <geometry>
        <cylinder length="0.14" radius="0.02"/>
      </geometry>
      <material name="black"/>
    </visual>
    <collision>
      <geometry>
        <cylinder length="0.14" radius="0.02"/>
      </geometry>
    </collision>
    <inertial>
      <mass value="0.3"/>
      <inertia ixx="0.0004900000000000001" ixy="0.0" ixz="0.0" iyy="0.0" iyz="0.0" izz="0.0004900000000000001"/>
    </inertial>
  </link>
  <link name="outer_leg_right_3">
    <visual>
      <geometry>
        <cylinder length="0.14" radius="0.016"/>
      </geometry>
      <material name="black"/>
    </visual>
    <collision>
      <geometry>
        <cylinder length="0.14" radius="0.016"/>
      </geometry>
    </collision>
    <inertial>
      <mass value="0.24"/>
      <inertia ixx="0.0003920000000000001" ixy="0.0" ixz="0.0" iyy="0.0" iyz="0.0" izz="0.0003920000000000001"/>
    </inertial>
  </link>
  <link name="center_leg_right_3">
    <visual>
      <geometry>
        <cylinder length="0.14" radius="0.012"/>
      </geometry>
      <material name="black"/>
    </visual>
    <collision>
      <geometry>
        <cylinder length="0.14" radius="0.012"/>
      </geometry>
    </collision>
    <inertial>
      <mass value="0.18"/>
      <inertia ixx="0.000294" ixy="0.0" ixz="0.0" iyy="0.000294" iyz="0.0" izz="0.0"/>
    </inertial>
  </link>
  <link name="inner_leg_right_3">
    <visual>
      <geometry>
        <cylinder length="0.14" radius="0.008"/>
      </geometry>
      <material name="black"/>
    </visual>
    <collision>
      <geometry>
        <cylinder length="0.14" radius="0.008"/>
      </geometry>
    </collision>
    <inertial>
      <mass value="0.12"/>
      <inertia ixx="0.00019600000000000005" ixy="0.0" ixz="0.0" iyy="0.00019600000000000005" iyz="0.0" izz="0.0"/>
    </inertial>
  </link>
  <joint name="base_to_hip_right_3" type="fixed">
    <parent link="filler_link"/>
    <child link="hip_right_3"/>
    <origin rpy="0 2.356194490192345 0" xyz="0.09899494936611666 0.4 -0.09899494936611665"/>
  </joint>
  <!--
    <joint name="outer_to_center_leg_${prefix}" type="fixed">
       <parent link="outer_leg_${prefix}"/>
       <child link="center_leg_${prefix}"/>
       <origin xyz="0 0 0.02"/>
    </joint>
    <joint name="center_to_inner_leg_${prefix}" type="fixed">
       <parent link="center_leg_${prefix}"/>
       <child link="inner_leg_${prefix}"/>
       <origin xyz="0 0 0.02"/>
    </joint>
    -->
  <joint name="hip_to_outer_leg_right_3" type="prismatic">
    <axis xyz="0 0 1"/>
    <parent link="hip_right_3"/>
    <child link="outer_leg_right_3"/>
    <limit effort="3000.0" lower="0.0" upper="0.14" velocity="0.1"/>
    <origin rpy="0 0 0" xyz="0 0 0"/>
    <dynamics damping="100.0" friction="200.0"/>
  </joint>
  <joint name="outer_to_center_leg_right_3" type="prismatic">
    <axis xyz="0 0 1"/>
    <parent link="outer_leg_right_3"/>
    <child link="center_leg_right_3"/>
    <limit effort="3000.0" lower="0.0" upper="0.14" velocity="0.1"/>
    <origin rpy="0 0 0" xyz="0 0 0"/>
    <dynamics damping="100.0" friction="200.0"/>
  </joint>
  <joint name="center_to_inner_leg_right_3" type="prismatic">
    <axis xyz="0 0 1"/>
    <parent link="center_leg_right_3"/>
    <child link="inner_leg_right_3"/>
    <limit effort="3000.0" lower="0.0" upper="0.14" velocity="0.1"/>
    <origin rpy="0 0 0" xyz="0 0 0"/>
    <dynamics damping="100.0" friction="200.0"/>
  </joint>
  <!--transmission name="base_to_hip_${prefix}">
      <type>transmission_interface/SimpleTransmission</type>
      <actuator name="$base_to_hip_${prefix}">
        <mechanicalReduction>1</mechanicalReduction>
      </actuator>
      <joint name="base_to_hip_${prefix}">
        <hardwareInterface>hardware_interface/VelocityJointInterface</hardwareInterface>
      </joint>
    </transmission-->
  <transmission name="outer_leg_extension_right_3_trans" type="SimpleTransmission">
    <type>transmission_interface/SimpleTransmission</type>
    <actuator name="outer_leg_extension_right_3_motor">
      <hardwareInterface>hardware_interface/PositionJointInterface</hardwareInterface>
      <mechanicalReduction>1</mechanicalReduction>
    </actuator>
    <joint name="hip_to_outer_leg_right_3">
      <hardwareInterface>hardware_interface/PositionJointInterface</hardwareInterface>
    </joint>
  </transmission>
  <transmission name="center_leg_extension_right_3_trans" type="SimpleTransmission">
    <type>transmission_interface/SimpleTransmission</type>
    <actuator name="center_leg_extension_right_3_motor">
      <hardwareInterface>hardware_interface/PositionJointInterface</hardwareInterface>
      <mechanicalReduction>1</mechanicalReduction>
    </actuator>
    <joint name="outer_to_center_leg_right_3">
      <hardwareInterface>hardware_interface/PositionJointInterface</hardwareInterface>
    </joint>
  </transmission>
  <transmission name="inner_leg_extension_right_3_trans" type="SimpleTransmission">
    <type>transmission_interface/SimpleTransmission</type>
    <actuator name="inner_leg_extension_right_3_motor">
      <hardwareInterface>hardware_interface/PositionJointInterface</hardwareInterface>
      <mechanicalReduction>1</mechanicalReduction>
    </actuator>
    <joint name="center_to_inner_leg_right_3">
      <hardwareInterface>hardware_interface/PositionJointInterface</hardwareInterface>
    </joint>
  </transmission>
  <link name="hip_right_5">
    <visual>
      <geometry>
        <cylinder length="0.14" radius="0.02"/>
      </geometry>
      <material name="black"/>
    </visual>
    <collision>
      <geometry>
        <cylinder length="0.14" radius="0.02"/>
      </geometry>
    </collision>
    <inertial>
      <mass value="0.3"/>
      <inertia ixx="0.0004900000000000001" ixy="0.0" ixz="0.0" iyy="0.0" iyz="0.0" izz="0.0004900000000000001"/>
    </inertial>
  </link>
  <link name="outer_leg_right_5">
    <visual>
      <geometry>
        <cylinder length="0.14" radius="0.016"/>
      </geometry>
      <material name="black"/>
    </visual>
    <collision>
      <geometry>
        <cylinder length="0.14" radius="0.016"/>
      </geometry>
    </collision>
    <inertial>
      <mass value="0.24"/>
      <inertia ixx="0.0003920000000000001" ixy="0.0" ixz="0.0" iyy="0.0" iyz="0.0" izz="0.0003920000000000001"/>
    </inertial>
  </link>
  <link name="center_leg_right_5">
    <visual>
      <geometry>
        <cylinder length="0.14" radius="0.012"/>
      </geometry>
      <material name="black"/>
    </visual>
    <collision>
      <geometry>
        <cylinder length="0.14" radius="0.012"/>
      </geometry>
    </collision>
    <inertial>
      <mass value="0.18"/>
      <inertia ixx="0.000294" ixy="0.0" ixz="0.0" iyy="0.000294" iyz="0.0" izz="0.0"/>
    </inertial>
  </link>
  <link name="inner_leg_right_5">
    <visual>
      <geometry>
        <cylinder length="0.14" radius="0.008"/>
      </geometry>
      <material name="black"/>
    </visual>
    <collision>
      <geometry>
        <cylinder length="0.14" radius="0.008"/>
      </geometry>
    </collision>
    <inertial>
      <mass value="0.12"/>
      <inertia ixx="0.00019600000000000005" ixy="0.0" ixz="0.0" iyy="0.00019600000000000005" iyz="0.0" izz="0.0"/>
    </inertial>
  </link>
  <joint name="base_to_hip_right_5" type="fixed">
    <parent link="filler_link"/>
    <child link="hip_right_5"/>
    <origin rpy="0 3.9269908169872414 0" xyz="-0.09899494936611665 0.4 -0.09899494936611669"/>
  </joint>
  <!--
    <joint name="outer_to_center_leg_${prefix}" type="fixed">
       <parent link="outer_leg_${prefix}"/>
       <child link="center_leg_${prefix}"/>
       <origin xyz="0 0 0.02"/>
    </joint>
    <joint name="center_to_inner_leg_${prefix}" type="fixed">
       <parent link="center_leg_${prefix}"/>
       <child link="inner_leg_${prefix}"/>
       <origin xyz="0 0 0.02"/>
    </joint>
    -->
  <joint name="hip_to_outer_leg_right_5" type="prismatic">
    <axis xyz="0 0 1"/>
    <parent link="hip_right_5"/>
    <child link="outer_leg_right_5"/>
    <limit effort="3000.0" lower="0.0" upper="0.14" velocity="0.1"/>
    <origin rpy="0 0 0" xyz="0 0 0"/>
    <dynamics damping="100.0" friction="200.0"/>
  </joint>
  <joint name="outer_to_center_leg_right_5" type="prismatic">
    <axis xyz="0 0 1"/>
    <parent link="outer_leg_right_5"/>
    <child link="center_leg_right_5"/>
    <limit effort="3000.0" lower="0.0" upper="0.14" velocity="0.1"/>
    <origin rpy="0 0 0" xyz="0 0 0"/>
    <dynamics damping="100.0" friction="200.0"/>
  </joint>
  <joint name="center_to_inner_leg_right_5" type="prismatic">
    <axis xyz="0 0 1"/>
    <parent link="center_leg_right_5"/>
    <child link="inner_leg_right_5"/>
    <limit effort="3000.0" lower="0.0" upper="0.14" velocity="0.1"/>
    <origin rpy="0 0 0" xyz="0 0 0"/>
    <dynamics damping="100.0" friction="200.0"/>
  </joint>
  <!--transmission name="base_to_hip_${prefix}">
      <type>transmission_interface/SimpleTransmission</type>
      <actuator name="$base_to_hip_${prefix}">
        <mechanicalReduction>1</mechanicalReduction>
      </actuator>
      <joint name="base_to_hip_${prefix}">
        <hardwareInterface>hardware_interface/VelocityJointInterface</hardwareInterface>
      </joint>
    </transmission-->
  <transmission name="outer_leg_extension_right_5_trans" type="SimpleTransmission">
    <type>transmission_interface/SimpleTransmission</type>
    <actuator name="outer_leg_extension_right_5_motor">
      <hardwareInterface>hardware_interface/PositionJointInterface</hardwareInterface>
      <mechanicalReduction>1</mechanicalReduction>
    </actuator>
    <joint name="hip_to_outer_leg_right_5">
      <hardwareInterface>hardware_interface/PositionJointInterface</hardwareInterface>
    </joint>
  </transmission>
  <transmission name="center_leg_extension_right_5_trans" type="SimpleTransmission">
    <type>transmission_interface/SimpleTransmission</type>
    <actuator name="center_leg_extension_right_5_motor">
      <hardwareInterface>hardware_interface/PositionJointInterface</hardwareInterface>
      <mechanicalReduction>1</mechanicalReduction>
    </actuator>
    <joint name="outer_to_center_leg_right_5">
      <hardwareInterface>hardware_interface/PositionJointInterface</hardwareInterface>
    </joint>
  </transmission>
  <transmission name="inner_leg_extension_right_5_trans" type="SimpleTransmission">
    <type>transmission_interface/SimpleTransmission</type>
    <actuator name="inner_leg_extension_right_5_motor">
      <hardwareInterface>hardware_interface/PositionJointInterface</hardwareInterface>
      <mechanicalReduction>1</mechanicalReduction>
    </actuator>
    <joint name="center_to_inner_leg_right_5">
      <hardwareInterface>hardware_interface/PositionJointInterface</hardwareInterface>
    </joint>
  </transmission>
  <link name="hip_right_7">
    <visual>
      <geometry>
        <cylinder length="0.14" radius="0.02"/>
      </geometry>
      <material name="black"/>
    </visual>
    <collision>
      <geometry>
        <cylinder length="0.14" radius="0.02"/>
      </geometry>
    </collision>
    <inertial>
      <mass value="0.3"/>
      <inertia ixx="0.0004900000000000001" ixy="0.0" ixz="0.0" iyy="0.0" iyz="0.0" izz="0.0004900000000000001"/>
    </inertial>
  </link>
  <link name="outer_leg_right_7">
    <visual>
      <geometry>
        <cylinder length="0.14" radius="0.016"/>
      </geometry>
      <material name="black"/>
    </visual>
    <collision>
      <geometry>
        <cylinder length="0.14" radius="0.016"/>
      </geometry>
    </collision>
    <inertial>
      <mass value="0.24"/>
      <inertia ixx="0.0003920000000000001" ixy="0.0" ixz="0.0" iyy="0.0" iyz="0.0" izz="0.0003920000000000001"/>
    </inertial>
  </link>
  <link name="center_leg_right_7">
    <visual>
      <geometry>
        <cylinder length="0.14" radius="0.012"/>
      </geometry>
      <material name="black"/>
    </visual>
    <collision>
      <geometry>
        <cylinder length="0.14" radius="0.012"/>
      </geometry>
    </collision>
    <inertial>
      <mass value="0.18"/>
      <inertia ixx="0.000294" ixy="0.0" ixz="0.0" iyy="0.000294" iyz="0.0" izz="0.0"/>
    </inertial>
  </link>
  <link name="inner_leg_right_7">
    <visual>
      <geometry>
        <cylinder length="0.14" radius="0.008"/>
      </geometry>
      <material name="black"/>
    </visual>
    <collision>
      <geometry>
        <cylinder length="0.14" radius="0.008"/>
      </geometry>
    </collision>
    <inertial>
      <mass value="0.12"/>
      <inertia ixx="0.00019600000000000005" ixy="0.0" ixz="0.0" iyy="0.00019600000000000005" iyz="0.0" izz="0.0"/>
    </inertial>
  </link>
  <joint name="base_to_hip_right_7" type="fixed">
    <parent link="filler_link"/>
    <child link="hip_right_7"/>
    <origin rpy="0 5.497787143782138 0" xyz="-0.09899494936611669 0.4 0.09899494936611664"/>
  </joint>
  <!--
    <joint name="outer_to_center_leg_${prefix}" type="fixed">
       <parent link="outer_leg_${prefix}"/>
       <child link="center_leg_${prefix}"/>
       <origin xyz="0 0 0.02"/>
    </joint>
    <joint name="center_to_inner_leg_${prefix}" type="fixed">
       <parent link="center_leg_${prefix}"/>
       <child link="inner_leg_${prefix}"/>
       <origin xyz="0 0 0.02"/>
    </joint>
    -->
  <joint name="hip_to_outer_leg_right_7" type="prismatic">
    <axis xyz="0 0 1"/>
    <parent link="hip_right_7"/>
    <child link="outer_leg_right_7"/>
    <limit effort="3000.0" lower="0.0" upper="0.14" velocity="0.1"/>
    <origin rpy="0 0 0" xyz="0 0 0"/>
    <dynamics damping="100.0" friction="200.0"/>
  </joint>
  <joint name="outer_to_center_leg_right_7" type="prismatic">
    <axis xyz="0 0 1"/>
    <parent link="outer_leg_right_7"/>
    <child link="center_leg_right_7"/>
    <limit effort="3000.0" lower="0.0" upper="0.14" velocity="0.1"/>
    <origin rpy="0 0 0" xyz="0 0 0"/>
    <dynamics damping="100.0" friction="200.0"/>
  </joint>
  <joint name="center_to_inner_leg_right_7" type="prismatic">
    <axis xyz="0 0 1"/>
    <parent link="center_leg_right_7"/>
    <child link="inner_leg_right_7"/>
    <limit effort="3000.0" lower="0.0" upper="0.14" velocity="0.1"/>
    <origin rpy="0 0 0" xyz="0 0 0"/>
    <dynamics damping="100.0" friction="200.0"/>
  </joint>
  <!--transmission name="base_to_hip_${prefix}">
      <type>transmission_interface/SimpleTransmission</type>
      <actuator name="$base_to_hip_${prefix}">
        <mechanicalReduction>1</mechanicalReduction>
      </actuator>
      <joint name="base_to_hip_${prefix}">
        <hardwareInterface>hardware_interface/VelocityJointInterface</hardwareInterface>
      </joint>
    </transmission-->
  <transmission name="outer_leg_extension_right_7_trans" type="SimpleTransmission">
    <type>transmission_interface/SimpleTransmission</type>
    <actuator name="outer_leg_extension_right_7_motor">
      <hardwareInterface>hardware_interface/PositionJointInterface</hardwareInterface>
      <mechanicalReduction>1</mechanicalReduction>
    </actuator>
    <joint name="hip_to_outer_leg_right_7">
      <hardwareInterface>hardware_interface/PositionJointInterface</hardwareInterface>
    </joint>
  </transmission>
  <transmission name="center_leg_extension_right_7_trans" type="SimpleTransmission">
    <type>transmission_interface/SimpleTransmission</type>
    <actuator name="center_leg_extension_right_7_motor">
      <hardwareInterface>hardware_interface/PositionJointInterface</hardwareInterface>
      <mechanicalReduction>1</mechanicalReduction>
    </actuator>
    <joint name="outer_to_center_leg_right_7">
      <hardwareInterface>hardware_interface/PositionJointInterface</hardwareInterface>
    </joint>
  </transmission>
  <transmission name="inner_leg_extension_right_7_trans" type="SimpleTransmission">
    <type>transmission_interface/SimpleTransmission</type>
    <actuator name="inner_leg_extension_right_7_motor">
      <hardwareInterface>hardware_interface/PositionJointInterface</hardwareInterface>
      <mechanicalReduction>1</mechanicalReduction>
    </actuator>
    <joint name="center_to_inner_leg_right_7">
      <hardwareInterface>hardware_interface/PositionJointInterface</hardwareInterface>
    </joint>
  </transmission>
  <link name="hip_left_0">
    <visual>
      <geometry>
        <cylinder length="0.14" radius="0.02"/>
      </geometry>
      <material name="black"/>
    </visual>
    <collision>
      <geometry>
        <cylinder length="0.14" radius="0.02"/>
      </geometry>
    </collision>
    <inertial>
      <mass value="0.3"/>
      <inertia ixx="0.0004900000000000001" ixy="0.0" ixz="0.0" iyy="0.0" iyz="0.0" izz="0.0004900000000000001"/>
    </inertial>
  </link>
  <link name="outer_leg_left_0">
    <visual>
      <geometry>
        <cylinder length="0.14" radius="0.016"/>
      </geometry>
      <material name="black"/>
    </visual>
    <collision>
      <geometry>
        <cylinder length="0.14" radius="0.016"/>
      </geometry>
    </collision>
    <inertial>
      <mass value="0.24"/>
      <inertia ixx="0.0003920000000000001" ixy="0.0" ixz="0.0" iyy="0.0" iyz="0.0" izz="0.0003920000000000001"/>
    </inertial>
  </link>
  <link name="center_leg_left_0">
    <visual>
      <geometry>
        <cylinder length="0.14" radius="0.012"/>
      </geometry>
      <material name="black"/>
    </visual>
    <collision>
      <geometry>
        <cylinder length="0.14" radius="0.012"/>
      </geometry>
    </collision>
    <inertial>
      <mass value="0.18"/>
      <inertia ixx="0.000294" ixy="0.0" ixz="0.0" iyy="0.000294" iyz="0.0" izz="0.0"/>
    </inertial>
  </link>
  <link name="inner_leg_left_0">
    <visual>
      <geometry>
        <cylinder length="0.14" radius="0.008"/>
      </geometry>
      <material name="black"/>
    </visual>
    <collision>
      <geometry>
        <cylinder length="0.14" radius="0.008"/>
      </geometry>
    </collision>
    <inertial>
      <mass value="0.12"/>
      <inertia ixx="0.00019600000000000005" ixy="0.0" ixz="0.0" iyy="0.00019600000000000005" iyz="0.0" izz="0.0"/>
    </inertial>
  </link>
  <joint name="base_to_hip_left_0" type="fixed">
    <parent link="filler_link"/>
    <child link="hip_left_0"/>
    <origin rpy="0 0.0 0" xyz="0.0 -0.4 0.14"/>
  </joint>
  <!--
    <joint name="outer_to_center_leg_${prefix}" type="fixed">
       <parent link="outer_leg_${prefix}"/>
       <child link="center_leg_${prefix}"/>
       <origin xyz="0 0 0.02"/>
    </joint>
    <joint name="center_to_inner_leg_${prefix}" type="fixed">
       <parent link="center_leg_${prefix}"/>
       <child link="inner_leg_${prefix}"/>
       <origin xyz="0 0 0.02"/>
    </joint>
    -->
  <joint name="hip_to_outer_leg_left_0" type="prismatic">
    <axis xyz="0 0 1"/>
    <parent link="hip_left_0"/>
    <child link="outer_leg_left_0"/>
    <limit effort="3000.0" lower="0.0" upper="0.14" velocity="0.1"/>
    <origin rpy="0 0 0" xyz="0 0 0"/>
    <dynamics damping="100.0" friction="200.0"/>
  </joint>
  <joint name="outer_to_center_leg_left_0" type="prismatic">
    <axis xyz="0 0 1"/>
    <parent link="outer_leg_left_0"/>
    <child link="center_leg_left_0"/>
    <limit effort="3000.0" lower="0.0" upper="0.14" velocity="0.1"/>
    <origin rpy="0 0 0" xyz="0 0 0"/>
    <dynamics damping="100.0" friction="200.0"/>
  </joint>
  <joint name="center_to_inner_leg_left_0" type="prismatic">
    <axis xyz="0 0 1"/>
    <parent link="center_leg_left_0"/>
    <child link="inner_leg_left_0"/>
    <limit effort="3000.0" lower="0.0" upper="0.14" velocity="0.1"/>
    <origin rpy="0 0 0" xyz="0 0 0"/>
    <dynamics damping="100.0" friction="200.0"/>
  </joint>
  <!--transmission name="base_to_hip_${prefix}">
      <type>transmission_interface/SimpleTransmission</type>
      <actuator name="$base_to_hip_${prefix}">
        <mechanicalReduction>1</mechanicalReduction>
      </actuator>
      <joint name="base_to_hip_${prefix}">
        <hardwareInterface>hardware_interface/VelocityJointInterface</hardwareInterface>
      </joint>
    </transmission-->
  <transmission name="outer_leg_extension_left_0_trans" type="SimpleTransmission">
    <type>transmission_interface/SimpleTransmission</type>
    <actuator name="outer_leg_extension_left_0_motor">
      <hardwareInterface>hardware_interface/PositionJointInterface</hardwareInterface>
      <mechanicalReduction>1</mechanicalReduction>
    </actuator>
    <joint name="hip_to_outer_leg_left_0">
      <hardwareInterface>hardware_interface/PositionJointInterface</hardwareInterface>
    </joint>
  </transmission>
  <transmission name="center_leg_extension_left_0_trans" type="SimpleTransmission">
    <type>transmission_interface/SimpleTransmission</type>
    <actuator name="center_leg_extension_left_0_motor">
      <hardwareInterface>hardware_interface/PositionJointInterface</hardwareInterface>
      <mechanicalReduction>1</mechanicalReduction>
    </actuator>
    <joint name="outer_to_center_leg_left_0">
      <hardwareInterface>hardware_interface/PositionJointInterface</hardwareInterface>
    </joint>
  </transmission>
  <transmission name="inner_leg_extension_left_0_trans" type="SimpleTransmission">
    <type>transmission_interface/SimpleTransmission</type>
    <actuator name="inner_leg_extension_left_0_motor">
      <hardwareInterface>hardware_interface/PositionJointInterface</hardwareInterface>
      <mechanicalReduction>1</mechanicalReduction>
    </actuator>
    <joint name="center_to_inner_leg_left_0">
      <hardwareInterface>hardware_interface/PositionJointInterface</hardwareInterface>
    </joint>
  </transmission>
  <link name="hip_left_2">
    <visual>
      <geometry>
        <cylinder length="0.14" radius="0.02"/>
      </geometry>
      <material name="black"/>
    </visual>
    <collision>
      <geometry>
        <cylinder length="0.14" radius="0.02"/>
      </geometry>
    </collision>
    <inertial>
      <mass value="0.3"/>
      <inertia ixx="0.0004900000000000001" ixy="0.0" ixz="0.0" iyy="0.0" iyz="0.0" izz="0.0004900000000000001"/>
    </inertial>
  </link>
  <link name="outer_leg_left_2">
    <visual>
      <geometry>
        <cylinder length="0.14" radius="0.016"/>
      </geometry>
      <material name="black"/>
    </visual>
    <collision>
      <geometry>
        <cylinder length="0.14" radius="0.016"/>
      </geometry>
    </collision>
    <inertial>
      <mass value="0.24"/>
      <inertia ixx="0.0003920000000000001" ixy="0.0" ixz="0.0" iyy="0.0" iyz="0.0" izz="0.0003920000000000001"/>
    </inertial>
  </link>
  <link name="center_leg_left_2">
    <visual>
      <geometry>
        <cylinder length="0.14" radius="0.012"/>
      </geometry>
      <material name="black"/>
    </visual>
    <collision>
      <geometry>
        <cylinder length="0.14" radius="0.012"/>
      </geometry>
    </collision>
    <inertial>
      <mass value="0.18"/>
      <inertia ixx="0.000294" ixy="0.0" ixz="0.0" iyy="0.000294" iyz="0.0" izz="0.0"/>
    </inertial>
  </link>
  <link name="inner_leg_left_2">
    <visual>
      <geometry>
        <cylinder length="0.14" radius="0.008"/>
      </geometry>
      <material name="black"/>
    </visual>
    <collision>
      <geometry>
        <cylinder length="0.14" radius="0.008"/>
      </geometry>
    </collision>
    <inertial>
      <mass value="0.12"/>
      <inertia ixx="0.00019600000000000005" ixy="0.0" ixz="0.0" iyy="0.00019600000000000005" iyz="0.0" izz="0.0"/>
    </inertial>
  </link>
  <joint name="base_to_hip_left_2" type="fixed">
    <parent link="filler_link"/>
    <child link="hip_left_2"/>
    <origin rpy="0 1.5707963267948966 0" xyz="0.14 -0.4 8.572527594031473e-18"/>
  </joint>
  <!--
    <joint name="outer_to_center_leg_${prefix}" type="fixed">
       <parent link="outer_leg_${prefix}"/>
       <child link="center_leg_${prefix}"/>
       <origin xyz="0 0 0.02"/>
    </joint>
    <joint name="center_to_inner_leg_${prefix}" type="fixed">
       <parent link="center_leg_${prefix}"/>
       <child link="inner_leg_${prefix}"/>
       <origin xyz="0 0 0.02"/>
    </joint>
    -->
  <joint name="hip_to_outer_leg_left_2" type="prismatic">
    <axis xyz="0 0 1"/>
    <parent link="hip_left_2"/>
    <child link="outer_leg_left_2"/>
    <limit effort="3000.0" lower="0.0" upper="0.14" velocity="0.1"/>
    <origin rpy="0 0 0" xyz="0 0 0"/>
    <dynamics damping="100.0" friction="200.0"/>
  </joint>
  <joint name="outer_to_center_leg_left_2" type="prismatic">
    <axis xyz="0 0 1"/>
    <parent link="outer_leg_left_2"/>
    <child link="center_leg_left_2"/>
    <limit effort="3000.0" lower="0.0" upper="0.14" velocity="0.1"/>
    <origin rpy="0 0 0" xyz="0 0 0"/>
    <dynamics damping="100.0" friction="200.0"/>
  </joint>
  <joint name="center_to_inner_leg_left_2" type="prismatic">
    <axis xyz="0 0 1"/>
    <parent link="center_leg_left_2"/>
    <child link="inner_leg_left_2"/>
    <limit effort="3000.0" lower="0.0" upper="0.14" velocity="0.1"/>
    <origin rpy="0 0 0" xyz="0 0 0"/>
    <dynamics damping="100.0" friction="200.0"/>
  </joint>
  <!--transmission name="base_to_hip_${prefix}">
      <type>transmission_interface/SimpleTransmission</type>
      <actuator name="$base_to_hip_${prefix}">
        <mechanicalReduction>1</mechanicalReduction>
      </actuator>
      <joint name="base_to_hip_${prefix}">
        <hardwareInterface>hardware_interface/VelocityJointInterface</hardwareInterface>
      </joint>
    </transmission-->
  <transmission name="outer_leg_extension_left_2_trans" type="SimpleTransmission">
    <type>transmission_interface/SimpleTransmission</type>
    <actuator name="outer_leg_extension_left_2_motor">
      <hardwareInterface>hardware_interface/PositionJointInterface</hardwareInterface>
      <mechanicalReduction>1</mechanicalReduction>
    </actuator>
    <joint name="hip_to_outer_leg_left_2">
      <hardwareInterface>hardware_interface/PositionJointInterface</hardwareInterface>
    </joint>
  </transmission>
  <transmission name="center_leg_extension_left_2_trans" type="SimpleTransmission">
    <type>transmission_interface/SimpleTransmission</type>
    <actuator name="center_leg_extension_left_2_motor">
      <hardwareInterface>hardware_interface/PositionJointInterface</hardwareInterface>
      <mechanicalReduction>1</mechanicalReduction>
    </actuator>
    <joint name="outer_to_center_leg_left_2">
      <hardwareInterface>hardware_interface/PositionJointInterface</hardwareInterface>
    </joint>
  </transmission>
  <transmission name="inner_leg_extension_left_2_trans" type="SimpleTransmission">
    <type>transmission_interface/SimpleTransmission</type>
    <actuator name="inner_leg_extension_left_2_motor">
      <hardwareInterface>hardware_interface/PositionJointInterface</hardwareInterface>
      <mechanicalReduction>1</mechanicalReduction>
    </actuator>
    <joint name="center_to_inner_leg_left_2">
      <hardwareInterface>hardware_interface/PositionJointInterface</hardwareInterface>
    </joint>
  </transmission>
  <link name="hip_left_4">
    <visual>
      <geometry>
        <cylinder length="0.14" radius="0.02"/>
      </geometry>
      <material name="black"/>
    </visual>
    <collision>
      <geometry>
        <cylinder length="0.14" radius="0.02"/>
      </geometry>
    </collision>
    <inertial>
      <mass value="0.3"/>
      <inertia ixx="0.0004900000000000001" ixy="0.0" ixz="0.0" iyy="0.0" iyz="0.0" izz="0.0004900000000000001"/>
    </inertial>
  </link>
  <link name="outer_leg_left_4">
    <visual>
      <geometry>
        <cylinder length="0.14" radius="0.016"/>
      </geometry>
      <material name="black"/>
    </visual>
    <collision>
      <geometry>
        <cylinder length="0.14" radius="0.016"/>
      </geometry>
    </collision>
    <inertial>
      <mass value="0.24"/>
      <inertia ixx="0.0003920000000000001" ixy="0.0" ixz="0.0" iyy="0.0" iyz="0.0" izz="0.0003920000000000001"/>
    </inertial>
  </link>
  <link name="center_leg_left_4">
    <visual>
      <geometry>
        <cylinder length="0.14" radius="0.012"/>
      </geometry>
      <material name="black"/>
    </visual>
    <collision>
      <geometry>
        <cylinder length="0.14" radius="0.012"/>
      </geometry>
    </collision>
    <inertial>
      <mass value="0.18"/>
      <inertia ixx="0.000294" ixy="0.0" ixz="0.0" iyy="0.000294" iyz="0.0" izz="0.0"/>
    </inertial>
  </link>
  <link name="inner_leg_left_4">
    <visual>
      <geometry>
        <cylinder length="0.14" radius="0.008"/>
      </geometry>
      <material name="black"/>
    </visual>
    <collision>
      <geometry>
        <cylinder length="0.14" radius="0.008"/>
      </geometry>
    </collision>
    <inertial>
      <mass value="0.12"/>
      <inertia ixx="0.00019600000000000005" ixy="0.0" ixz="0.0" iyy="0.00019600000000000005" iyz="0.0" izz="0.0"/>
    </inertial>
  </link>
  <joint name="base_to_hip_left_4" type="fixed">
    <parent link="filler_link"/>
    <child link="hip_left_4"/>
    <origin rpy="0 3.141592653589793 0" xyz="1.7145055188062947e-17 -0.4 -0.14"/>
  </joint>
  <!--
    <joint name="outer_to_center_leg_${prefix}" type="fixed">
       <parent link="outer_leg_${prefix}"/>
       <child link="center_leg_${prefix}"/>
       <origin xyz="0 0 0.02"/>
    </joint>
    <joint name="center_to_inner_leg_${prefix}" type="fixed">
       <parent link="center_leg_${prefix}"/>
       <child link="inner_leg_${prefix}"/>
       <origin xyz="0 0 0.02"/>
    </joint>
    -->
  <joint name="hip_to_outer_leg_left_4" type="prismatic">
    <axis xyz="0 0 1"/>
    <parent link="hip_left_4"/>
    <child link="outer_leg_left_4"/>
    <limit effort="3000.0" lower="0.0" upper="0.14" velocity="0.1"/>
    <origin rpy="0 0 0" xyz="0 0 0"/>
    <dynamics damping="100.0" friction="200.0"/>
  </joint>
  <joint name="outer_to_center_leg_left_4" type="prismatic">
    <axis xyz="0 0 1"/>
    <parent link="outer_leg_left_4"/>
    <child link="center_leg_left_4"/>
    <limit effort="3000.0" lower="0.0" upper="0.14" velocity="0.1"/>
    <origin rpy="0 0 0" xyz="0 0 0"/>
    <dynamics damping="100.0" friction="200.0"/>
  </joint>
  <joint name="center_to_inner_leg_left_4" type="prismatic">
    <axis xyz="0 0 1"/>
    <parent link="center_leg_left_4"/>
    <child link="inner_leg_left_4"/>
    <limit effort="3000.0" lower="0.0" upper="0.14" velocity="0.1"/>
    <origin rpy="0 0 0" xyz="0 0 0"/>
    <dynamics damping="100.0" friction="200.0"/>
  </joint>
  <!--transmission name="base_to_hip_${prefix}">
      <type>transmission_interface/SimpleTransmission</type>
      <actuator name="$base_to_hip_${prefix}">
        <mechanicalReduction>1</mechanicalReduction>
      </actuator>
      <joint name="base_to_hip_${prefix}">
        <hardwareInterface>hardware_interface/VelocityJointInterface</hardwareInterface>
      </joint>
    </transmission-->
  <transmission name="outer_leg_extension_left_4_trans" type="SimpleTransmission">
    <type>transmission_interface/SimpleTransmission</type>
    <actuator name="outer_leg_extension_left_4_motor">
      <hardwareInterface>hardware_interface/PositionJointInterface</hardwareInterface>
      <mechanicalReduction>1</mechanicalReduction>
    </actuator>
    <joint name="hip_to_outer_leg_left_4">
      <hardwareInterface>hardware_interface/PositionJointInterface</hardwareInterface>
    </joint>
  </transmission>
  <transmission name="center_leg_extension_left_4_trans" type="SimpleTransmission">
    <type>transmission_interface/SimpleTransmission</type>
    <actuator name="center_leg_extension_left_4_motor">
      <hardwareInterface>hardware_interface/PositionJointInterface</hardwareInterface>
      <mechanicalReduction>1</mechanicalReduction>
    </actuator>
    <joint name="outer_to_center_leg_left_4">
      <hardwareInterface>hardware_interface/PositionJointInterface</hardwareInterface>
    </joint>
  </transmission>
  <transmission name="inner_leg_extension_left_4_trans" type="SimpleTransmission">
    <type>transmission_interface/SimpleTransmission</type>
    <actuator name="inner_leg_extension_left_4_motor">
      <hardwareInterface>hardware_interface/PositionJointInterface</hardwareInterface>
      <mechanicalReduction>1</mechanicalReduction>
    </actuator>
    <joint name="center_to_inner_leg_left_4">
      <hardwareInterface>hardware_interface/PositionJointInterface</hardwareInterface>
    </joint>
  </transmission>
  <link name="hip_left_6">
    <visual>
      <geometry>
        <cylinder length="0.14" radius="0.02"/>
      </geometry>
      <material name="black"/>
    </visual>
    <collision>
      <geometry>
        <cylinder length="0.14" radius="0.02"/>
      </geometry>
    </collision>
    <inertial>
      <mass value="0.3"/>
      <inertia ixx="0.0004900000000000001" ixy="0.0" ixz="0.0" iyy="0.0" iyz="0.0" izz="0.0004900000000000001"/>
    </inertial>
  </link>
  <link name="outer_leg_left_6">
    <visual>
      <geometry>
        <cylinder length="0.14" radius="0.016"/>
      </geometry>
      <material name="black"/>
    </visual>
    <collision>
      <geometry>
        <cylinder length="0.14" radius="0.016"/>
      </geometry>
    </collision>
    <inertial>
      <mass value="0.24"/>
      <inertia ixx="0.0003920000000000001" ixy="0.0" ixz="0.0" iyy="0.0" iyz="0.0" izz="0.0003920000000000001"/>
    </inertial>
  </link>
  <link name="center_leg_left_6">
    <visual>
      <geometry>
        <cylinder length="0.14" radius="0.012"/>
      </geometry>
      <material name="black"/>
    </visual>
    <collision>
      <geometry>
        <cylinder length="0.14" radius="0.012"/>
      </geometry>
    </collision>
    <inertial>
      <mass value="0.18"/>
      <inertia ixx="0.000294" ixy="0.0" ixz="0.0" iyy="0.000294" iyz="0.0" izz="0.0"/>
    </inertial>
  </link>
  <link name="inner_leg_left_6">
    <visual>
      <geometry>
        <cylinder length="0.14" radius="0.008"/>
      </geometry>
      <material name="black"/>
    </visual>
    <collision>
      <geometry>
        <cylinder length="0.14" radius="0.008"/>
      </geometry>
    </collision>
    <inertial>
      <mass value="0.12"/>
      <inertia ixx="0.00019600000000000005" ixy="0.0" ixz="0.0" iyy="0.00019600000000000005" iyz="0.0" izz="0.0"/>
    </inertial>
  </link>
  <joint name="base_to_hip_left_6" type="fixed">
    <parent link="filler_link"/>
    <child link="hip_left_6"/>
    <origin rpy="0 4.71238898038469 0" xyz="-0.14 -0.4 -2.571758278209442e-17"/>
  </joint>
  <!--
    <joint name="outer_to_center_leg_${prefix}" type="fixed">
       <parent link="outer_leg_${prefix}"/>
       <child link="center_leg_${prefix}"/>
       <origin xyz="0 0 0.02"/>
    </joint>
    <joint name="center_to_inner_leg_${prefix}" type="fixed">
       <parent link="center_leg_${prefix}"/>
       <child link="inner_leg_${prefix}"/>
       <origin xyz="0 0 0.02"/>
    </joint>
    -->
  <joint name="hip_to_outer_leg_left_6" type="prismatic">
    <axis xyz="0 0 1"/>
    <parent link="hip_left_6"/>
    <child link="outer_leg_left_6"/>
    <limit effort="3000.0" lower="0.0" upper="0.14" velocity="0.1"/>
    <origin rpy="0 0 0" xyz="0 0 0"/>
    <dynamics damping="100.0" friction="200.0"/>
  </joint>
  <joint name="outer_to_center_leg_left_6" type="prismatic">
    <axis xyz="0 0 1"/>
    <parent link="outer_leg_left_6"/>
    <child link="center_leg_left_6"/>
    <limit effort="3000.0" lower="0.0" upper="0.14" velocity="0.1"/>
    <origin rpy="0 0 0" xyz="0 0 0"/>
    <dynamics damping="100.0" friction="200.0"/>
  </joint>
  <joint name="center_to_inner_leg_left_6" type="prismatic">
    <axis xyz="0 0 1"/>
    <parent link="center_leg_left_6"/>
    <child link="inner_leg_left_6"/>
    <limit effort="3000.0" lower="0.0" upper="0.14" velocity="0.1"/>
    <origin rpy="0 0 0" xyz="0 0 0"/>
    <dynamics damping="100.0" friction="200.0"/>
  </joint>
  <!--transmission name="base_to_hip_${prefix}">
      <type>transmission_interface/SimpleTransmission</type>
      <actuator name="$base_to_hip_${prefix}">
        <mechanicalReduction>1</mechanicalReduction>
      </actuator>
      <joint name="base_to_hip_${prefix}">
        <hardwareInterface>hardware_interface/VelocityJointInterface</hardwareInterface>
      </joint>
    </transmission-->
  <transmission name="outer_leg_extension_left_6_trans" type="SimpleTransmission">
    <type>transmission_interface/SimpleTransmission</type>
    <actuator name="outer_leg_extension_left_6_motor">
      <hardwareInterface>hardware_interface/PositionJointInterface</hardwareInterface>
      <mechanicalReduction>1</mechanicalReduction>
    </actuator>
    <joint name="hip_to_outer_leg_left_6">
      <hardwareInterface>hardware_interface/PositionJointInterface</hardwareInterface>
    </joint>
  </transmission>
  <transmission name="center_leg_extension_left_6_trans" type="SimpleTransmission">
    <type>transmission_interface/SimpleTransmission</type>
    <actuator name="center_leg_extension_left_6_motor">
      <hardwareInterface>hardware_interface/PositionJointInterface</hardwareInterface>
      <mechanicalReduction>1</mechanicalReduction>
    </actuator>
    <joint name="outer_to_center_leg_left_6">
      <hardwareInterface>hardware_interface/PositionJointInterface</hardwareInterface>
    </joint>
  </transmission>
  <transmission name="inner_leg_extension_left_6_trans" type="SimpleTransmission">
    <type>transmission_interface/SimpleTransmission</type>
    <actuator name="inner_leg_extension_left_6_motor">
      <hardwareInterface>hardware_interface/PositionJointInterface</hardwareInterface>
      <mechanicalReduction>1</mechanicalReduction>
    </actuator>
    <joint name="center_to_inner_leg_left_6">
      <hardwareInterface>hardware_interface/PositionJointInterface</hardwareInterface>
    </joint>
  </transmission>
  <link name="hip_left_1">
    <visual>
      <geometry>
        <cylinder length="0.14" radius="0.02"/>
      </geometry>
      <material name="black"/>
    </visual>
    <collision>
      <geometry>
        <cylinder length="0.14" radius="0.02"/>
      </geometry>
    </collision>
    <inertial>
      <mass value="0.3"/>
      <inertia ixx="0.0004900000000000001" ixy="0.0" ixz="0.0" iyy="0.0" iyz="0.0" izz="0.0004900000000000001"/>
    </inertial>
  </link>
  <link name="outer_leg_left_1">
    <visual>
      <geometry>
        <cylinder length="0.14" radius="0.016"/>
      </geometry>
      <material name="black"/>
    </visual>
    <collision>
      <geometry>
        <cylinder length="0.14" radius="0.016"/>
      </geometry>
    </collision>
    <inertial>
      <mass value="0.24"/>
      <inertia ixx="0.0003920000000000001" ixy="0.0" ixz="0.0" iyy="0.0" iyz="0.0" izz="0.0003920000000000001"/>
    </inertial>
  </link>
  <link name="center_leg_left_1">
    <visual>
      <geometry>
        <cylinder length="0.14" radius="0.012"/>
      </geometry>
      <material name="black"/>
    </visual>
    <collision>
      <geometry>
        <cylinder length="0.14" radius="0.012"/>
      </geometry>
    </collision>
    <inertial>
      <mass value="0.18"/>
      <inertia ixx="0.000294" ixy="0.0" ixz="0.0" iyy="0.000294" iyz="0.0" izz="0.0"/>
    </inertial>
  </link>
  <link name="inner_leg_left_1">
    <visual>
      <geometry>
        <cylinder length="0.14" radius="0.008"/>
      </geometry>
      <material name="black"/>
    </visual>
    <collision>
      <geometry>
        <cylinder length="0.14" radius="0.008"/>
      </geometry>
    </collision>
    <inertial>
      <mass value="0.12"/>
      <inertia ixx="0.00019600000000000005" ixy="0.0" ixz="0.0" iyy="0.00019600000000000005" iyz="0.0" izz="0.0"/>
    </inertial>
  </link>
  <joint name="base_to_hip_left_1" type="fixed">
    <parent link="filler_link"/>
    <child link="hip_left_1"/>
    <origin rpy="0 0.7853981633974483 0" xyz="0.09899494936611665 -0.4 0.09899494936611666"/>
  </joint>
  <!--
    <joint name="outer_to_center_leg_${prefix}" type="fixed">
       <parent link="outer_leg_${prefix}"/>
       <child link="center_leg_${prefix}"/>
       <origin xyz="0 0 0.02"/>
    </joint>
    <joint name="center_to_inner_leg_${prefix}" type="fixed">
       <parent link="center_leg_${prefix}"/>
       <child link="inner_leg_${prefix}"/>
       <origin xyz="0 0 0.02"/>
    </joint>
    -->
  <joint name="hip_to_outer_leg_left_1" type="prismatic">
    <axis xyz="0 0 1"/>
    <parent link="hip_left_1"/>
    <child link="outer_leg_left_1"/>
    <limit effort="3000.0" lower="0.0" upper="0.14" velocity="0.1"/>
    <origin rpy="0 0 0" xyz="0 0 0"/>
    <dynamics damping="100.0" friction="200.0"/>
  </joint>
  <joint name="outer_to_center_leg_left_1" type="prismatic">
    <axis xyz="0 0 1"/>
    <parent link="outer_leg_left_1"/>
    <child link="center_leg_left_1"/>
    <limit effort="3000.0" lower="0.0" upper="0.14" velocity="0.1"/>
    <origin rpy="0 0 0" xyz="0 0 0"/>
    <dynamics damping="100.0" friction="200.0"/>
  </joint>
  <joint name="center_to_inner_leg_left_1" type="prismatic">
    <axis xyz="0 0 1"/>
    <parent link="center_leg_left_1"/>
    <child link="inner_leg_left_1"/>
    <limit effort="3000.0" lower="0.0" upper="0.14" velocity="0.1"/>
    <origin rpy="0 0 0" xyz="0 0 0"/>
    <dynamics damping="100.0" friction="200.0"/>
  </joint>
  <!--transmission name="base_to_hip_${prefix}">
      <type>transmission_interface/SimpleTransmission</type>
      <actuator name="$base_to_hip_${prefix}">
        <mechanicalReduction>1</mechanicalReduction>
      </actuator>
      <joint name="base_to_hip_${prefix}">
        <hardwareInterface>hardware_interface/VelocityJointInterface</hardwareInterface>
      </joint>
    </transmission-->
  <transmission name="outer_leg_extension_left_1_trans" type="SimpleTransmission">
    <type>transmission_interface/SimpleTransmission</type>
    <actuator name="outer_leg_extension_left_1_motor">
      <hardwareInterface>hardware_interface/PositionJointInterface</hardwareInterface>
      <mechanicalReduction>1</mechanicalReduction>
    </actuator>
    <joint name="hip_to_outer_leg_left_1">
      <hardwareInterface>hardware_interface/PositionJointInterface</hardwareInterface>
    </joint>
  </transmission>
  <transmission name="center_leg_extension_left_1_trans" type="SimpleTransmission">
    <type>transmission_interface/SimpleTransmission</type>
    <actuator name="center_leg_extension_left_1_motor">
      <hardwareInterface>hardware_interface/PositionJointInterface</hardwareInterface>
      <mechanicalReduction>1</mechanicalReduction>
    </actuator>
    <joint name="outer_to_center_leg_left_1">
      <hardwareInterface>hardware_interface/PositionJointInterface</hardwareInterface>
    </joint>
  </transmission>
  <transmission name="inner_leg_extension_left_1_trans" type="SimpleTransmission">
    <type>transmission_interface/SimpleTransmission</type>
    <actuator name="inner_leg_extension_left_1_motor">
      <hardwareInterface>hardware_interface/PositionJointInterface</hardwareInterface>
      <mechanicalReduction>1</mechanicalReduction>
    </actuator>
    <joint name="center_to_inner_leg_left_1">
      <hardwareInterface>hardware_interface/PositionJointInterface</hardwareInterface>
    </joint>
  </transmission>
  <link name="hip_left_3">
    <visual>
      <geometry>
        <cylinder length="0.14" radius="0.02"/>
      </geometry>
      <material name="black"/>
    </visual>
    <collision>
      <geometry>
        <cylinder length="0.14" radius="0.02"/>
      </geometry>
    </collision>
    <inertial>
      <mass value="0.3"/>
      <inertia ixx="0.0004900000000000001" ixy="0.0" ixz="0.0" iyy="0.0" iyz="0.0" izz="0.0004900000000000001"/>
    </inertial>
  </link>
  <link name="outer_leg_left_3">
    <visual>
      <geometry>
        <cylinder length="0.14" radius="0.016"/>
      </geometry>
      <material name="black"/>
    </visual>
    <collision>
      <geometry>
        <cylinder length="0.14" radius="0.016"/>
      </geometry>
    </collision>
    <inertial>
      <mass value="0.24"/>
      <inertia ixx="0.0003920000000000001" ixy="0.0" ixz="0.0" iyy="0.0" iyz="0.0" izz="0.0003920000000000001"/>
    </inertial>
  </link>
  <link name="center_leg_left_3">
    <visual>
      <geometry>
        <cylinder length="0.14" radius="0.012"/>
      </geometry>
      <material name="black"/>
    </visual>
    <collision>
      <geometry>
        <cylinder length="0.14" radius="0.012"/>
      </geometry>
    </collision>
    <inertial>
      <mass value="0.18"/>
      <inertia ixx="0.000294" ixy="0.0" ixz="0.0" iyy="0.000294" iyz="0.0" izz="0.0"/>
    </inertial>
  </link>
  <link name="inner_leg_left_3">
    <visual>
      <geometry>
        <cylinder length="0.14" radius="0.008"/>
      </geometry>
      <material name="black"/>
    </visual>
    <collision>
      <geometry>
        <cylinder length="0.14" radius="0.008"/>
      </geometry>
    </collision>
    <inertial>
      <mass value="0.12"/>
      <inertia ixx="0.00019600000000000005" ixy="0.0" ixz="0.0" iyy="0.00019600000000000005" iyz="0.0" izz="0.0"/>
    </inertial>
  </link>
  <joint name="base_to_hip_left_3" type="fixed">
    <parent link="filler_link"/>
    <child link="hip_left_3"/>
    <origin rpy="0 2.356194490192345 0" xyz="0.09899494936611666 -0.4 -0.09899494936611665"/>
  </joint>
  <!--
    <joint name="outer_to_center_leg_${prefix}" type="fixed">
       <parent link="outer_leg_${prefix}"/>
       <child link="center_leg_${prefix}"/>
       <origin xyz="0 0 0.02"/>
    </joint>
    <joint name="center_to_inner_leg_${prefix}" type="fixed">
       <parent link="center_leg_${prefix}"/>
       <child link="inner_leg_${prefix}"/>
       <origin xyz="0 0 0.02"/>
    </joint>
    -->
  <joint name="hip_to_outer_leg_left_3" type="prismatic">
    <axis xyz="0 0 1"/>
    <parent link="hip_left_3"/>
    <child link="outer_leg_left_3"/>
    <limit effort="3000.0" lower="0.0" upper="0.14" velocity="0.1"/>
    <origin rpy="0 0 0" xyz="0 0 0"/>
    <dynamics damping="100.0" friction="200.0"/>
  </joint>
  <joint name="outer_to_center_leg_left_3" type="prismatic">
    <axis xyz="0 0 1"/>
    <parent link="outer_leg_left_3"/>
    <child link="center_leg_left_3"/>
    <limit effort="3000.0" lower="0.0" upper="0.14" velocity="0.1"/>
    <origin rpy="0 0 0" xyz="0 0 0"/>
    <dynamics damping="100.0" friction="200.0"/>
  </joint>
  <joint name="center_to_inner_leg_left_3" type="prismatic">
    <axis xyz="0 0 1"/>
    <parent link="center_leg_left_3"/>
    <child link="inner_leg_left_3"/>
    <limit effort="3000.0" lower="0.0" upper="0.14" velocity="0.1"/>
    <origin rpy="0 0 0" xyz="0 0 0"/>
    <dynamics damping="100.0" friction="200.0"/>
  </joint>
  <!--transmission name="base_to_hip_${prefix}">
      <type>transmission_interface/SimpleTransmission</type>
      <actuator name="$base_to_hip_${prefix}">
        <mechanicalReduction>1</mechanicalReduction>
      </actuator>
      <joint name="base_to_hip_${prefix}">
        <hardwareInterface>hardware_interface/VelocityJointInterface</hardwareInterface>
      </joint>
    </transmission-->
  <transmission name="outer_leg_extension_left_3_trans" type="SimpleTransmission">
    <type>transmission_interface/SimpleTransmission</type>
    <actuator name="outer_leg_extension_left_3_motor">
      <hardwareInterface>hardware_interface/PositionJointInterface</hardwareInterface>
      <mechanicalReduction>1</mechanicalReduction>
    </actuator>
    <joint name="hip_to_outer_leg_left_3">
      <hardwareInterface>hardware_interface/PositionJointInterface</hardwareInterface>
    </joint>
  </transmission>
  <transmission name="center_leg_extension_left_3_trans" type="SimpleTransmission">
    <type>transmission_interface/SimpleTransmission</type>
    <actuator name="center_leg_extension_left_3_motor">
      <hardwareInterface>hardware_interface/PositionJointInterface</hardwareInterface>
      <mechanicalReduction>1</mechanicalReduction>
    </actuator>
    <joint name="outer_to_center_leg_left_3">
      <hardwareInterface>hardware_interface/PositionJointInterface</hardwareInterface>
    </joint>
  </transmission>
  <transmission name="inner_leg_extension_left_3_trans" type="SimpleTransmission">
    <type>transmission_interface/SimpleTransmission</type>
    <actuator name="inner_leg_extension_left_3_motor">
      <hardwareInterface>hardware_interface/PositionJointInterface</hardwareInterface>
      <mechanicalReduction>1</mechanicalReduction>
    </actuator>
    <joint name="center_to_inner_leg_left_3">
      <hardwareInterface>hardware_interface/PositionJointInterface</hardwareInterface>
    </joint>
  </transmission>
  <link name="hip_left_5">
    <visual>
      <geometry>
        <cylinder length="0.14" radius="0.02"/>
      </geometry>
      <material name="black"/>
    </visual>
    <collision>
      <geometry>
        <cylinder length="0.14" radius="0.02"/>
      </geometry>
    </collision>
    <inertial>
      <mass value="0.3"/>
      <inertia ixx="0.0004900000000000001" ixy="0.0" ixz="0.0" iyy="0.0" iyz="0.0" izz="0.0004900000000000001"/>
    </inertial>
  </link>
  <link name="outer_leg_left_5">
    <visual>
      <geometry>
        <cylinder length="0.14" radius="0.016"/>
      </geometry>
      <material name="black"/>
    </visual>
    <collision>
      <geometry>
        <cylinder length="0.14" radius="0.016"/>
      </geometry>
    </collision>
    <inertial>
      <mass value="0.24"/>
      <inertia ixx="0.0003920000000000001" ixy="0.0" ixz="0.0" iyy="0.0" iyz="0.0" izz="0.0003920000000000001"/>
    </inertial>
  </link>
  <link name="center_leg_left_5">
    <visual>
      <geometry>
        <cylinder length="0.14" radius="0.012"/>
      </geometry>
      <material name="black"/>
    </visual>
    <collision>
      <geometry>
        <cylinder length="0.14" radius="0.012"/>
      </geometry>
    </collision>
    <inertial>
      <mass value="0.18"/>
      <inertia ixx="0.000294" ixy="0.0" ixz="0.0" iyy="0.000294" iyz="0.0" izz="0.0"/>
    </inertial>
  </link>
  <link name="inner_leg_left_5">
    <visual>
      <geometry>
        <cylinder length="0.14" radius="0.008"/>
      </geometry>
      <material name="black"/>
    </visual>
    <collision>
      <geometry>
        <cylinder length="0.14" radius="0.008"/>
      </geometry>
    </collision>
    <inertial>
      <mass value="0.12"/>
      <inertia ixx="0.00019600000000000005" ixy="0.0" ixz="0.0" iyy="0.00019600000000000005" iyz="0.0" izz="0.0"/>
    </inertial>
  </link>
  <joint name="base_to_hip_left_5" type="fixed">
    <parent link="filler_link"/>
    <child link="hip_left_5"/>
    <origin rpy="0 3.9269908169872414 0" xyz="-0.09899494936611665 -0.4 -0.09899494936611669"/>
  </joint>
  <!--
    <joint name="outer_to_center_leg_${prefix}" type="fixed">
       <parent link="outer_leg_${prefix}"/>
       <child link="center_leg_${prefix}"/>
       <origin xyz="0 0 0.02"/>
    </joint>
    <joint name="center_to_inner_leg_${prefix}" type="fixed">
       <parent link="center_leg_${prefix}"/>
       <child link="inner_leg_${prefix}"/>
       <origin xyz="0 0 0.02"/>
    </joint>
    -->
  <joint name="hip_to_outer_leg_left_5" type="prismatic">
    <axis xyz="0 0 1"/>
    <parent link="hip_left_5"/>
    <child link="outer_leg_left_5"/>
    <limit effort="3000.0" lower="0.0" upper="0.14" velocity="0.1"/>
    <origin rpy="0 0 0" xyz="0 0 0"/>
    <dynamics damping="100.0" friction="200.0"/>
  </joint>
  <joint name="outer_to_center_leg_left_5" type="prismatic">
    <axis xyz="0 0 1"/>
    <parent link="outer_leg_left_5"/>
    <child link="center_leg_left_5"/>
    <limit effort="3000.0" lower="0.0" upper="0.14" velocity="0.1"/>
    <origin rpy="0 0 0" xyz="0 0 0"/>
    <dynamics damping="100.0" friction="200.0"/>
  </joint>
  <joint name="center_to_inner_leg_left_5" type="prismatic">
    <axis xyz="0 0 1"/>
    <parent link="center_leg_left_5"/>
    <child link="inner_leg_left_5"/>
    <limit effort="3000.0" lower="0.0" upper="0.14" velocity="0.1"/>
    <origin rpy="0 0 0" xyz="0 0 0"/>
    <dynamics damping="100.0" friction="200.0"/>
  </joint>
  <!--transmission name="base_to_hip_${prefix}">
      <type>transmission_interface/SimpleTransmission</type>
      <actuator name="$base_to_hip_${prefix}">
        <mechanicalReduction>1</mechanicalReduction>
      </actuator>
      <joint name="base_to_hip_${prefix}">
        <hardwareInterface>hardware_interface/VelocityJointInterface</hardwareInterface>
      </joint>
    </transmission-->
  <transmission name="outer_leg_extension_left_5_trans" type="SimpleTransmission">
    <type>transmission_interface/SimpleTransmission</type>
    <actuator name="outer_leg_extension_left_5_motor">
      <hardwareInterface>hardware_interface/PositionJointInterface</hardwareInterface>
      <mechanicalReduction>1</mechanicalReduction>
    </actuator>
    <joint name="hip_to_outer_leg_left_5">
      <hardwareInterface>hardware_interface/PositionJointInterface</hardwareInterface>
    </joint>
  </transmission>
  <transmission name="center_leg_extension_left_5_trans" type="SimpleTransmission">
    <type>transmission_interface/SimpleTransmission</type>
    <actuator name="center_leg_extension_left_5_motor">
      <hardwareInterface>hardware_interface/PositionJointInterface</hardwareInterface>
      <mechanicalReduction>1</mechanicalReduction>
    </actuator>
    <joint name="outer_to_center_leg_left_5">
      <hardwareInterface>hardware_interface/PositionJointInterface</hardwareInterface>
    </joint>
  </transmission>
  <transmission name="inner_leg_extension_left_5_trans" type="SimpleTransmission">
    <type>transmission_interface/SimpleTransmission</type>
    <actuator name="inner_leg_extension_left_5_motor">
      <hardwareInterface>hardware_interface/PositionJointInterface</hardwareInterface>
      <mechanicalReduction>1</mechanicalReduction>
    </actuator>
    <joint name="center_to_inner_leg_left_5">
      <hardwareInterface>hardware_interface/PositionJointInterface</hardwareInterface>
    </joint>
  </transmission>
  <link name="hip_left_7">
    <visual>
      <geometry>
        <cylinder length="0.14" radius="0.02"/>
      </geometry>
      <material name="black"/>
    </visual>
    <collision>
      <geometry>
        <cylinder length="0.14" radius="0.02"/>
      </geometry>
    </collision>
    <inertial>
      <mass value="0.3"/>
      <inertia ixx="0.0004900000000000001" ixy="0.0" ixz="0.0" iyy="0.0" iyz="0.0" izz="0.0004900000000000001"/>
    </inertial>
  </link>
  <link name="outer_leg_left_7">
    <visual>
      <geometry>
        <cylinder length="0.14" radius="0.016"/>
      </geometry>
      <material name="black"/>
    </visual>
    <collision>
      <geometry>
        <cylinder length="0.14" radius="0.016"/>
      </geometry>
    </collision>
    <inertial>
      <mass value="0.24"/>
      <inertia ixx="0.0003920000000000001" ixy="0.0" ixz="0.0" iyy="0.0" iyz="0.0" izz="0.0003920000000000001"/>
    </inertial>
  </link>
  <link name="center_leg_left_7">
    <visual>
      <geometry>
        <cylinder length="0.14" radius="0.012"/>
      </geometry>
      <material name="black"/>
    </visual>
    <collision>
      <geometry>
        <cylinder length="0.14" radius="0.012"/>
      </geometry>
    </collision>
    <inertial>
      <mass value="0.18"/>
      <inertia ixx="0.000294" ixy="0.0" ixz="0.0" iyy="0.000294" iyz="0.0" izz="0.0"/>
    </inertial>
  </link>
  <link name="inner_leg_left_7">
    <visual>
      <geometry>
        <cylinder length="0.14" radius="0.008"/>
      </geometry>
      <material name="black"/>
    </visual>
    <collision>
      <geometry>
        <cylinder length="0.14" radius="0.008"/>
      </geometry>
    </collision>
    <inertial>
      <mass value="0.12"/>
      <inertia ixx="0.00019600000000000005" ixy="0.0" ixz="0.0" iyy="0.00019600000000000005" iyz="0.0" izz="0.0"/>
    </inertial>
  </link>
  <joint name="base_to_hip_left_7" type="fixed">
    <parent link="filler_link"/>
    <child link="hip_left_7"/>
    <origin rpy="0 5.497787143782138 0" xyz="-0.09899494936611669 -0.4 0.09899494936611664"/>
  </joint>
  <!--
    <joint name="outer_to_center_leg_${prefix}" type="fixed">
       <parent link="outer_leg_${prefix}"/>
       <child link="center_leg_${prefix}"/>
       <origin xyz="0 0 0.02"/>
    </joint>
    <joint name="center_to_inner_leg_${prefix}" type="fixed">
       <parent link="center_leg_${prefix}"/>
       <child link="inner_leg_${prefix}"/>
       <origin xyz="0 0 0.02"/>
    </joint>
    -->
  <joint name="hip_to_outer_leg_left_7" type="prismatic">
    <axis xyz="0 0 1"/>
    <parent link="hip_left_7"/>
    <child link="outer_leg_left_7"/>
    <limit effort="3000.0" lower="0.0" upper="0.14" velocity="0.1"/>
    <origin rpy="0 0 0" xyz="0 0 0"/>
    <dynamics damping="100.0" friction="200.0"/>
  </joint>
  <joint name="outer_to_center_leg_left_7" type="prismatic">
    <axis xyz="0 0 1"/>
    <parent link="outer_leg_left_7"/>
    <child link="center_leg_left_7"/>
    <limit effort="3000.0" lower="0.0" upper="0.14" velocity="0.1"/>
    <origin rpy="0 0 0" xyz="0 0 0"/>
    <dynamics damping="100.0" friction="200.0"/>
  </joint>
  <joint name="center_to_inner_leg_left_7" type="prismatic">
    <axis xyz="0 0 1"/>
    <parent link="center_leg_left_7"/>
    <child link="inner_leg_left_7"/>
    <limit effort="3000.0" lower="0.0" upper="0.14" velocity="0.1"/>
    <origin rpy="0 0 0" xyz="0 0 0"/>
    <dynamics damping="100.0" friction="200.0"/>
  </joint>
  <!--transmission name="base_to_hip_${prefix}">
      <type>transmission_interface/SimpleTransmission</type>
      <actuator name="$base_to_hip_${prefix}">
        <mechanicalReduction>1</mechanicalReduction>
      </actuator>
      <joint name="base_to_hip_${prefix}">
        <hardwareInterface>hardware_interface/VelocityJointInterface</hardwareInterface>
      </joint>
    </transmission-->
  <transmission name="outer_leg_extension_left_7_trans" type="SimpleTransmission">
    <type>transmission_interface/SimpleTransmission</type>
    <actuator name="outer_leg_extension_left_7_motor">
      <hardwareInterface>hardware_interface/PositionJointInterface</hardwareInterface>
      <mechanicalReduction>1</mechanicalReduction>
    </actuator>
    <joint name="hip_to_outer_leg_left_7">
      <hardwareInterface>hardware_interface/PositionJointInterface</hardwareInterface>
    </joint>
  </transmission>
  <transmission name="center_leg_extension_left_7_trans" type="SimpleTransmission">
    <type>transmission_interface/SimpleTransmission</type>
    <actuator name="center_leg_extension_left_7_motor">
      <hardwareInterface>hardware_interface/PositionJointInterface</hardwareInterface>
      <mechanicalReduction>1</mechanicalReduction>
    </actuator>
    <joint name="outer_to_center_leg_left_7">
      <hardwareInterface>hardware_interface/PositionJointInterface</hardwareInterface>
    </joint>
  </transmission>
  <transmission name="inner_leg_extension_left_7_trans" type="SimpleTransmission">
    <type>transmission_interface/SimpleTransmission</type>
    <actuator name="inner_leg_extension_left_7_motor">
      <hardwareInterface>hardware_interface/PositionJointInterface</hardwareInterface>
      <mechanicalReduction>1</mechanicalReduction>
    </actuator>
    <joint name="center_to_inner_leg_left_7">
      <hardwareInterface>hardware_interface/PositionJointInterface</hardwareInterface>
    </joint>
  </transmission>
  <!--
  -->
  <gazebo>
    <plugin filename="libgazebo_ros_control.so" name="gazebo_ros_control">
      <robotNamespace>/</robotNamespace>
    </plugin>
  </gazebo>
</robot>
